#### This is the worker script job ####
INFO:Redis-Worker:Start redis worker. Max run time 86400.0s, HOST=jwc03n244.juwels, PID=20740
INFO:Redis-Worker:Start redis worker. Max run time 86400.0s, HOST=jwc03n244.juwels, PID=20741
INFO:Redis-Worker:Start redis worker. Max run time 86400.0s, HOST=jwc03n244.juwels, PID=20742
INFO:Redis-Worker:Start redis worker. Max run time 86400.0s, HOST=jwc03n244.juwels, PID=20743
INFO:Redis-Worker:Start redis worker. Max run time 86400.0s, HOST=jwc03n244.juwels, PID=20744
INFO:Redis-Worker:Start redis worker. Max run time 86400.0s, HOST=jwc03n244.juwels, PID=20745
INFO:Redis-Worker:Start redis worker. Max run time 86400.0s, HOST=jwc03n244.juwels, PID=20746
INFO:Redis-Worker:Start redis worker. Max run time 86400.0s, HOST=jwc03n244.juwels, PID=20747
INFO:Redis-Worker:Start redis worker. Max run time 86400.0s, HOST=jwc03n244.juwels, PID=20748
INFO:Redis-Worker:Start redis worker. Max run time 86400.0s, HOST=jwc03n244.juwels, PID=20749
INFO:Redis-Worker:Start redis worker. Max run time 86400.0s, HOST=jwc03n244.juwels, PID=20750
INFO:Redis-Worker:Start redis worker. Max run time 86400.0s, HOST=jwc03n244.juwels, PID=20751
INFO:Redis-Worker:Start redis worker. Max run time 86400.0s, HOST=jwc03n244.juwels, PID=20752
INFO:Redis-Worker:Start redis worker. Max run time 86400.0s, HOST=jwc03n244.juwels, PID=20753
INFO:Redis-Worker:Start redis worker. Max run time 86400.0s, HOST=jwc03n244.juwels, PID=20754
INFO:Redis-Worker:Start redis worker. Max run time 86400.0s, HOST=jwc03n244.juwels, PID=20755
Process Process-12:
Traceback (most recent call last):
  File "/p/home/jusers/reck1/juwels/keksenv/lib/python3.8/site-packages/redis/connection.py", line 559, in connect
    sock = self._connect()
  File "/p/home/jusers/reck1/juwels/keksenv/lib/python3.8/site-packages/redis/connection.py", line 584, in _connect
    for res in socket.getaddrinfo(self.host, self.port, self.socket_type,
  File "/p/software/juwels/stages/2020/software/Python/3.8.5-GCCcore-9.3.0/lib/python3.8/socket.py", line 918, in getaddrinfo
    for res in _socket.getaddrinfo(host, port, family, type, proto, flags):
socket.gaierror: [Errno -2] Name or service not known

During handling of the above exception, another exception occurred:

Traceback (most recent call last):
  File "/p/software/juwels/stages/2020/software/Python/3.8.5-GCCcore-9.3.0/lib/python3.8/multiprocessing/process.py", line 315, in _bootstrap
    self.run()
  File "/p/software/juwels/stages/2020/software/Python/3.8.5-GCCcore-9.3.0/lib/python3.8/multiprocessing/process.py", line 108, in run
    self._target(*self._args, **self._kwargs)
  File "/p/home/jusers/reck1/juwels/pyABC/pyabc/sampler/redis_eps/cli.py", line 99, in _work
    p.subscribe(MSG)
  File "/p/home/jusers/reck1/juwels/keksenv/lib/python3.8/site-packages/redis/client.py", line 3580, in subscribe
    ret_val = self.execute_command('SUBSCRIBE', *iterkeys(new_channels))
  File "/p/home/jusers/reck1/juwels/keksenv/lib/python3.8/site-packages/redis/client.py", line 3466, in execute_command
    self.connection = self.connection_pool.get_connection(
  File "/p/home/jusers/reck1/juwels/keksenv/lib/python3.8/site-packages/redis/connection.py", line 1192, in get_connection
    connection.connect()
  File "/p/home/jusers/reck1/juwels/keksenv/lib/python3.8/site-packages/redis/connection.py", line 563, in connect
    raise ConnectionError(self._error_message(e))
redis.exceptions.ConnectionError: Error -2 connecting to found::6358. Name or service not known.
Process Process-14:
Traceback (most recent call last):
  File "/p/home/jusers/reck1/juwels/keksenv/lib/python3.8/site-packages/redis/connection.py", line 559, in connect
    sock = self._connect()
  File "/p/home/jusers/reck1/juwels/keksenv/lib/python3.8/site-packages/redis/connection.py", line 584, in _connect
    for res in socket.getaddrinfo(self.host, self.port, self.socket_type,
  File "/p/software/juwels/stages/2020/software/Python/3.8.5-GCCcore-9.3.0/lib/python3.8/socket.py", line 918, in getaddrinfo
    for res in _socket.getaddrinfo(host, port, family, type, proto, flags):
socket.gaierror: [Errno -2] Name or service not known

During handling of the above exception, another exception occurred:

Traceback (most recent call last):
  File "/p/software/juwels/stages/2020/software/Python/3.8.5-GCCcore-9.3.0/lib/python3.8/multiprocessing/process.py", line 315, in _bootstrap
    self.run()
  File "/p/software/juwels/stages/2020/software/Python/3.8.5-GCCcore-9.3.0/lib/python3.8/multiprocessing/process.py", line 108, in run
    self._target(*self._args, **self._kwargs)
  File "/p/home/jusers/reck1/juwels/pyABC/pyabc/sampler/redis_eps/cli.py", line 99, in _work
    p.subscribe(MSG)
  File "/p/home/jusers/reck1/juwels/keksenv/lib/python3.8/site-packages/redis/client.py", line 3580, in subscribe
    ret_val = self.execute_command('SUBSCRIBE', *iterkeys(new_channels))
  File "/p/home/jusers/reck1/juwels/keksenv/lib/python3.8/site-packages/redis/client.py", line 3466, in execute_command
    self.connection = self.connection_pool.get_connection(
  File "/p/home/jusers/reck1/juwels/keksenv/lib/python3.8/site-packages/redis/connection.py", line 1192, in get_connection
    connection.connect()
  File "/p/home/jusers/reck1/juwels/keksenv/lib/python3.8/site-packages/redis/connection.py", line 563, in connect
    raise ConnectionError(self._error_message(e))
redis.exceptions.ConnectionError: Error -2 connecting to found::6358. Name or service not known.
Process Process-11:
Traceback (most recent call last):
  File "/p/home/jusers/reck1/juwels/keksenv/lib/python3.8/site-packages/redis/connection.py", line 559, in connect
    sock = self._connect()
  File "/p/home/jusers/reck1/juwels/keksenv/lib/python3.8/site-packages/redis/connection.py", line 584, in _connect
    for res in socket.getaddrinfo(self.host, self.port, self.socket_type,
  File "/p/software/juwels/stages/2020/software/Python/3.8.5-GCCcore-9.3.0/lib/python3.8/socket.py", line 918, in getaddrinfo
    for res in _socket.getaddrinfo(host, port, family, type, proto, flags):
socket.gaierror: [Errno -2] Name or service not known

During handling of the above exception, another exception occurred:

Traceback (most recent call last):
  File "/p/software/juwels/stages/2020/software/Python/3.8.5-GCCcore-9.3.0/lib/python3.8/multiprocessing/process.py", line 315, in _bootstrap
    self.run()
  File "/p/software/juwels/stages/2020/software/Python/3.8.5-GCCcore-9.3.0/lib/python3.8/multiprocessing/process.py", line 108, in run
    self._target(*self._args, **self._kwargs)
  File "/p/home/jusers/reck1/juwels/pyABC/pyabc/sampler/redis_eps/cli.py", line 99, in _work
    p.subscribe(MSG)
  File "/p/home/jusers/reck1/juwels/keksenv/lib/python3.8/site-packages/redis/client.py", line 3580, in subscribe
    ret_val = self.execute_command('SUBSCRIBE', *iterkeys(new_channels))
  File "/p/home/jusers/reck1/juwels/keksenv/lib/python3.8/site-packages/redis/client.py", line 3466, in execute_command
    self.connection = self.connection_pool.get_connection(
  File "/p/home/jusers/reck1/juwels/keksenv/lib/python3.8/site-packages/redis/connection.py", line 1192, in get_connection
    connection.connect()
  File "/p/home/jusers/reck1/juwels/keksenv/lib/python3.8/site-packages/redis/connection.py", line 563, in connect
    raise ConnectionError(self._error_message(e))
redis.exceptions.ConnectionError: Error -2 connecting to found::6358. Name or service not known.
Process Process-15:
Traceback (most recent call last):
  File "/p/home/jusers/reck1/juwels/keksenv/lib/python3.8/site-packages/redis/connection.py", line 559, in connect
    sock = self._connect()
  File "/p/home/jusers/reck1/juwels/keksenv/lib/python3.8/site-packages/redis/connection.py", line 584, in _connect
    for res in socket.getaddrinfo(self.host, self.port, self.socket_type,
  File "/p/software/juwels/stages/2020/software/Python/3.8.5-GCCcore-9.3.0/lib/python3.8/socket.py", line 918, in getaddrinfo
    for res in _socket.getaddrinfo(host, port, family, type, proto, flags):
socket.gaierror: [Errno -2] Name or service not known

During handling of the above exception, another exception occurred:

Traceback (most recent call last):
  File "/p/software/juwels/stages/2020/software/Python/3.8.5-GCCcore-9.3.0/lib/python3.8/multiprocessing/process.py", line 315, in _bootstrap
    self.run()
  File "/p/software/juwels/stages/2020/software/Python/3.8.5-GCCcore-9.3.0/lib/python3.8/multiprocessing/process.py", line 108, in run
    self._target(*self._args, **self._kwargs)
  File "/p/home/jusers/reck1/juwels/pyABC/pyabc/sampler/redis_eps/cli.py", line 99, in _work
    p.subscribe(MSG)
  File "/p/home/jusers/reck1/juwels/keksenv/lib/python3.8/site-packages/redis/client.py", line 3580, in subscribe
    ret_val = self.execute_command('SUBSCRIBE', *iterkeys(new_channels))
  File "/p/home/jusers/reck1/juwels/keksenv/lib/python3.8/site-packages/redis/client.py", line 3466, in execute_command
    self.connection = self.connection_pool.get_connection(
  File "/p/home/jusers/reck1/juwels/keksenv/lib/python3.8/site-packages/redis/connection.py", line 1192, in get_connection
    connection.connect()
  File "/p/home/jusers/reck1/juwels/keksenv/lib/python3.8/site-packages/redis/connection.py", line 563, in connect
    raise ConnectionError(self._error_message(e))
redis.exceptions.ConnectionError: Error -2 connecting to found::6358. Name or service not known.
Process Process-16:
Traceback (most recent call last):
  File "/p/home/jusers/reck1/juwels/keksenv/lib/python3.8/site-packages/redis/connection.py", line 559, in connect
    sock = self._connect()
  File "/p/home/jusers/reck1/juwels/keksenv/lib/python3.8/site-packages/redis/connection.py", line 584, in _connect
    for res in socket.getaddrinfo(self.host, self.port, self.socket_type,
  File "/p/software/juwels/stages/2020/software/Python/3.8.5-GCCcore-9.3.0/lib/python3.8/socket.py", line 918, in getaddrinfo
    for res in _socket.getaddrinfo(host, port, family, type, proto, flags):
socket.gaierror: [Errno -2] Name or service not known

During handling of the above exception, another exception occurred:

Traceback (most recent call last):
  File "/p/software/juwels/stages/2020/software/Python/3.8.5-GCCcore-9.3.0/lib/python3.8/multiprocessing/process.py", line 315, in _bootstrap
    self.run()
  File "/p/software/juwels/stages/2020/software/Python/3.8.5-GCCcore-9.3.0/lib/python3.8/multiprocessing/process.py", line 108, in run
    self._target(*self._args, **self._kwargs)
  File "/p/home/jusers/reck1/juwels/pyABC/pyabc/sampler/redis_eps/cli.py", line 99, in _work
    p.subscribe(MSG)
  File "/p/home/jusers/reck1/juwels/keksenv/lib/python3.8/site-packages/redis/client.py", line 3580, in subscribe
    ret_val = self.execute_command('SUBSCRIBE', *iterkeys(new_channels))
  File "/p/home/jusers/reck1/juwels/keksenv/lib/python3.8/site-packages/redis/client.py", line 3466, in execute_command
    self.connection = self.connection_pool.get_connection(
  File "/p/home/jusers/reck1/juwels/keksenv/lib/python3.8/site-packages/redis/connection.py", line 1192, in get_connection
    connection.connect()
  File "/p/home/jusers/reck1/juwels/keksenv/lib/python3.8/site-packages/redis/connection.py", line 563, in connect
    raise ConnectionError(self._error_message(e))
redis.exceptions.ConnectionError: Error -2 connecting to found::6358. Name or service not known.
Process Process-13:
Traceback (most recent call last):
  File "/p/home/jusers/reck1/juwels/keksenv/lib/python3.8/site-packages/redis/connection.py", line 559, in connect
    sock = self._connect()
  File "/p/home/jusers/reck1/juwels/keksenv/lib/python3.8/site-packages/redis/connection.py", line 584, in _connect
    for res in socket.getaddrinfo(self.host, self.port, self.socket_type,
  File "/p/software/juwels/stages/2020/software/Python/3.8.5-GCCcore-9.3.0/lib/python3.8/socket.py", line 918, in getaddrinfo
    for res in _socket.getaddrinfo(host, port, family, type, proto, flags):
socket.gaierror: [Errno -2] Name or service not known

During handling of the above exception, another exception occurred:

Traceback (most recent call last):
  File "/p/software/juwels/stages/2020/software/Python/3.8.5-GCCcore-9.3.0/lib/python3.8/multiprocessing/process.py", line 315, in _bootstrap
    self.run()
  File "/p/software/juwels/stages/2020/software/Python/3.8.5-GCCcore-9.3.0/lib/python3.8/multiprocessing/process.py", line 108, in run
    self._target(*self._args, **self._kwargs)
  File "/p/home/jusers/reck1/juwels/pyABC/pyabc/sampler/redis_eps/cli.py", line 99, in _work
    p.subscribe(MSG)
  File "/p/home/jusers/reck1/juwels/keksenv/lib/python3.8/site-packages/redis/client.py", line 3580, in subscribe
    ret_val = self.execute_command('SUBSCRIBE', *iterkeys(new_channels))
  File "/p/home/jusers/reck1/juwels/keksenv/lib/python3.8/site-packages/redis/client.py", line 3466, in execute_command
    self.connection = self.connection_pool.get_connection(
  File "/p/home/jusers/reck1/juwels/keksenv/lib/python3.8/site-packages/redis/connection.py", line 1192, in get_connection
    connection.connect()
  File "/p/home/jusers/reck1/juwels/keksenv/lib/python3.8/site-packages/redis/connection.py", line 563, in connect
    raise ConnectionError(self._error_message(e))
redis.exceptions.ConnectionError: Error -2 connecting to found::6358. Name or service not known.
INFO:Redis-Worker:Start redis worker. Max run time 86400.0s, HOST=jwc03n244.juwels, PID=20756
Process Process-4:
Traceback (most recent call last):
  File "/p/home/jusers/reck1/juwels/keksenv/lib/python3.8/site-packages/redis/connection.py", line 559, in connect
    sock = self._connect()
  File "/p/home/jusers/reck1/juwels/keksenv/lib/python3.8/site-packages/redis/connection.py", line 584, in _connect
    for res in socket.getaddrinfo(self.host, self.port, self.socket_type,
  File "/p/software/juwels/stages/2020/software/Python/3.8.5-GCCcore-9.3.0/lib/python3.8/socket.py", line 918, in getaddrinfo
    for res in _socket.getaddrinfo(host, port, family, type, proto, flags):
socket.gaierror: [Errno -2] Name or service not known

During handling of the above exception, another exception occurred:

Traceback (most recent call last):
  File "/p/software/juwels/stages/2020/software/Python/3.8.5-GCCcore-9.3.0/lib/python3.8/multiprocessing/process.py", line 315, in _bootstrap
    self.run()
  File "/p/software/juwels/stages/2020/software/Python/3.8.5-GCCcore-9.3.0/lib/python3.8/multiprocessing/process.py", line 108, in run
    self._target(*self._args, **self._kwargs)
  File "/p/home/jusers/reck1/juwels/pyABC/pyabc/sampler/redis_eps/cli.py", line 99, in _work
    p.subscribe(MSG)
  File "/p/home/jusers/reck1/juwels/keksenv/lib/python3.8/site-packages/redis/client.py", line 3580, in subscribe
    ret_val = self.execute_command('SUBSCRIBE', *iterkeys(new_channels))
  File "/p/home/jusers/reck1/juwels/keksenv/lib/python3.8/site-packages/redis/client.py", line 3466, in execute_command
    self.connection = self.connection_pool.get_connection(
  File "/p/home/jusers/reck1/juwels/keksenv/lib/python3.8/site-packages/redis/connection.py", line 1192, in get_connection
    connection.connect()
  File "/p/home/jusers/reck1/juwels/keksenv/lib/python3.8/site-packages/redis/connection.py", line 563, in connect
    raise ConnectionError(self._error_message(e))
redis.exceptions.ConnectionError: Error -2 connecting to found::6358. Name or service not known.
Process Process-1:
Traceback (most recent call last):
  File "/p/home/jusers/reck1/juwels/keksenv/lib/python3.8/site-packages/redis/connection.py", line 559, in connect
    sock = self._connect()
  File "/p/home/jusers/reck1/juwels/keksenv/lib/python3.8/site-packages/redis/connection.py", line 584, in _connect
    for res in socket.getaddrinfo(self.host, self.port, self.socket_type,
  File "/p/software/juwels/stages/2020/software/Python/3.8.5-GCCcore-9.3.0/lib/python3.8/socket.py", line 918, in getaddrinfo
    for res in _socket.getaddrinfo(host, port, family, type, proto, flags):
socket.gaierror: [Errno -2] Name or service not known

During handling of the above exception, another exception occurred:

Traceback (most recent call last):
  File "/p/software/juwels/stages/2020/software/Python/3.8.5-GCCcore-9.3.0/lib/python3.8/multiprocessing/process.py", line 315, in _bootstrap
    self.run()
  File "/p/software/juwels/stages/2020/software/Python/3.8.5-GCCcore-9.3.0/lib/python3.8/multiprocessing/process.py", line 108, in run
    self._target(*self._args, **self._kwargs)
  File "/p/home/jusers/reck1/juwels/pyABC/pyabc/sampler/redis_eps/cli.py", line 99, in _work
    p.subscribe(MSG)
  File "/p/home/jusers/reck1/juwels/keksenv/lib/python3.8/site-packages/redis/client.py", line 3580, in subscribe
    ret_val = self.execute_command('SUBSCRIBE', *iterkeys(new_channels))
  File "/p/home/jusers/reck1/juwels/keksenv/lib/python3.8/site-packages/redis/client.py", line 3466, in execute_command
    self.connection = self.connection_pool.get_connection(
  File "/p/home/jusers/reck1/juwels/keksenv/lib/python3.8/site-packages/redis/connection.py", line 1192, in get_connection
    connection.connect()
  File "/p/home/jusers/reck1/juwels/keksenv/lib/python3.8/site-packages/redis/connection.py", line 563, in connect
    raise ConnectionError(self._error_message(e))
redis.exceptions.ConnectionError: Error -2 connecting to found::6358. Name or service not known.
Process Process-6:
Traceback (most recent call last):
  File "/p/home/jusers/reck1/juwels/keksenv/lib/python3.8/site-packages/redis/connection.py", line 559, in connect
    sock = self._connect()
  File "/p/home/jusers/reck1/juwels/keksenv/lib/python3.8/site-packages/redis/connection.py", line 584, in _connect
    for res in socket.getaddrinfo(self.host, self.port, self.socket_type,
  File "/p/software/juwels/stages/2020/software/Python/3.8.5-GCCcore-9.3.0/lib/python3.8/socket.py", line 918, in getaddrinfo
    for res in _socket.getaddrinfo(host, port, family, type, proto, flags):
socket.gaierror: [Errno -2] Name or service not known

During handling of the above exception, another exception occurred:

Traceback (most recent call last):
  File "/p/software/juwels/stages/2020/software/Python/3.8.5-GCCcore-9.3.0/lib/python3.8/multiprocessing/process.py", line 315, in _bootstrap
    self.run()
  File "/p/software/juwels/stages/2020/software/Python/3.8.5-GCCcore-9.3.0/lib/python3.8/multiprocessing/process.py", line 108, in run
    self._target(*self._args, **self._kwargs)
  File "/p/home/jusers/reck1/juwels/pyABC/pyabc/sampler/redis_eps/cli.py", line 99, in _work
    p.subscribe(MSG)
  File "/p/home/jusers/reck1/juwels/keksenv/lib/python3.8/site-packages/redis/client.py", line 3580, in subscribe
    ret_val = self.execute_command('SUBSCRIBE', *iterkeys(new_channels))
  File "/p/home/jusers/reck1/juwels/keksenv/lib/python3.8/site-packages/redis/client.py", line 3466, in execute_command
    self.connection = self.connection_pool.get_connection(
  File "/p/home/jusers/reck1/juwels/keksenv/lib/python3.8/site-packages/redis/connection.py", line 1192, in get_connection
    connection.connect()
  File "/p/home/jusers/reck1/juwels/keksenv/lib/python3.8/site-packages/redis/connection.py", line 563, in connect
    raise ConnectionError(self._error_message(e))
redis.exceptions.ConnectionError: Error -2 connecting to found::6358. Name or service not known.
Process Process-8:
Traceback (most recent call last):
  File "/p/home/jusers/reck1/juwels/keksenv/lib/python3.8/site-packages/redis/connection.py", line 559, in connect
    sock = self._connect()
  File "/p/home/jusers/reck1/juwels/keksenv/lib/python3.8/site-packages/redis/connection.py", line 584, in _connect
    for res in socket.getaddrinfo(self.host, self.port, self.socket_type,
  File "/p/software/juwels/stages/2020/software/Python/3.8.5-GCCcore-9.3.0/lib/python3.8/socket.py", line 918, in getaddrinfo
    for res in _socket.getaddrinfo(host, port, family, type, proto, flags):
socket.gaierror: [Errno -2] Name or service not known

During handling of the above exception, another exception occurred:

Traceback (most recent call last):
  File "/p/software/juwels/stages/2020/software/Python/3.8.5-GCCcore-9.3.0/lib/python3.8/multiprocessing/process.py", line 315, in _bootstrap
    self.run()
  File "/p/software/juwels/stages/2020/software/Python/3.8.5-GCCcore-9.3.0/lib/python3.8/multiprocessing/process.py", line 108, in run
    self._target(*self._args, **self._kwargs)
  File "/p/home/jusers/reck1/juwels/pyABC/pyabc/sampler/redis_eps/cli.py", line 99, in _work
    p.subscribe(MSG)
  File "/p/home/jusers/reck1/juwels/keksenv/lib/python3.8/site-packages/redis/client.py", line 3580, in subscribe
    ret_val = self.execute_command('SUBSCRIBE', *iterkeys(new_channels))
  File "/p/home/jusers/reck1/juwels/keksenv/lib/python3.8/site-packages/redis/client.py", line 3466, in execute_command
    self.connection = self.connection_pool.get_connection(
  File "/p/home/jusers/reck1/juwels/keksenv/lib/python3.8/site-packages/redis/connection.py", line 1192, in get_connection
    connection.connect()
  File "/p/home/jusers/reck1/juwels/keksenv/lib/python3.8/site-packages/redis/connection.py", line 563, in connect
    raise ConnectionError(self._error_message(e))
redis.exceptions.ConnectionError: Error -2 connecting to found::6358. Name or service not known.
Process Process-7:
Traceback (most recent call last):
  File "/p/home/jusers/reck1/juwels/keksenv/lib/python3.8/site-packages/redis/connection.py", line 559, in connect
    sock = self._connect()
  File "/p/home/jusers/reck1/juwels/keksenv/lib/python3.8/site-packages/redis/connection.py", line 584, in _connect
    for res in socket.getaddrinfo(self.host, self.port, self.socket_type,
  File "/p/software/juwels/stages/2020/software/Python/3.8.5-GCCcore-9.3.0/lib/python3.8/socket.py", line 918, in getaddrinfo
    for res in _socket.getaddrinfo(host, port, family, type, proto, flags):
socket.gaierror: [Errno -2] Name or service not known

During handling of the above exception, another exception occurred:

Traceback (most recent call last):
  File "/p/software/juwels/stages/2020/software/Python/3.8.5-GCCcore-9.3.0/lib/python3.8/multiprocessing/process.py", line 315, in _bootstrap
    self.run()
  File "/p/software/juwels/stages/2020/software/Python/3.8.5-GCCcore-9.3.0/lib/python3.8/multiprocessing/process.py", line 108, in run
    self._target(*self._args, **self._kwargs)
  File "/p/home/jusers/reck1/juwels/pyABC/pyabc/sampler/redis_eps/cli.py", line 99, in _work
    p.subscribe(MSG)
  File "/p/home/jusers/reck1/juwels/keksenv/lib/python3.8/site-packages/redis/client.py", line 3580, in subscribe
    ret_val = self.execute_command('SUBSCRIBE', *iterkeys(new_channels))
  File "/p/home/jusers/reck1/juwels/keksenv/lib/python3.8/site-packages/redis/client.py", line 3466, in execute_command
    self.connection = self.connection_pool.get_connection(
  File "/p/home/jusers/reck1/juwels/keksenv/lib/python3.8/site-packages/redis/connection.py", line 1192, in get_connection
    connection.connect()
  File "/p/home/jusers/reck1/juwels/keksenv/lib/python3.8/site-packages/redis/connection.py", line 563, in connect
    raise ConnectionError(self._error_message(e))
redis.exceptions.ConnectionError: Error -2 connecting to found::6358. Name or service not known.
Process Process-2:
Traceback (most recent call last):
  File "/p/home/jusers/reck1/juwels/keksenv/lib/python3.8/site-packages/redis/connection.py", line 559, in connect
    sock = self._connect()
  File "/p/home/jusers/reck1/juwels/keksenv/lib/python3.8/site-packages/redis/connection.py", line 584, in _connect
    for res in socket.getaddrinfo(self.host, self.port, self.socket_type,
  File "/p/software/juwels/stages/2020/software/Python/3.8.5-GCCcore-9.3.0/lib/python3.8/socket.py", line 918, in getaddrinfo
    for res in _socket.getaddrinfo(host, port, family, type, proto, flags):
socket.gaierror: [Errno -2] Name or service not known

During handling of the above exception, another exception occurred:

Traceback (most recent call last):
  File "/p/software/juwels/stages/2020/software/Python/3.8.5-GCCcore-9.3.0/lib/python3.8/multiprocessing/process.py", line 315, in _bootstrap
    self.run()
  File "/p/software/juwels/stages/2020/software/Python/3.8.5-GCCcore-9.3.0/lib/python3.8/multiprocessing/process.py", line 108, in run
    self._target(*self._args, **self._kwargs)
  File "/p/home/jusers/reck1/juwels/pyABC/pyabc/sampler/redis_eps/cli.py", line 99, in _work
    p.subscribe(MSG)
  File "/p/home/jusers/reck1/juwels/keksenv/lib/python3.8/site-packages/redis/client.py", line 3580, in subscribe
    ret_val = self.execute_command('SUBSCRIBE', *iterkeys(new_channels))
  File "/p/home/jusers/reck1/juwels/keksenv/lib/python3.8/site-packages/redis/client.py", line 3466, in execute_command
    self.connection = self.connection_pool.get_connection(
  File "/p/home/jusers/reck1/juwels/keksenv/lib/python3.8/site-packages/redis/connection.py", line 1192, in get_connection
    connection.connect()
  File "/p/home/jusers/reck1/juwels/keksenv/lib/python3.8/site-packages/redis/connection.py", line 563, in connect
    raise ConnectionError(self._error_message(e))
redis.exceptions.ConnectionError: Error -2 connecting to found::6358. Name or service not known.
Process Process-9:
Traceback (most recent call last):
  File "/p/home/jusers/reck1/juwels/keksenv/lib/python3.8/site-packages/redis/connection.py", line 559, in connect
    sock = self._connect()
  File "/p/home/jusers/reck1/juwels/keksenv/lib/python3.8/site-packages/redis/connection.py", line 584, in _connect
    for res in socket.getaddrinfo(self.host, self.port, self.socket_type,
  File "/p/software/juwels/stages/2020/software/Python/3.8.5-GCCcore-9.3.0/lib/python3.8/socket.py", line 918, in getaddrinfo
    for res in _socket.getaddrinfo(host, port, family, type, proto, flags):
socket.gaierror: [Errno -2] Name or service not known

During handling of the above exception, another exception occurred:

Traceback (most recent call last):
  File "/p/software/juwels/stages/2020/software/Python/3.8.5-GCCcore-9.3.0/lib/python3.8/multiprocessing/process.py", line 315, in _bootstrap
    self.run()
  File "/p/software/juwels/stages/2020/software/Python/3.8.5-GCCcore-9.3.0/lib/python3.8/multiprocessing/process.py", line 108, in run
    self._target(*self._args, **self._kwargs)
  File "/p/home/jusers/reck1/juwels/pyABC/pyabc/sampler/redis_eps/cli.py", line 99, in _work
    p.subscribe(MSG)
  File "/p/home/jusers/reck1/juwels/keksenv/lib/python3.8/site-packages/redis/client.py", line 3580, in subscribe
    ret_val = self.execute_command('SUBSCRIBE', *iterkeys(new_channels))
  File "/p/home/jusers/reck1/juwels/keksenv/lib/python3.8/site-packages/redis/client.py", line 3466, in execute_command
    self.connection = self.connection_pool.get_connection(
  File "/p/home/jusers/reck1/juwels/keksenv/lib/python3.8/site-packages/redis/connection.py", line 1192, in get_connection
    connection.connect()
  File "/p/home/jusers/reck1/juwels/keksenv/lib/python3.8/site-packages/redis/connection.py", line 563, in connect
    raise ConnectionError(self._error_message(e))
redis.exceptions.ConnectionError: Error -2 connecting to found::6358. Name or service not known.
Process Process-10:
Traceback (most recent call last):
  File "/p/home/jusers/reck1/juwels/keksenv/lib/python3.8/site-packages/redis/connection.py", line 559, in connect
    sock = self._connect()
  File "/p/home/jusers/reck1/juwels/keksenv/lib/python3.8/site-packages/redis/connection.py", line 584, in _connect
    for res in socket.getaddrinfo(self.host, self.port, self.socket_type,
  File "/p/software/juwels/stages/2020/software/Python/3.8.5-GCCcore-9.3.0/lib/python3.8/socket.py", line 918, in getaddrinfo
    for res in _socket.getaddrinfo(host, port, family, type, proto, flags):
socket.gaierror: [Errno -2] Name or service not known

During handling of the above exception, another exception occurred:

Traceback (most recent call last):
  File "/p/software/juwels/stages/2020/software/Python/3.8.5-GCCcore-9.3.0/lib/python3.8/multiprocessing/process.py", line 315, in _bootstrap
    self.run()
  File "/p/software/juwels/stages/2020/software/Python/3.8.5-GCCcore-9.3.0/lib/python3.8/multiprocessing/process.py", line 108, in run
    self._target(*self._args, **self._kwargs)
  File "/p/home/jusers/reck1/juwels/pyABC/pyabc/sampler/redis_eps/cli.py", line 99, in _work
    p.subscribe(MSG)
  File "/p/home/jusers/reck1/juwels/keksenv/lib/python3.8/site-packages/redis/client.py", line 3580, in subscribe
    ret_val = self.execute_command('SUBSCRIBE', *iterkeys(new_channels))
  File "/p/home/jusers/reck1/juwels/keksenv/lib/python3.8/site-packages/redis/client.py", line 3466, in execute_command
    self.connection = self.connection_pool.get_connection(
  File "/p/home/jusers/reck1/juwels/keksenv/lib/python3.8/site-packages/redis/connection.py", line 1192, in get_connection
    connection.connect()
  File "/p/home/jusers/reck1/juwels/keksenv/lib/python3.8/site-packages/redis/connection.py", line 563, in connect
    raise ConnectionError(self._error_message(e))
redis.exceptions.ConnectionError: Error -2 connecting to found::6358. Name or service not known.
Process Process-3:
Traceback (most recent call last):
  File "/p/home/jusers/reck1/juwels/keksenv/lib/python3.8/site-packages/redis/connection.py", line 559, in connect
    sock = self._connect()
  File "/p/home/jusers/reck1/juwels/keksenv/lib/python3.8/site-packages/redis/connection.py", line 584, in _connect
    for res in socket.getaddrinfo(self.host, self.port, self.socket_type,
  File "/p/software/juwels/stages/2020/software/Python/3.8.5-GCCcore-9.3.0/lib/python3.8/socket.py", line 918, in getaddrinfo
    for res in _socket.getaddrinfo(host, port, family, type, proto, flags):
socket.gaierror: [Errno -2] Name or service not known

During handling of the above exception, another exception occurred:

Traceback (most recent call last):
  File "/p/software/juwels/stages/2020/software/Python/3.8.5-GCCcore-9.3.0/lib/python3.8/multiprocessing/process.py", line 315, in _bootstrap
    self.run()
  File "/p/software/juwels/stages/2020/software/Python/3.8.5-GCCcore-9.3.0/lib/python3.8/multiprocessing/process.py", line 108, in run
    self._target(*self._args, **self._kwargs)
  File "/p/home/jusers/reck1/juwels/pyABC/pyabc/sampler/redis_eps/cli.py", line 99, in _work
    p.subscribe(MSG)
  File "/p/home/jusers/reck1/juwels/keksenv/lib/python3.8/site-packages/redis/client.py", line 3580, in subscribe
    ret_val = self.execute_command('SUBSCRIBE', *iterkeys(new_channels))
  File "/p/home/jusers/reck1/juwels/keksenv/lib/python3.8/site-packages/redis/client.py", line 3466, in execute_command
    self.connection = self.connection_pool.get_connection(
  File "/p/home/jusers/reck1/juwels/keksenv/lib/python3.8/site-packages/redis/connection.py", line 1192, in get_connection
    connection.connect()
  File "/p/home/jusers/reck1/juwels/keksenv/lib/python3.8/site-packages/redis/connection.py", line 563, in connect
    raise ConnectionError(self._error_message(e))
redis.exceptions.ConnectionError: Error -2 connecting to found::6358. Name or service not known.
Process Process-5:
Traceback (most recent call last):
  File "/p/home/jusers/reck1/juwels/keksenv/lib/python3.8/site-packages/redis/connection.py", line 559, in connect
    sock = self._connect()
  File "/p/home/jusers/reck1/juwels/keksenv/lib/python3.8/site-packages/redis/connection.py", line 584, in _connect
    for res in socket.getaddrinfo(self.host, self.port, self.socket_type,
  File "/p/software/juwels/stages/2020/software/Python/3.8.5-GCCcore-9.3.0/lib/python3.8/socket.py", line 918, in getaddrinfo
    for res in _socket.getaddrinfo(host, port, family, type, proto, flags):
socket.gaierror: [Errno -2] Name or service not known

During handling of the above exception, another exception occurred:

Traceback (most recent call last):
  File "/p/software/juwels/stages/2020/software/Python/3.8.5-GCCcore-9.3.0/lib/python3.8/multiprocessing/process.py", line 315, in _bootstrap
    self.run()
  File "/p/software/juwels/stages/2020/software/Python/3.8.5-GCCcore-9.3.0/lib/python3.8/multiprocessing/process.py", line 108, in run
    self._target(*self._args, **self._kwargs)
  File "/p/home/jusers/reck1/juwels/pyABC/pyabc/sampler/redis_eps/cli.py", line 99, in _work
    p.subscribe(MSG)
  File "/p/home/jusers/reck1/juwels/keksenv/lib/python3.8/site-packages/redis/client.py", line 3580, in subscribe
    ret_val = self.execute_command('SUBSCRIBE', *iterkeys(new_channels))
  File "/p/home/jusers/reck1/juwels/keksenv/lib/python3.8/site-packages/redis/client.py", line 3466, in execute_command
    self.connection = self.connection_pool.get_connection(
  File "/p/home/jusers/reck1/juwels/keksenv/lib/python3.8/site-packages/redis/connection.py", line 1192, in get_connection
    connection.connect()
  File "/p/home/jusers/reck1/juwels/keksenv/lib/python3.8/site-packages/redis/connection.py", line 563, in connect
    raise ConnectionError(self._error_message(e))
redis.exceptions.ConnectionError: Error -2 connecting to found::6358. Name or service not known.
Process Process-17:
Traceback (most recent call last):
  File "/p/home/jusers/reck1/juwels/keksenv/lib/python3.8/site-packages/redis/connection.py", line 559, in connect
    sock = self._connect()
  File "/p/home/jusers/reck1/juwels/keksenv/lib/python3.8/site-packages/redis/connection.py", line 584, in _connect
    for res in socket.getaddrinfo(self.host, self.port, self.socket_type,
  File "/p/software/juwels/stages/2020/software/Python/3.8.5-GCCcore-9.3.0/lib/python3.8/socket.py", line 918, in getaddrinfo
    for res in _socket.getaddrinfo(host, port, family, type, proto, flags):
socket.gaierror: [Errno -2] Name or service not known

During handling of the above exception, another exception occurred:

Traceback (most recent call last):
  File "/p/software/juwels/stages/2020/software/Python/3.8.5-GCCcore-9.3.0/lib/python3.8/multiprocessing/process.py", line 315, in _bootstrap
    self.run()
  File "/p/software/juwels/stages/2020/software/Python/3.8.5-GCCcore-9.3.0/lib/python3.8/multiprocessing/process.py", line 108, in run
    self._target(*self._args, **self._kwargs)
  File "/p/home/jusers/reck1/juwels/pyABC/pyabc/sampler/redis_eps/cli.py", line 99, in _work
    p.subscribe(MSG)
  File "/p/home/jusers/reck1/juwels/keksenv/lib/python3.8/site-packages/redis/client.py", line 3580, in subscribe
    ret_val = self.execute_command('SUBSCRIBE', *iterkeys(new_channels))
  File "/p/home/jusers/reck1/juwels/keksenv/lib/python3.8/site-packages/redis/client.py", line 3466, in execute_command
    self.connection = self.connection_pool.get_connection(
  File "/p/home/jusers/reck1/juwels/keksenv/lib/python3.8/site-packages/redis/connection.py", line 1192, in get_connection
    connection.connect()
  File "/p/home/jusers/reck1/juwels/keksenv/lib/python3.8/site-packages/redis/connection.py", line 563, in connect
    raise ConnectionError(self._error_message(e))
redis.exceptions.ConnectionError: Error -2 connecting to found::6358. Name or service not known.
INFO:Redis-Worker:Start redis worker. Max run time 86400.0s, HOST=jwc03n244.juwels, PID=20757
Process Process-18:
Traceback (most recent call last):
  File "/p/home/jusers/reck1/juwels/keksenv/lib/python3.8/site-packages/redis/connection.py", line 559, in connect
    sock = self._connect()
  File "/p/home/jusers/reck1/juwels/keksenv/lib/python3.8/site-packages/redis/connection.py", line 584, in _connect
    for res in socket.getaddrinfo(self.host, self.port, self.socket_type,
  File "/p/software/juwels/stages/2020/software/Python/3.8.5-GCCcore-9.3.0/lib/python3.8/socket.py", line 918, in getaddrinfo
    for res in _socket.getaddrinfo(host, port, family, type, proto, flags):
socket.gaierror: [Errno -2] Name or service not known

During handling of the above exception, another exception occurred:

Traceback (most recent call last):
  File "/p/software/juwels/stages/2020/software/Python/3.8.5-GCCcore-9.3.0/lib/python3.8/multiprocessing/process.py", line 315, in _bootstrap
    self.run()
  File "/p/software/juwels/stages/2020/software/Python/3.8.5-GCCcore-9.3.0/lib/python3.8/multiprocessing/process.py", line 108, in run
    self._target(*self._args, **self._kwargs)
  File "/p/home/jusers/reck1/juwels/pyABC/pyabc/sampler/redis_eps/cli.py", line 99, in _work
    p.subscribe(MSG)
  File "/p/home/jusers/reck1/juwels/keksenv/lib/python3.8/site-packages/redis/client.py", line 3580, in subscribe
    ret_val = self.execute_command('SUBSCRIBE', *iterkeys(new_channels))
  File "/p/home/jusers/reck1/juwels/keksenv/lib/python3.8/site-packages/redis/client.py", line 3466, in execute_command
    self.connection = self.connection_pool.get_connection(
  File "/p/home/jusers/reck1/juwels/keksenv/lib/python3.8/site-packages/redis/connection.py", line 1192, in get_connection
    connection.connect()
  File "/p/home/jusers/reck1/juwels/keksenv/lib/python3.8/site-packages/redis/connection.py", line 563, in connect
    raise ConnectionError(self._error_message(e))
redis.exceptions.ConnectionError: Error -2 connecting to found::6358. Name or service not known.
INFO:Redis-Worker:Start redis worker. Max run time 86400.0s, HOST=jwc03n244.juwels, PID=20758
Process Process-19:
Traceback (most recent call last):
  File "/p/home/jusers/reck1/juwels/keksenv/lib/python3.8/site-packages/redis/connection.py", line 559, in connect
    sock = self._connect()
  File "/p/home/jusers/reck1/juwels/keksenv/lib/python3.8/site-packages/redis/connection.py", line 584, in _connect
    for res in socket.getaddrinfo(self.host, self.port, self.socket_type,
  File "/p/software/juwels/stages/2020/software/Python/3.8.5-GCCcore-9.3.0/lib/python3.8/socket.py", line 918, in getaddrinfo
    for res in _socket.getaddrinfo(host, port, family, type, proto, flags):
socket.gaierror: [Errno -2] Name or service not known

During handling of the above exception, another exception occurred:

Traceback (most recent call last):
  File "/p/software/juwels/stages/2020/software/Python/3.8.5-GCCcore-9.3.0/lib/python3.8/multiprocessing/process.py", line 315, in _bootstrap
    self.run()
  File "/p/software/juwels/stages/2020/software/Python/3.8.5-GCCcore-9.3.0/lib/python3.8/multiprocessing/process.py", line 108, in run
    self._target(*self._args, **self._kwargs)
  File "/p/home/jusers/reck1/juwels/pyABC/pyabc/sampler/redis_eps/cli.py", line 99, in _work
    p.subscribe(MSG)
  File "/p/home/jusers/reck1/juwels/keksenv/lib/python3.8/site-packages/redis/client.py", line 3580, in subscribe
    ret_val = self.execute_command('SUBSCRIBE', *iterkeys(new_channels))
  File "/p/home/jusers/reck1/juwels/keksenv/lib/python3.8/site-packages/redis/client.py", line 3466, in execute_command
    self.connection = self.connection_pool.get_connection(
  File "/p/home/jusers/reck1/juwels/keksenv/lib/python3.8/site-packages/redis/connection.py", line 1192, in get_connection
    connection.connect()
  File "/p/home/jusers/reck1/juwels/keksenv/lib/python3.8/site-packages/redis/connection.py", line 563, in connect
    raise ConnectionError(self._error_message(e))
redis.exceptions.ConnectionError: Error -2 connecting to found::6358. Name or service not known.
INFO:Redis-Worker:Start redis worker. Max run time 86400.0s, HOST=jwc03n244.juwels, PID=20759
Process Process-20:
Traceback (most recent call last):
  File "/p/home/jusers/reck1/juwels/keksenv/lib/python3.8/site-packages/redis/connection.py", line 559, in connect
    sock = self._connect()
  File "/p/home/jusers/reck1/juwels/keksenv/lib/python3.8/site-packages/redis/connection.py", line 584, in _connect
    for res in socket.getaddrinfo(self.host, self.port, self.socket_type,
  File "/p/software/juwels/stages/2020/software/Python/3.8.5-GCCcore-9.3.0/lib/python3.8/socket.py", line 918, in getaddrinfo
    for res in _socket.getaddrinfo(host, port, family, type, proto, flags):
socket.gaierror: [Errno -2] Name or service not known

During handling of the above exception, another exception occurred:

Traceback (most recent call last):
  File "/p/software/juwels/stages/2020/software/Python/3.8.5-GCCcore-9.3.0/lib/python3.8/multiprocessing/process.py", line 315, in _bootstrap
    self.run()
  File "/p/software/juwels/stages/2020/software/Python/3.8.5-GCCcore-9.3.0/lib/python3.8/multiprocessing/process.py", line 108, in run
    self._target(*self._args, **self._kwargs)
  File "/p/home/jusers/reck1/juwels/pyABC/pyabc/sampler/redis_eps/cli.py", line 99, in _work
    p.subscribe(MSG)
  File "/p/home/jusers/reck1/juwels/keksenv/lib/python3.8/site-packages/redis/client.py", line 3580, in subscribe
    ret_val = self.execute_command('SUBSCRIBE', *iterkeys(new_channels))
  File "/p/home/jusers/reck1/juwels/keksenv/lib/python3.8/site-packages/redis/client.py", line 3466, in execute_command
    self.connection = self.connection_pool.get_connection(
  File "/p/home/jusers/reck1/juwels/keksenv/lib/python3.8/site-packages/redis/connection.py", line 1192, in get_connection
    connection.connect()
  File "/p/home/jusers/reck1/juwels/keksenv/lib/python3.8/site-packages/redis/connection.py", line 563, in connect
    raise ConnectionError(self._error_message(e))
redis.exceptions.ConnectionError: Error -2 connecting to found::6358. Name or service not known.
INFO:Redis-Worker:Start redis worker. Max run time 86400.0s, HOST=jwc03n244.juwels, PID=20760
Process Process-21:
Traceback (most recent call last):
  File "/p/home/jusers/reck1/juwels/keksenv/lib/python3.8/site-packages/redis/connection.py", line 559, in connect
    sock = self._connect()
  File "/p/home/jusers/reck1/juwels/keksenv/lib/python3.8/site-packages/redis/connection.py", line 584, in _connect
    for res in socket.getaddrinfo(self.host, self.port, self.socket_type,
  File "/p/software/juwels/stages/2020/software/Python/3.8.5-GCCcore-9.3.0/lib/python3.8/socket.py", line 918, in getaddrinfo
    for res in _socket.getaddrinfo(host, port, family, type, proto, flags):
socket.gaierror: [Errno -2] Name or service not known

During handling of the above exception, another exception occurred:

Traceback (most recent call last):
  File "/p/software/juwels/stages/2020/software/Python/3.8.5-GCCcore-9.3.0/lib/python3.8/multiprocessing/process.py", line 315, in _bootstrap
    self.run()
  File "/p/software/juwels/stages/2020/software/Python/3.8.5-GCCcore-9.3.0/lib/python3.8/multiprocessing/process.py", line 108, in run
    self._target(*self._args, **self._kwargs)
  File "/p/home/jusers/reck1/juwels/pyABC/pyabc/sampler/redis_eps/cli.py", line 99, in _work
    p.subscribe(MSG)
  File "/p/home/jusers/reck1/juwels/keksenv/lib/python3.8/site-packages/redis/client.py", line 3580, in subscribe
    ret_val = self.execute_command('SUBSCRIBE', *iterkeys(new_channels))
  File "/p/home/jusers/reck1/juwels/keksenv/lib/python3.8/site-packages/redis/client.py", line 3466, in execute_command
    self.connection = self.connection_pool.get_connection(
  File "/p/home/jusers/reck1/juwels/keksenv/lib/python3.8/site-packages/redis/connection.py", line 1192, in get_connection
    connection.connect()
  File "/p/home/jusers/reck1/juwels/keksenv/lib/python3.8/site-packages/redis/connection.py", line 563, in connect
    raise ConnectionError(self._error_message(e))
redis.exceptions.ConnectionError: Error -2 connecting to found::6358. Name or service not known.
INFO:Redis-Worker:Start redis worker. Max run time 86400.0s, HOST=jwc03n244.juwels, PID=20761
Process Process-22:
Traceback (most recent call last):
  File "/p/home/jusers/reck1/juwels/keksenv/lib/python3.8/site-packages/redis/connection.py", line 559, in connect
    sock = self._connect()
  File "/p/home/jusers/reck1/juwels/keksenv/lib/python3.8/site-packages/redis/connection.py", line 584, in _connect
    for res in socket.getaddrinfo(self.host, self.port, self.socket_type,
  File "/p/software/juwels/stages/2020/software/Python/3.8.5-GCCcore-9.3.0/lib/python3.8/socket.py", line 918, in getaddrinfo
    for res in _socket.getaddrinfo(host, port, family, type, proto, flags):
socket.gaierror: [Errno -2] Name or service not known

During handling of the above exception, another exception occurred:

Traceback (most recent call last):
  File "/p/software/juwels/stages/2020/software/Python/3.8.5-GCCcore-9.3.0/lib/python3.8/multiprocessing/process.py", line 315, in _bootstrap
    self.run()
  File "/p/software/juwels/stages/2020/software/Python/3.8.5-GCCcore-9.3.0/lib/python3.8/multiprocessing/process.py", line 108, in run
    self._target(*self._args, **self._kwargs)
  File "/p/home/jusers/reck1/juwels/pyABC/pyabc/sampler/redis_eps/cli.py", line 99, in _work
    p.subscribe(MSG)
  File "/p/home/jusers/reck1/juwels/keksenv/lib/python3.8/site-packages/redis/client.py", line 3580, in subscribe
    ret_val = self.execute_command('SUBSCRIBE', *iterkeys(new_channels))
  File "/p/home/jusers/reck1/juwels/keksenv/lib/python3.8/site-packages/redis/client.py", line 3466, in execute_command
    self.connection = self.connection_pool.get_connection(
  File "/p/home/jusers/reck1/juwels/keksenv/lib/python3.8/site-packages/redis/connection.py", line 1192, in get_connection
    connection.connect()
  File "/p/home/jusers/reck1/juwels/keksenv/lib/python3.8/site-packages/redis/connection.py", line 563, in connect
    raise ConnectionError(self._error_message(e))
redis.exceptions.ConnectionError: Error -2 connecting to found::6358. Name or service not known.
INFO:Redis-Worker:Start redis worker. Max run time 86400.0s, HOST=jwc03n244.juwels, PID=20762
Process Process-23:
Traceback (most recent call last):
  File "/p/home/jusers/reck1/juwels/keksenv/lib/python3.8/site-packages/redis/connection.py", line 559, in connect
    sock = self._connect()
  File "/p/home/jusers/reck1/juwels/keksenv/lib/python3.8/site-packages/redis/connection.py", line 584, in _connect
    for res in socket.getaddrinfo(self.host, self.port, self.socket_type,
  File "/p/software/juwels/stages/2020/software/Python/3.8.5-GCCcore-9.3.0/lib/python3.8/socket.py", line 918, in getaddrinfo
    for res in _socket.getaddrinfo(host, port, family, type, proto, flags):
socket.gaierror: [Errno -2] Name or service not known

During handling of the above exception, another exception occurred:

Traceback (most recent call last):
  File "/p/software/juwels/stages/2020/software/Python/3.8.5-GCCcore-9.3.0/lib/python3.8/multiprocessing/process.py", line 315, in _bootstrap
    self.run()
  File "/p/software/juwels/stages/2020/software/Python/3.8.5-GCCcore-9.3.0/lib/python3.8/multiprocessing/process.py", line 108, in run
    self._target(*self._args, **self._kwargs)
  File "/p/home/jusers/reck1/juwels/pyABC/pyabc/sampler/redis_eps/cli.py", line 99, in _work
    p.subscribe(MSG)
  File "/p/home/jusers/reck1/juwels/keksenv/lib/python3.8/site-packages/redis/client.py", line 3580, in subscribe
    ret_val = self.execute_command('SUBSCRIBE', *iterkeys(new_channels))
  File "/p/home/jusers/reck1/juwels/keksenv/lib/python3.8/site-packages/redis/client.py", line 3466, in execute_command
    self.connection = self.connection_pool.get_connection(
  File "/p/home/jusers/reck1/juwels/keksenv/lib/python3.8/site-packages/redis/connection.py", line 1192, in get_connection
    connection.connect()
  File "/p/home/jusers/reck1/juwels/keksenv/lib/python3.8/site-packages/redis/connection.py", line 563, in connect
    raise ConnectionError(self._error_message(e))
redis.exceptions.ConnectionError: Error -2 connecting to found::6358. Name or service not known.
INFO:Redis-Worker:Start redis worker. Max run time 86400.0s, HOST=jwc03n244.juwels, PID=20763
Process Process-24:
Traceback (most recent call last):
  File "/p/home/jusers/reck1/juwels/keksenv/lib/python3.8/site-packages/redis/connection.py", line 559, in connect
    sock = self._connect()
  File "/p/home/jusers/reck1/juwels/keksenv/lib/python3.8/site-packages/redis/connection.py", line 584, in _connect
    for res in socket.getaddrinfo(self.host, self.port, self.socket_type,
  File "/p/software/juwels/stages/2020/software/Python/3.8.5-GCCcore-9.3.0/lib/python3.8/socket.py", line 918, in getaddrinfo
    for res in _socket.getaddrinfo(host, port, family, type, proto, flags):
socket.gaierror: [Errno -2] Name or service not known

During handling of the above exception, another exception occurred:

Traceback (most recent call last):
  File "/p/software/juwels/stages/2020/software/Python/3.8.5-GCCcore-9.3.0/lib/python3.8/multiprocessing/process.py", line 315, in _bootstrap
    self.run()
  File "/p/software/juwels/stages/2020/software/Python/3.8.5-GCCcore-9.3.0/lib/python3.8/multiprocessing/process.py", line 108, in run
    self._target(*self._args, **self._kwargs)
  File "/p/home/jusers/reck1/juwels/pyABC/pyabc/sampler/redis_eps/cli.py", line 99, in _work
    p.subscribe(MSG)
  File "/p/home/jusers/reck1/juwels/keksenv/lib/python3.8/site-packages/redis/client.py", line 3580, in subscribe
    ret_val = self.execute_command('SUBSCRIBE', *iterkeys(new_channels))
  File "/p/home/jusers/reck1/juwels/keksenv/lib/python3.8/site-packages/redis/client.py", line 3466, in execute_command
    self.connection = self.connection_pool.get_connection(
  File "/p/home/jusers/reck1/juwels/keksenv/lib/python3.8/site-packages/redis/connection.py", line 1192, in get_connection
    connection.connect()
  File "/p/home/jusers/reck1/juwels/keksenv/lib/python3.8/site-packages/redis/connection.py", line 563, in connect
    raise ConnectionError(self._error_message(e))
redis.exceptions.ConnectionError: Error -2 connecting to found::6358. Name or service not known.
INFO:Redis-Worker:Start redis worker. Max run time 86400.0s, HOST=jwc03n244.juwels, PID=20764
Process Process-25:
Traceback (most recent call last):
  File "/p/home/jusers/reck1/juwels/keksenv/lib/python3.8/site-packages/redis/connection.py", line 559, in connect
    sock = self._connect()
  File "/p/home/jusers/reck1/juwels/keksenv/lib/python3.8/site-packages/redis/connection.py", line 584, in _connect
    for res in socket.getaddrinfo(self.host, self.port, self.socket_type,
  File "/p/software/juwels/stages/2020/software/Python/3.8.5-GCCcore-9.3.0/lib/python3.8/socket.py", line 918, in getaddrinfo
    for res in _socket.getaddrinfo(host, port, family, type, proto, flags):
socket.gaierror: [Errno -2] Name or service not known

During handling of the above exception, another exception occurred:

Traceback (most recent call last):
  File "/p/software/juwels/stages/2020/software/Python/3.8.5-GCCcore-9.3.0/lib/python3.8/multiprocessing/process.py", line 315, in _bootstrap
    self.run()
  File "/p/software/juwels/stages/2020/software/Python/3.8.5-GCCcore-9.3.0/lib/python3.8/multiprocessing/process.py", line 108, in run
    self._target(*self._args, **self._kwargs)
  File "/p/home/jusers/reck1/juwels/pyABC/pyabc/sampler/redis_eps/cli.py", line 99, in _work
    p.subscribe(MSG)
  File "/p/home/jusers/reck1/juwels/keksenv/lib/python3.8/site-packages/redis/client.py", line 3580, in subscribe
    ret_val = self.execute_command('SUBSCRIBE', *iterkeys(new_channels))
  File "/p/home/jusers/reck1/juwels/keksenv/lib/python3.8/site-packages/redis/client.py", line 3466, in execute_command
    self.connection = self.connection_pool.get_connection(
  File "/p/home/jusers/reck1/juwels/keksenv/lib/python3.8/site-packages/redis/connection.py", line 1192, in get_connection
    connection.connect()
  File "/p/home/jusers/reck1/juwels/keksenv/lib/python3.8/site-packages/redis/connection.py", line 563, in connect
    raise ConnectionError(self._error_message(e))
redis.exceptions.ConnectionError: Error -2 connecting to found::6358. Name or service not known.
INFO:Redis-Worker:Start redis worker. Max run time 86400.0s, HOST=jwc03n244.juwels, PID=20765
Process Process-26:
Traceback (most recent call last):
  File "/p/home/jusers/reck1/juwels/keksenv/lib/python3.8/site-packages/redis/connection.py", line 559, in connect
    sock = self._connect()
  File "/p/home/jusers/reck1/juwels/keksenv/lib/python3.8/site-packages/redis/connection.py", line 584, in _connect
    for res in socket.getaddrinfo(self.host, self.port, self.socket_type,
  File "/p/software/juwels/stages/2020/software/Python/3.8.5-GCCcore-9.3.0/lib/python3.8/socket.py", line 918, in getaddrinfo
    for res in _socket.getaddrinfo(host, port, family, type, proto, flags):
socket.gaierror: [Errno -2] Name or service not known

During handling of the above exception, another exception occurred:

Traceback (most recent call last):
  File "/p/software/juwels/stages/2020/software/Python/3.8.5-GCCcore-9.3.0/lib/python3.8/multiprocessing/process.py", line 315, in _bootstrap
    self.run()
  File "/p/software/juwels/stages/2020/software/Python/3.8.5-GCCcore-9.3.0/lib/python3.8/multiprocessing/process.py", line 108, in run
    self._target(*self._args, **self._kwargs)
  File "/p/home/jusers/reck1/juwels/pyABC/pyabc/sampler/redis_eps/cli.py", line 99, in _work
    p.subscribe(MSG)
  File "/p/home/jusers/reck1/juwels/keksenv/lib/python3.8/site-packages/redis/client.py", line 3580, in subscribe
    ret_val = self.execute_command('SUBSCRIBE', *iterkeys(new_channels))
  File "/p/home/jusers/reck1/juwels/keksenv/lib/python3.8/site-packages/redis/client.py", line 3466, in execute_command
    self.connection = self.connection_pool.get_connection(
  File "/p/home/jusers/reck1/juwels/keksenv/lib/python3.8/site-packages/redis/connection.py", line 1192, in get_connection
    connection.connect()
  File "/p/home/jusers/reck1/juwels/keksenv/lib/python3.8/site-packages/redis/connection.py", line 563, in connect
    raise ConnectionError(self._error_message(e))
redis.exceptions.ConnectionError: Error -2 connecting to found::6358. Name or service not known.
INFO:Redis-Worker:Start redis worker. Max run time 86400.0s, HOST=jwc03n244.juwels, PID=20766
Process Process-27:
Traceback (most recent call last):
  File "/p/home/jusers/reck1/juwels/keksenv/lib/python3.8/site-packages/redis/connection.py", line 559, in connect
    sock = self._connect()
  File "/p/home/jusers/reck1/juwels/keksenv/lib/python3.8/site-packages/redis/connection.py", line 584, in _connect
    for res in socket.getaddrinfo(self.host, self.port, self.socket_type,
  File "/p/software/juwels/stages/2020/software/Python/3.8.5-GCCcore-9.3.0/lib/python3.8/socket.py", line 918, in getaddrinfo
    for res in _socket.getaddrinfo(host, port, family, type, proto, flags):
socket.gaierror: [Errno -2] Name or service not known

During handling of the above exception, another exception occurred:

Traceback (most recent call last):
  File "/p/software/juwels/stages/2020/software/Python/3.8.5-GCCcore-9.3.0/lib/python3.8/multiprocessing/process.py", line 315, in _bootstrap
    self.run()
  File "/p/software/juwels/stages/2020/software/Python/3.8.5-GCCcore-9.3.0/lib/python3.8/multiprocessing/process.py", line 108, in run
    self._target(*self._args, **self._kwargs)
  File "/p/home/jusers/reck1/juwels/pyABC/pyabc/sampler/redis_eps/cli.py", line 99, in _work
    p.subscribe(MSG)
  File "/p/home/jusers/reck1/juwels/keksenv/lib/python3.8/site-packages/redis/client.py", line 3580, in subscribe
    ret_val = self.execute_command('SUBSCRIBE', *iterkeys(new_channels))
  File "/p/home/jusers/reck1/juwels/keksenv/lib/python3.8/site-packages/redis/client.py", line 3466, in execute_command
    self.connection = self.connection_pool.get_connection(
  File "/p/home/jusers/reck1/juwels/keksenv/lib/python3.8/site-packages/redis/connection.py", line 1192, in get_connection
    connection.connect()
  File "/p/home/jusers/reck1/juwels/keksenv/lib/python3.8/site-packages/redis/connection.py", line 563, in connect
    raise ConnectionError(self._error_message(e))
redis.exceptions.ConnectionError: Error -2 connecting to found::6358. Name or service not known.
INFO:Redis-Worker:Start redis worker. Max run time 86400.0s, HOST=jwc03n244.juwels, PID=20767
Process Process-28:
Traceback (most recent call last):
  File "/p/home/jusers/reck1/juwels/keksenv/lib/python3.8/site-packages/redis/connection.py", line 559, in connect
    sock = self._connect()
  File "/p/home/jusers/reck1/juwels/keksenv/lib/python3.8/site-packages/redis/connection.py", line 584, in _connect
    for res in socket.getaddrinfo(self.host, self.port, self.socket_type,
  File "/p/software/juwels/stages/2020/software/Python/3.8.5-GCCcore-9.3.0/lib/python3.8/socket.py", line 918, in getaddrinfo
    for res in _socket.getaddrinfo(host, port, family, type, proto, flags):
socket.gaierror: [Errno -2] Name or service not known

During handling of the above exception, another exception occurred:

Traceback (most recent call last):
  File "/p/software/juwels/stages/2020/software/Python/3.8.5-GCCcore-9.3.0/lib/python3.8/multiprocessing/process.py", line 315, in _bootstrap
    self.run()
  File "/p/software/juwels/stages/2020/software/Python/3.8.5-GCCcore-9.3.0/lib/python3.8/multiprocessing/process.py", line 108, in run
    self._target(*self._args, **self._kwargs)
  File "/p/home/jusers/reck1/juwels/pyABC/pyabc/sampler/redis_eps/cli.py", line 99, in _work
    p.subscribe(MSG)
  File "/p/home/jusers/reck1/juwels/keksenv/lib/python3.8/site-packages/redis/client.py", line 3580, in subscribe
    ret_val = self.execute_command('SUBSCRIBE', *iterkeys(new_channels))
  File "/p/home/jusers/reck1/juwels/keksenv/lib/python3.8/site-packages/redis/client.py", line 3466, in execute_command
    self.connection = self.connection_pool.get_connection(
  File "/p/home/jusers/reck1/juwels/keksenv/lib/python3.8/site-packages/redis/connection.py", line 1192, in get_connection
    connection.connect()
  File "/p/home/jusers/reck1/juwels/keksenv/lib/python3.8/site-packages/redis/connection.py", line 563, in connect
    raise ConnectionError(self._error_message(e))
redis.exceptions.ConnectionError: Error -2 connecting to found::6358. Name or service not known.
INFO:Redis-Worker:Start redis worker. Max run time 86400.0s, HOST=jwc03n244.juwels, PID=20768
Process Process-29:
Traceback (most recent call last):
  File "/p/home/jusers/reck1/juwels/keksenv/lib/python3.8/site-packages/redis/connection.py", line 559, in connect
    sock = self._connect()
  File "/p/home/jusers/reck1/juwels/keksenv/lib/python3.8/site-packages/redis/connection.py", line 584, in _connect
    for res in socket.getaddrinfo(self.host, self.port, self.socket_type,
  File "/p/software/juwels/stages/2020/software/Python/3.8.5-GCCcore-9.3.0/lib/python3.8/socket.py", line 918, in getaddrinfo
    for res in _socket.getaddrinfo(host, port, family, type, proto, flags):
socket.gaierror: [Errno -2] Name or service not known

During handling of the above exception, another exception occurred:

Traceback (most recent call last):
  File "/p/software/juwels/stages/2020/software/Python/3.8.5-GCCcore-9.3.0/lib/python3.8/multiprocessing/process.py", line 315, in _bootstrap
    self.run()
  File "/p/software/juwels/stages/2020/software/Python/3.8.5-GCCcore-9.3.0/lib/python3.8/multiprocessing/process.py", line 108, in run
    self._target(*self._args, **self._kwargs)
  File "/p/home/jusers/reck1/juwels/pyABC/pyabc/sampler/redis_eps/cli.py", line 99, in _work
    p.subscribe(MSG)
  File "/p/home/jusers/reck1/juwels/keksenv/lib/python3.8/site-packages/redis/client.py", line 3580, in subscribe
    ret_val = self.execute_command('SUBSCRIBE', *iterkeys(new_channels))
  File "/p/home/jusers/reck1/juwels/keksenv/lib/python3.8/site-packages/redis/client.py", line 3466, in execute_command
    self.connection = self.connection_pool.get_connection(
  File "/p/home/jusers/reck1/juwels/keksenv/lib/python3.8/site-packages/redis/connection.py", line 1192, in get_connection
    connection.connect()
  File "/p/home/jusers/reck1/juwels/keksenv/lib/python3.8/site-packages/redis/connection.py", line 563, in connect
    raise ConnectionError(self._error_message(e))
redis.exceptions.ConnectionError: Error -2 connecting to found::6358. Name or service not known.
INFO:Redis-Worker:Start redis worker. Max run time 86400.0s, HOST=jwc03n244.juwels, PID=20769
Process Process-30:
Traceback (most recent call last):
  File "/p/home/jusers/reck1/juwels/keksenv/lib/python3.8/site-packages/redis/connection.py", line 559, in connect
    sock = self._connect()
  File "/p/home/jusers/reck1/juwels/keksenv/lib/python3.8/site-packages/redis/connection.py", line 584, in _connect
    for res in socket.getaddrinfo(self.host, self.port, self.socket_type,
  File "/p/software/juwels/stages/2020/software/Python/3.8.5-GCCcore-9.3.0/lib/python3.8/socket.py", line 918, in getaddrinfo
    for res in _socket.getaddrinfo(host, port, family, type, proto, flags):
socket.gaierror: [Errno -2] Name or service not known

During handling of the above exception, another exception occurred:

Traceback (most recent call last):
  File "/p/software/juwels/stages/2020/software/Python/3.8.5-GCCcore-9.3.0/lib/python3.8/multiprocessing/process.py", line 315, in _bootstrap
    self.run()
  File "/p/software/juwels/stages/2020/software/Python/3.8.5-GCCcore-9.3.0/lib/python3.8/multiprocessing/process.py", line 108, in run
    self._target(*self._args, **self._kwargs)
  File "/p/home/jusers/reck1/juwels/pyABC/pyabc/sampler/redis_eps/cli.py", line 99, in _work
    p.subscribe(MSG)
  File "/p/home/jusers/reck1/juwels/keksenv/lib/python3.8/site-packages/redis/client.py", line 3580, in subscribe
    ret_val = self.execute_command('SUBSCRIBE', *iterkeys(new_channels))
  File "/p/home/jusers/reck1/juwels/keksenv/lib/python3.8/site-packages/redis/client.py", line 3466, in execute_command
    self.connection = self.connection_pool.get_connection(
  File "/p/home/jusers/reck1/juwels/keksenv/lib/python3.8/site-packages/redis/connection.py", line 1192, in get_connection
    connection.connect()
  File "/p/home/jusers/reck1/juwels/keksenv/lib/python3.8/site-packages/redis/connection.py", line 563, in connect
    raise ConnectionError(self._error_message(e))
redis.exceptions.ConnectionError: Error -2 connecting to found::6358. Name or service not known.
INFO:Redis-Worker:Start redis worker. Max run time 86400.0s, HOST=jwc03n244.juwels, PID=20770
Process Process-31:
Traceback (most recent call last):
  File "/p/home/jusers/reck1/juwels/keksenv/lib/python3.8/site-packages/redis/connection.py", line 559, in connect
    sock = self._connect()
  File "/p/home/jusers/reck1/juwels/keksenv/lib/python3.8/site-packages/redis/connection.py", line 584, in _connect
    for res in socket.getaddrinfo(self.host, self.port, self.socket_type,
  File "/p/software/juwels/stages/2020/software/Python/3.8.5-GCCcore-9.3.0/lib/python3.8/socket.py", line 918, in getaddrinfo
    for res in _socket.getaddrinfo(host, port, family, type, proto, flags):
socket.gaierror: [Errno -2] Name or service not known

During handling of the above exception, another exception occurred:

Traceback (most recent call last):
  File "/p/software/juwels/stages/2020/software/Python/3.8.5-GCCcore-9.3.0/lib/python3.8/multiprocessing/process.py", line 315, in _bootstrap
    self.run()
  File "/p/software/juwels/stages/2020/software/Python/3.8.5-GCCcore-9.3.0/lib/python3.8/multiprocessing/process.py", line 108, in run
    self._target(*self._args, **self._kwargs)
  File "/p/home/jusers/reck1/juwels/pyABC/pyabc/sampler/redis_eps/cli.py", line 99, in _work
    p.subscribe(MSG)
  File "/p/home/jusers/reck1/juwels/keksenv/lib/python3.8/site-packages/redis/client.py", line 3580, in subscribe
    ret_val = self.execute_command('SUBSCRIBE', *iterkeys(new_channels))
  File "/p/home/jusers/reck1/juwels/keksenv/lib/python3.8/site-packages/redis/client.py", line 3466, in execute_command
    self.connection = self.connection_pool.get_connection(
  File "/p/home/jusers/reck1/juwels/keksenv/lib/python3.8/site-packages/redis/connection.py", line 1192, in get_connection
    connection.connect()
  File "/p/home/jusers/reck1/juwels/keksenv/lib/python3.8/site-packages/redis/connection.py", line 563, in connect
    raise ConnectionError(self._error_message(e))
redis.exceptions.ConnectionError: Error -2 connecting to found::6358. Name or service not known.
INFO:Redis-Worker:Start redis worker. Max run time 86400.0s, HOST=jwc03n244.juwels, PID=20771
Process Process-32:
Traceback (most recent call last):
  File "/p/home/jusers/reck1/juwels/keksenv/lib/python3.8/site-packages/redis/connection.py", line 559, in connect
    sock = self._connect()
  File "/p/home/jusers/reck1/juwels/keksenv/lib/python3.8/site-packages/redis/connection.py", line 584, in _connect
    for res in socket.getaddrinfo(self.host, self.port, self.socket_type,
  File "/p/software/juwels/stages/2020/software/Python/3.8.5-GCCcore-9.3.0/lib/python3.8/socket.py", line 918, in getaddrinfo
    for res in _socket.getaddrinfo(host, port, family, type, proto, flags):
socket.gaierror: [Errno -2] Name or service not known

During handling of the above exception, another exception occurred:

Traceback (most recent call last):
  File "/p/software/juwels/stages/2020/software/Python/3.8.5-GCCcore-9.3.0/lib/python3.8/multiprocessing/process.py", line 315, in _bootstrap
    self.run()
  File "/p/software/juwels/stages/2020/software/Python/3.8.5-GCCcore-9.3.0/lib/python3.8/multiprocessing/process.py", line 108, in run
    self._target(*self._args, **self._kwargs)
  File "/p/home/jusers/reck1/juwels/pyABC/pyabc/sampler/redis_eps/cli.py", line 99, in _work
    p.subscribe(MSG)
  File "/p/home/jusers/reck1/juwels/keksenv/lib/python3.8/site-packages/redis/client.py", line 3580, in subscribe
    ret_val = self.execute_command('SUBSCRIBE', *iterkeys(new_channels))
  File "/p/home/jusers/reck1/juwels/keksenv/lib/python3.8/site-packages/redis/client.py", line 3466, in execute_command
    self.connection = self.connection_pool.get_connection(
  File "/p/home/jusers/reck1/juwels/keksenv/lib/python3.8/site-packages/redis/connection.py", line 1192, in get_connection
    connection.connect()
  File "/p/home/jusers/reck1/juwels/keksenv/lib/python3.8/site-packages/redis/connection.py", line 563, in connect
    raise ConnectionError(self._error_message(e))
redis.exceptions.ConnectionError: Error -2 connecting to found::6358. Name or service not known.
INFO:Redis-Worker:Start redis worker. Max run time 86400.0s, HOST=jwc03n244.juwels, PID=20772
Process Process-33:
Traceback (most recent call last):
  File "/p/home/jusers/reck1/juwels/keksenv/lib/python3.8/site-packages/redis/connection.py", line 559, in connect
    sock = self._connect()
  File "/p/home/jusers/reck1/juwels/keksenv/lib/python3.8/site-packages/redis/connection.py", line 584, in _connect
    for res in socket.getaddrinfo(self.host, self.port, self.socket_type,
  File "/p/software/juwels/stages/2020/software/Python/3.8.5-GCCcore-9.3.0/lib/python3.8/socket.py", line 918, in getaddrinfo
    for res in _socket.getaddrinfo(host, port, family, type, proto, flags):
socket.gaierror: [Errno -2] Name or service not known

During handling of the above exception, another exception occurred:

Traceback (most recent call last):
  File "/p/software/juwels/stages/2020/software/Python/3.8.5-GCCcore-9.3.0/lib/python3.8/multiprocessing/process.py", line 315, in _bootstrap
    self.run()
  File "/p/software/juwels/stages/2020/software/Python/3.8.5-GCCcore-9.3.0/lib/python3.8/multiprocessing/process.py", line 108, in run
    self._target(*self._args, **self._kwargs)
  File "/p/home/jusers/reck1/juwels/pyABC/pyabc/sampler/redis_eps/cli.py", line 99, in _work
    p.subscribe(MSG)
  File "/p/home/jusers/reck1/juwels/keksenv/lib/python3.8/site-packages/redis/client.py", line 3580, in subscribe
    ret_val = self.execute_command('SUBSCRIBE', *iterkeys(new_channels))
  File "/p/home/jusers/reck1/juwels/keksenv/lib/python3.8/site-packages/redis/client.py", line 3466, in execute_command
    self.connection = self.connection_pool.get_connection(
  File "/p/home/jusers/reck1/juwels/keksenv/lib/python3.8/site-packages/redis/connection.py", line 1192, in get_connection
    connection.connect()
  File "/p/home/jusers/reck1/juwels/keksenv/lib/python3.8/site-packages/redis/connection.py", line 563, in connect
    raise ConnectionError(self._error_message(e))
redis.exceptions.ConnectionError: Error -2 connecting to found::6358. Name or service not known.
INFO:Redis-Worker:Start redis worker. Max run time 86400.0s, HOST=jwc03n244.juwels, PID=20773
Process Process-34:
Traceback (most recent call last):
  File "/p/home/jusers/reck1/juwels/keksenv/lib/python3.8/site-packages/redis/connection.py", line 559, in connect
    sock = self._connect()
  File "/p/home/jusers/reck1/juwels/keksenv/lib/python3.8/site-packages/redis/connection.py", line 584, in _connect
    for res in socket.getaddrinfo(self.host, self.port, self.socket_type,
  File "/p/software/juwels/stages/2020/software/Python/3.8.5-GCCcore-9.3.0/lib/python3.8/socket.py", line 918, in getaddrinfo
    for res in _socket.getaddrinfo(host, port, family, type, proto, flags):
socket.gaierror: [Errno -2] Name or service not known

During handling of the above exception, another exception occurred:

Traceback (most recent call last):
  File "/p/software/juwels/stages/2020/software/Python/3.8.5-GCCcore-9.3.0/lib/python3.8/multiprocessing/process.py", line 315, in _bootstrap
    self.run()
  File "/p/software/juwels/stages/2020/software/Python/3.8.5-GCCcore-9.3.0/lib/python3.8/multiprocessing/process.py", line 108, in run
    self._target(*self._args, **self._kwargs)
  File "/p/home/jusers/reck1/juwels/pyABC/pyabc/sampler/redis_eps/cli.py", line 99, in _work
    p.subscribe(MSG)
  File "/p/home/jusers/reck1/juwels/keksenv/lib/python3.8/site-packages/redis/client.py", line 3580, in subscribe
    ret_val = self.execute_command('SUBSCRIBE', *iterkeys(new_channels))
  File "/p/home/jusers/reck1/juwels/keksenv/lib/python3.8/site-packages/redis/client.py", line 3466, in execute_command
    self.connection = self.connection_pool.get_connection(
  File "/p/home/jusers/reck1/juwels/keksenv/lib/python3.8/site-packages/redis/connection.py", line 1192, in get_connection
    connection.connect()
  File "/p/home/jusers/reck1/juwels/keksenv/lib/python3.8/site-packages/redis/connection.py", line 563, in connect
    raise ConnectionError(self._error_message(e))
redis.exceptions.ConnectionError: Error -2 connecting to found::6358. Name or service not known.
INFO:Redis-Worker:Start redis worker. Max run time 86400.0s, HOST=jwc03n244.juwels, PID=20774
Process Process-35:
Traceback (most recent call last):
  File "/p/home/jusers/reck1/juwels/keksenv/lib/python3.8/site-packages/redis/connection.py", line 559, in connect
    sock = self._connect()
  File "/p/home/jusers/reck1/juwels/keksenv/lib/python3.8/site-packages/redis/connection.py", line 584, in _connect
    for res in socket.getaddrinfo(self.host, self.port, self.socket_type,
  File "/p/software/juwels/stages/2020/software/Python/3.8.5-GCCcore-9.3.0/lib/python3.8/socket.py", line 918, in getaddrinfo
    for res in _socket.getaddrinfo(host, port, family, type, proto, flags):
socket.gaierror: [Errno -2] Name or service not known

During handling of the above exception, another exception occurred:

Traceback (most recent call last):
  File "/p/software/juwels/stages/2020/software/Python/3.8.5-GCCcore-9.3.0/lib/python3.8/multiprocessing/process.py", line 315, in _bootstrap
    self.run()
  File "/p/software/juwels/stages/2020/software/Python/3.8.5-GCCcore-9.3.0/lib/python3.8/multiprocessing/process.py", line 108, in run
    self._target(*self._args, **self._kwargs)
  File "/p/home/jusers/reck1/juwels/pyABC/pyabc/sampler/redis_eps/cli.py", line 99, in _work
    p.subscribe(MSG)
  File "/p/home/jusers/reck1/juwels/keksenv/lib/python3.8/site-packages/redis/client.py", line 3580, in subscribe
    ret_val = self.execute_command('SUBSCRIBE', *iterkeys(new_channels))
  File "/p/home/jusers/reck1/juwels/keksenv/lib/python3.8/site-packages/redis/client.py", line 3466, in execute_command
    self.connection = self.connection_pool.get_connection(
  File "/p/home/jusers/reck1/juwels/keksenv/lib/python3.8/site-packages/redis/connection.py", line 1192, in get_connection
    connection.connect()
  File "/p/home/jusers/reck1/juwels/keksenv/lib/python3.8/site-packages/redis/connection.py", line 563, in connect
    raise ConnectionError(self._error_message(e))
redis.exceptions.ConnectionError: Error -2 connecting to found::6358. Name or service not known.
INFO:Redis-Worker:Start redis worker. Max run time 86400.0s, HOST=jwc03n244.juwels, PID=20775
Process Process-36:
Traceback (most recent call last):
  File "/p/home/jusers/reck1/juwels/keksenv/lib/python3.8/site-packages/redis/connection.py", line 559, in connect
    sock = self._connect()
  File "/p/home/jusers/reck1/juwels/keksenv/lib/python3.8/site-packages/redis/connection.py", line 584, in _connect
    for res in socket.getaddrinfo(self.host, self.port, self.socket_type,
  File "/p/software/juwels/stages/2020/software/Python/3.8.5-GCCcore-9.3.0/lib/python3.8/socket.py", line 918, in getaddrinfo
    for res in _socket.getaddrinfo(host, port, family, type, proto, flags):
socket.gaierror: [Errno -2] Name or service not known

During handling of the above exception, another exception occurred:

Traceback (most recent call last):
  File "/p/software/juwels/stages/2020/software/Python/3.8.5-GCCcore-9.3.0/lib/python3.8/multiprocessing/process.py", line 315, in _bootstrap
    self.run()
  File "/p/software/juwels/stages/2020/software/Python/3.8.5-GCCcore-9.3.0/lib/python3.8/multiprocessing/process.py", line 108, in run
    self._target(*self._args, **self._kwargs)
  File "/p/home/jusers/reck1/juwels/pyABC/pyabc/sampler/redis_eps/cli.py", line 99, in _work
    p.subscribe(MSG)
  File "/p/home/jusers/reck1/juwels/keksenv/lib/python3.8/site-packages/redis/client.py", line 3580, in subscribe
    ret_val = self.execute_command('SUBSCRIBE', *iterkeys(new_channels))
  File "/p/home/jusers/reck1/juwels/keksenv/lib/python3.8/site-packages/redis/client.py", line 3466, in execute_command
    self.connection = self.connection_pool.get_connection(
  File "/p/home/jusers/reck1/juwels/keksenv/lib/python3.8/site-packages/redis/connection.py", line 1192, in get_connection
    connection.connect()
  File "/p/home/jusers/reck1/juwels/keksenv/lib/python3.8/site-packages/redis/connection.py", line 563, in connect
    raise ConnectionError(self._error_message(e))
redis.exceptions.ConnectionError: Error -2 connecting to found::6358. Name or service not known.
INFO:Redis-Worker:Start redis worker. Max run time 86400.0s, HOST=jwc03n244.juwels, PID=20776
Process Process-37:
Traceback (most recent call last):
  File "/p/home/jusers/reck1/juwels/keksenv/lib/python3.8/site-packages/redis/connection.py", line 559, in connect
    sock = self._connect()
  File "/p/home/jusers/reck1/juwels/keksenv/lib/python3.8/site-packages/redis/connection.py", line 584, in _connect
    for res in socket.getaddrinfo(self.host, self.port, self.socket_type,
  File "/p/software/juwels/stages/2020/software/Python/3.8.5-GCCcore-9.3.0/lib/python3.8/socket.py", line 918, in getaddrinfo
    for res in _socket.getaddrinfo(host, port, family, type, proto, flags):
socket.gaierror: [Errno -2] Name or service not known

During handling of the above exception, another exception occurred:

Traceback (most recent call last):
  File "/p/software/juwels/stages/2020/software/Python/3.8.5-GCCcore-9.3.0/lib/python3.8/multiprocessing/process.py", line 315, in _bootstrap
    self.run()
  File "/p/software/juwels/stages/2020/software/Python/3.8.5-GCCcore-9.3.0/lib/python3.8/multiprocessing/process.py", line 108, in run
    self._target(*self._args, **self._kwargs)
  File "/p/home/jusers/reck1/juwels/pyABC/pyabc/sampler/redis_eps/cli.py", line 99, in _work
    p.subscribe(MSG)
  File "/p/home/jusers/reck1/juwels/keksenv/lib/python3.8/site-packages/redis/client.py", line 3580, in subscribe
    ret_val = self.execute_command('SUBSCRIBE', *iterkeys(new_channels))
  File "/p/home/jusers/reck1/juwels/keksenv/lib/python3.8/site-packages/redis/client.py", line 3466, in execute_command
    self.connection = self.connection_pool.get_connection(
  File "/p/home/jusers/reck1/juwels/keksenv/lib/python3.8/site-packages/redis/connection.py", line 1192, in get_connection
    connection.connect()
  File "/p/home/jusers/reck1/juwels/keksenv/lib/python3.8/site-packages/redis/connection.py", line 563, in connect
    raise ConnectionError(self._error_message(e))
redis.exceptions.ConnectionError: Error -2 connecting to found::6358. Name or service not known.
INFO:Redis-Worker:Start redis worker. Max run time 86400.0s, HOST=jwc03n244.juwels, PID=20777
Process Process-38:
Traceback (most recent call last):
  File "/p/home/jusers/reck1/juwels/keksenv/lib/python3.8/site-packages/redis/connection.py", line 559, in connect
    sock = self._connect()
  File "/p/home/jusers/reck1/juwels/keksenv/lib/python3.8/site-packages/redis/connection.py", line 584, in _connect
    for res in socket.getaddrinfo(self.host, self.port, self.socket_type,
  File "/p/software/juwels/stages/2020/software/Python/3.8.5-GCCcore-9.3.0/lib/python3.8/socket.py", line 918, in getaddrinfo
    for res in _socket.getaddrinfo(host, port, family, type, proto, flags):
socket.gaierror: [Errno -2] Name or service not known

During handling of the above exception, another exception occurred:

Traceback (most recent call last):
  File "/p/software/juwels/stages/2020/software/Python/3.8.5-GCCcore-9.3.0/lib/python3.8/multiprocessing/process.py", line 315, in _bootstrap
    self.run()
  File "/p/software/juwels/stages/2020/software/Python/3.8.5-GCCcore-9.3.0/lib/python3.8/multiprocessing/process.py", line 108, in run
    self._target(*self._args, **self._kwargs)
  File "/p/home/jusers/reck1/juwels/pyABC/pyabc/sampler/redis_eps/cli.py", line 99, in _work
    p.subscribe(MSG)
  File "/p/home/jusers/reck1/juwels/keksenv/lib/python3.8/site-packages/redis/client.py", line 3580, in subscribe
    ret_val = self.execute_command('SUBSCRIBE', *iterkeys(new_channels))
  File "/p/home/jusers/reck1/juwels/keksenv/lib/python3.8/site-packages/redis/client.py", line 3466, in execute_command
    self.connection = self.connection_pool.get_connection(
  File "/p/home/jusers/reck1/juwels/keksenv/lib/python3.8/site-packages/redis/connection.py", line 1192, in get_connection
    connection.connect()
  File "/p/home/jusers/reck1/juwels/keksenv/lib/python3.8/site-packages/redis/connection.py", line 563, in connect
    raise ConnectionError(self._error_message(e))
redis.exceptions.ConnectionError: Error -2 connecting to found::6358. Name or service not known.
INFO:Redis-Worker:Start redis worker. Max run time 86400.0s, HOST=jwc03n244.juwels, PID=20779
Process Process-39:
Traceback (most recent call last):
  File "/p/home/jusers/reck1/juwels/keksenv/lib/python3.8/site-packages/redis/connection.py", line 559, in connect
    sock = self._connect()
  File "/p/home/jusers/reck1/juwels/keksenv/lib/python3.8/site-packages/redis/connection.py", line 584, in _connect
    for res in socket.getaddrinfo(self.host, self.port, self.socket_type,
  File "/p/software/juwels/stages/2020/software/Python/3.8.5-GCCcore-9.3.0/lib/python3.8/socket.py", line 918, in getaddrinfo
    for res in _socket.getaddrinfo(host, port, family, type, proto, flags):
socket.gaierror: [Errno -2] Name or service not known

During handling of the above exception, another exception occurred:

Traceback (most recent call last):
  File "/p/software/juwels/stages/2020/software/Python/3.8.5-GCCcore-9.3.0/lib/python3.8/multiprocessing/process.py", line 315, in _bootstrap
    self.run()
  File "/p/software/juwels/stages/2020/software/Python/3.8.5-GCCcore-9.3.0/lib/python3.8/multiprocessing/process.py", line 108, in run
    self._target(*self._args, **self._kwargs)
  File "/p/home/jusers/reck1/juwels/pyABC/pyabc/sampler/redis_eps/cli.py", line 99, in _work
    p.subscribe(MSG)
  File "/p/home/jusers/reck1/juwels/keksenv/lib/python3.8/site-packages/redis/client.py", line 3580, in subscribe
    ret_val = self.execute_command('SUBSCRIBE', *iterkeys(new_channels))
  File "/p/home/jusers/reck1/juwels/keksenv/lib/python3.8/site-packages/redis/client.py", line 3466, in execute_command
    self.connection = self.connection_pool.get_connection(
  File "/p/home/jusers/reck1/juwels/keksenv/lib/python3.8/site-packages/redis/connection.py", line 1192, in get_connection
    connection.connect()
  File "/p/home/jusers/reck1/juwels/keksenv/lib/python3.8/site-packages/redis/connection.py", line 563, in connect
    raise ConnectionError(self._error_message(e))
redis.exceptions.ConnectionError: Error -2 connecting to found::6358. Name or service not known.
INFO:Redis-Worker:Start redis worker. Max run time 86400.0s, HOST=jwc03n244.juwels, PID=20780
Process Process-40:
Traceback (most recent call last):
  File "/p/home/jusers/reck1/juwels/keksenv/lib/python3.8/site-packages/redis/connection.py", line 559, in connect
    sock = self._connect()
  File "/p/home/jusers/reck1/juwels/keksenv/lib/python3.8/site-packages/redis/connection.py", line 584, in _connect
    for res in socket.getaddrinfo(self.host, self.port, self.socket_type,
  File "/p/software/juwels/stages/2020/software/Python/3.8.5-GCCcore-9.3.0/lib/python3.8/socket.py", line 918, in getaddrinfo
    for res in _socket.getaddrinfo(host, port, family, type, proto, flags):
socket.gaierror: [Errno -2] Name or service not known

During handling of the above exception, another exception occurred:

Traceback (most recent call last):
  File "/p/software/juwels/stages/2020/software/Python/3.8.5-GCCcore-9.3.0/lib/python3.8/multiprocessing/process.py", line 315, in _bootstrap
    self.run()
  File "/p/software/juwels/stages/2020/software/Python/3.8.5-GCCcore-9.3.0/lib/python3.8/multiprocessing/process.py", line 108, in run
    self._target(*self._args, **self._kwargs)
  File "/p/home/jusers/reck1/juwels/pyABC/pyabc/sampler/redis_eps/cli.py", line 99, in _work
    p.subscribe(MSG)
  File "/p/home/jusers/reck1/juwels/keksenv/lib/python3.8/site-packages/redis/client.py", line 3580, in subscribe
    ret_val = self.execute_command('SUBSCRIBE', *iterkeys(new_channels))
  File "/p/home/jusers/reck1/juwels/keksenv/lib/python3.8/site-packages/redis/client.py", line 3466, in execute_command
    self.connection = self.connection_pool.get_connection(
  File "/p/home/jusers/reck1/juwels/keksenv/lib/python3.8/site-packages/redis/connection.py", line 1192, in get_connection
    connection.connect()
  File "/p/home/jusers/reck1/juwels/keksenv/lib/python3.8/site-packages/redis/connection.py", line 563, in connect
    raise ConnectionError(self._error_message(e))
redis.exceptions.ConnectionError: Error -2 connecting to found::6358. Name or service not known.
INFO:Redis-Worker:Start redis worker. Max run time 86400.0s, HOST=jwc03n244.juwels, PID=20781
Process Process-41:
Traceback (most recent call last):
  File "/p/home/jusers/reck1/juwels/keksenv/lib/python3.8/site-packages/redis/connection.py", line 559, in connect
    sock = self._connect()
  File "/p/home/jusers/reck1/juwels/keksenv/lib/python3.8/site-packages/redis/connection.py", line 584, in _connect
    for res in socket.getaddrinfo(self.host, self.port, self.socket_type,
  File "/p/software/juwels/stages/2020/software/Python/3.8.5-GCCcore-9.3.0/lib/python3.8/socket.py", line 918, in getaddrinfo
    for res in _socket.getaddrinfo(host, port, family, type, proto, flags):
socket.gaierror: [Errno -2] Name or service not known

During handling of the above exception, another exception occurred:

Traceback (most recent call last):
  File "/p/software/juwels/stages/2020/software/Python/3.8.5-GCCcore-9.3.0/lib/python3.8/multiprocessing/process.py", line 315, in _bootstrap
    self.run()
  File "/p/software/juwels/stages/2020/software/Python/3.8.5-GCCcore-9.3.0/lib/python3.8/multiprocessing/process.py", line 108, in run
    self._target(*self._args, **self._kwargs)
  File "/p/home/jusers/reck1/juwels/pyABC/pyabc/sampler/redis_eps/cli.py", line 99, in _work
    p.subscribe(MSG)
  File "/p/home/jusers/reck1/juwels/keksenv/lib/python3.8/site-packages/redis/client.py", line 3580, in subscribe
    ret_val = self.execute_command('SUBSCRIBE', *iterkeys(new_channels))
  File "/p/home/jusers/reck1/juwels/keksenv/lib/python3.8/site-packages/redis/client.py", line 3466, in execute_command
    self.connection = self.connection_pool.get_connection(
  File "/p/home/jusers/reck1/juwels/keksenv/lib/python3.8/site-packages/redis/connection.py", line 1192, in get_connection
    connection.connect()
  File "/p/home/jusers/reck1/juwels/keksenv/lib/python3.8/site-packages/redis/connection.py", line 563, in connect
    raise ConnectionError(self._error_message(e))
redis.exceptions.ConnectionError: Error -2 connecting to found::6358. Name or service not known.
INFO:Redis-Worker:Start redis worker. Max run time 86400.0s, HOST=jwc03n244.juwels, PID=20782
Process Process-42:
Traceback (most recent call last):
  File "/p/home/jusers/reck1/juwels/keksenv/lib/python3.8/site-packages/redis/connection.py", line 559, in connect
    sock = self._connect()
  File "/p/home/jusers/reck1/juwels/keksenv/lib/python3.8/site-packages/redis/connection.py", line 584, in _connect
    for res in socket.getaddrinfo(self.host, self.port, self.socket_type,
  File "/p/software/juwels/stages/2020/software/Python/3.8.5-GCCcore-9.3.0/lib/python3.8/socket.py", line 918, in getaddrinfo
    for res in _socket.getaddrinfo(host, port, family, type, proto, flags):
socket.gaierror: [Errno -2] Name or service not known

During handling of the above exception, another exception occurred:

Traceback (most recent call last):
  File "/p/software/juwels/stages/2020/software/Python/3.8.5-GCCcore-9.3.0/lib/python3.8/multiprocessing/process.py", line 315, in _bootstrap
    self.run()
  File "/p/software/juwels/stages/2020/software/Python/3.8.5-GCCcore-9.3.0/lib/python3.8/multiprocessing/process.py", line 108, in run
    self._target(*self._args, **self._kwargs)
  File "/p/home/jusers/reck1/juwels/pyABC/pyabc/sampler/redis_eps/cli.py", line 99, in _work
    p.subscribe(MSG)
  File "/p/home/jusers/reck1/juwels/keksenv/lib/python3.8/site-packages/redis/client.py", line 3580, in subscribe
    ret_val = self.execute_command('SUBSCRIBE', *iterkeys(new_channels))
  File "/p/home/jusers/reck1/juwels/keksenv/lib/python3.8/site-packages/redis/client.py", line 3466, in execute_command
    self.connection = self.connection_pool.get_connection(
  File "/p/home/jusers/reck1/juwels/keksenv/lib/python3.8/site-packages/redis/connection.py", line 1192, in get_connection
    connection.connect()
  File "/p/home/jusers/reck1/juwels/keksenv/lib/python3.8/site-packages/redis/connection.py", line 563, in connect
    raise ConnectionError(self._error_message(e))
redis.exceptions.ConnectionError: Error -2 connecting to found::6358. Name or service not known.
INFO:Redis-Worker:Start redis worker. Max run time 86400.0s, HOST=jwc03n244.juwels, PID=20783
Process Process-43:
Traceback (most recent call last):
  File "/p/home/jusers/reck1/juwels/keksenv/lib/python3.8/site-packages/redis/connection.py", line 559, in connect
    sock = self._connect()
  File "/p/home/jusers/reck1/juwels/keksenv/lib/python3.8/site-packages/redis/connection.py", line 584, in _connect
    for res in socket.getaddrinfo(self.host, self.port, self.socket_type,
  File "/p/software/juwels/stages/2020/software/Python/3.8.5-GCCcore-9.3.0/lib/python3.8/socket.py", line 918, in getaddrinfo
    for res in _socket.getaddrinfo(host, port, family, type, proto, flags):
socket.gaierror: [Errno -2] Name or service not known

During handling of the above exception, another exception occurred:

Traceback (most recent call last):
  File "/p/software/juwels/stages/2020/software/Python/3.8.5-GCCcore-9.3.0/lib/python3.8/multiprocessing/process.py", line 315, in _bootstrap
    self.run()
  File "/p/software/juwels/stages/2020/software/Python/3.8.5-GCCcore-9.3.0/lib/python3.8/multiprocessing/process.py", line 108, in run
    self._target(*self._args, **self._kwargs)
  File "/p/home/jusers/reck1/juwels/pyABC/pyabc/sampler/redis_eps/cli.py", line 99, in _work
    p.subscribe(MSG)
  File "/p/home/jusers/reck1/juwels/keksenv/lib/python3.8/site-packages/redis/client.py", line 3580, in subscribe
    ret_val = self.execute_command('SUBSCRIBE', *iterkeys(new_channels))
  File "/p/home/jusers/reck1/juwels/keksenv/lib/python3.8/site-packages/redis/client.py", line 3466, in execute_command
    self.connection = self.connection_pool.get_connection(
  File "/p/home/jusers/reck1/juwels/keksenv/lib/python3.8/site-packages/redis/connection.py", line 1192, in get_connection
    connection.connect()
  File "/p/home/jusers/reck1/juwels/keksenv/lib/python3.8/site-packages/redis/connection.py", line 563, in connect
    raise ConnectionError(self._error_message(e))
redis.exceptions.ConnectionError: Error -2 connecting to found::6358. Name or service not known.
INFO:Redis-Worker:Start redis worker. Max run time 86400.0s, HOST=jwc03n244.juwels, PID=20784
Process Process-44:
Traceback (most recent call last):
  File "/p/home/jusers/reck1/juwels/keksenv/lib/python3.8/site-packages/redis/connection.py", line 559, in connect
    sock = self._connect()
  File "/p/home/jusers/reck1/juwels/keksenv/lib/python3.8/site-packages/redis/connection.py", line 584, in _connect
    for res in socket.getaddrinfo(self.host, self.port, self.socket_type,
  File "/p/software/juwels/stages/2020/software/Python/3.8.5-GCCcore-9.3.0/lib/python3.8/socket.py", line 918, in getaddrinfo
    for res in _socket.getaddrinfo(host, port, family, type, proto, flags):
socket.gaierror: [Errno -2] Name or service not known

During handling of the above exception, another exception occurred:

Traceback (most recent call last):
  File "/p/software/juwels/stages/2020/software/Python/3.8.5-GCCcore-9.3.0/lib/python3.8/multiprocessing/process.py", line 315, in _bootstrap
    self.run()
  File "/p/software/juwels/stages/2020/software/Python/3.8.5-GCCcore-9.3.0/lib/python3.8/multiprocessing/process.py", line 108, in run
    self._target(*self._args, **self._kwargs)
  File "/p/home/jusers/reck1/juwels/pyABC/pyabc/sampler/redis_eps/cli.py", line 99, in _work
    p.subscribe(MSG)
  File "/p/home/jusers/reck1/juwels/keksenv/lib/python3.8/site-packages/redis/client.py", line 3580, in subscribe
    ret_val = self.execute_command('SUBSCRIBE', *iterkeys(new_channels))
  File "/p/home/jusers/reck1/juwels/keksenv/lib/python3.8/site-packages/redis/client.py", line 3466, in execute_command
    self.connection = self.connection_pool.get_connection(
  File "/p/home/jusers/reck1/juwels/keksenv/lib/python3.8/site-packages/redis/connection.py", line 1192, in get_connection
    connection.connect()
  File "/p/home/jusers/reck1/juwels/keksenv/lib/python3.8/site-packages/redis/connection.py", line 563, in connect
    raise ConnectionError(self._error_message(e))
redis.exceptions.ConnectionError: Error -2 connecting to found::6358. Name or service not known.
INFO:Redis-Worker:Start redis worker. Max run time 86400.0s, HOST=jwc03n244.juwels, PID=20785
Process Process-45:
Traceback (most recent call last):
  File "/p/home/jusers/reck1/juwels/keksenv/lib/python3.8/site-packages/redis/connection.py", line 559, in connect
    sock = self._connect()
  File "/p/home/jusers/reck1/juwels/keksenv/lib/python3.8/site-packages/redis/connection.py", line 584, in _connect
    for res in socket.getaddrinfo(self.host, self.port, self.socket_type,
  File "/p/software/juwels/stages/2020/software/Python/3.8.5-GCCcore-9.3.0/lib/python3.8/socket.py", line 918, in getaddrinfo
    for res in _socket.getaddrinfo(host, port, family, type, proto, flags):
socket.gaierror: [Errno -2] Name or service not known

During handling of the above exception, another exception occurred:

Traceback (most recent call last):
  File "/p/software/juwels/stages/2020/software/Python/3.8.5-GCCcore-9.3.0/lib/python3.8/multiprocessing/process.py", line 315, in _bootstrap
    self.run()
  File "/p/software/juwels/stages/2020/software/Python/3.8.5-GCCcore-9.3.0/lib/python3.8/multiprocessing/process.py", line 108, in run
    self._target(*self._args, **self._kwargs)
  File "/p/home/jusers/reck1/juwels/pyABC/pyabc/sampler/redis_eps/cli.py", line 99, in _work
    p.subscribe(MSG)
  File "/p/home/jusers/reck1/juwels/keksenv/lib/python3.8/site-packages/redis/client.py", line 3580, in subscribe
    ret_val = self.execute_command('SUBSCRIBE', *iterkeys(new_channels))
  File "/p/home/jusers/reck1/juwels/keksenv/lib/python3.8/site-packages/redis/client.py", line 3466, in execute_command
    self.connection = self.connection_pool.get_connection(
  File "/p/home/jusers/reck1/juwels/keksenv/lib/python3.8/site-packages/redis/connection.py", line 1192, in get_connection
    connection.connect()
  File "/p/home/jusers/reck1/juwels/keksenv/lib/python3.8/site-packages/redis/connection.py", line 563, in connect
    raise ConnectionError(self._error_message(e))
redis.exceptions.ConnectionError: Error -2 connecting to found::6358. Name or service not known.
INFO:Redis-Worker:Start redis worker. Max run time 86400.0s, HOST=jwc03n244.juwels, PID=20786
Process Process-46:
Traceback (most recent call last):
  File "/p/home/jusers/reck1/juwels/keksenv/lib/python3.8/site-packages/redis/connection.py", line 559, in connect
    sock = self._connect()
  File "/p/home/jusers/reck1/juwels/keksenv/lib/python3.8/site-packages/redis/connection.py", line 584, in _connect
    for res in socket.getaddrinfo(self.host, self.port, self.socket_type,
  File "/p/software/juwels/stages/2020/software/Python/3.8.5-GCCcore-9.3.0/lib/python3.8/socket.py", line 918, in getaddrinfo
    for res in _socket.getaddrinfo(host, port, family, type, proto, flags):
socket.gaierror: [Errno -2] Name or service not known

During handling of the above exception, another exception occurred:

Traceback (most recent call last):
  File "/p/software/juwels/stages/2020/software/Python/3.8.5-GCCcore-9.3.0/lib/python3.8/multiprocessing/process.py", line 315, in _bootstrap
    self.run()
  File "/p/software/juwels/stages/2020/software/Python/3.8.5-GCCcore-9.3.0/lib/python3.8/multiprocessing/process.py", line 108, in run
    self._target(*self._args, **self._kwargs)
  File "/p/home/jusers/reck1/juwels/pyABC/pyabc/sampler/redis_eps/cli.py", line 99, in _work
    p.subscribe(MSG)
  File "/p/home/jusers/reck1/juwels/keksenv/lib/python3.8/site-packages/redis/client.py", line 3580, in subscribe
    ret_val = self.execute_command('SUBSCRIBE', *iterkeys(new_channels))
  File "/p/home/jusers/reck1/juwels/keksenv/lib/python3.8/site-packages/redis/client.py", line 3466, in execute_command
    self.connection = self.connection_pool.get_connection(
  File "/p/home/jusers/reck1/juwels/keksenv/lib/python3.8/site-packages/redis/connection.py", line 1192, in get_connection
    connection.connect()
  File "/p/home/jusers/reck1/juwels/keksenv/lib/python3.8/site-packages/redis/connection.py", line 563, in connect
    raise ConnectionError(self._error_message(e))
redis.exceptions.ConnectionError: Error -2 connecting to found::6358. Name or service not known.
INFO:Redis-Worker:Start redis worker. Max run time 86400.0s, HOST=jwc03n244.juwels, PID=20787
Process Process-47:
Traceback (most recent call last):
  File "/p/home/jusers/reck1/juwels/keksenv/lib/python3.8/site-packages/redis/connection.py", line 559, in connect
    sock = self._connect()
  File "/p/home/jusers/reck1/juwels/keksenv/lib/python3.8/site-packages/redis/connection.py", line 584, in _connect
    for res in socket.getaddrinfo(self.host, self.port, self.socket_type,
  File "/p/software/juwels/stages/2020/software/Python/3.8.5-GCCcore-9.3.0/lib/python3.8/socket.py", line 918, in getaddrinfo
    for res in _socket.getaddrinfo(host, port, family, type, proto, flags):
socket.gaierror: [Errno -2] Name or service not known

During handling of the above exception, another exception occurred:

Traceback (most recent call last):
  File "/p/software/juwels/stages/2020/software/Python/3.8.5-GCCcore-9.3.0/lib/python3.8/multiprocessing/process.py", line 315, in _bootstrap
    self.run()
  File "/p/software/juwels/stages/2020/software/Python/3.8.5-GCCcore-9.3.0/lib/python3.8/multiprocessing/process.py", line 108, in run
    self._target(*self._args, **self._kwargs)
  File "/p/home/jusers/reck1/juwels/pyABC/pyabc/sampler/redis_eps/cli.py", line 99, in _work
    p.subscribe(MSG)
  File "/p/home/jusers/reck1/juwels/keksenv/lib/python3.8/site-packages/redis/client.py", line 3580, in subscribe
    ret_val = self.execute_command('SUBSCRIBE', *iterkeys(new_channels))
  File "/p/home/jusers/reck1/juwels/keksenv/lib/python3.8/site-packages/redis/client.py", line 3466, in execute_command
    self.connection = self.connection_pool.get_connection(
  File "/p/home/jusers/reck1/juwels/keksenv/lib/python3.8/site-packages/redis/connection.py", line 1192, in get_connection
    connection.connect()
  File "/p/home/jusers/reck1/juwels/keksenv/lib/python3.8/site-packages/redis/connection.py", line 563, in connect
    raise ConnectionError(self._error_message(e))
redis.exceptions.ConnectionError: Error -2 connecting to found::6358. Name or service not known.
INFO:Redis-Worker:Started subprocess with pid 20740
INFO:Redis-Worker:Started subprocess with pid 20741
INFO:Redis-Worker:Started subprocess with pid 20742
INFO:Redis-Worker:Started subprocess with pid 20743
INFO:Redis-Worker:Started subprocess with pid 20744
INFO:Redis-Worker:Started subprocess with pid 20745
INFO:Redis-Worker:Started subprocess with pid 20746
INFO:Redis-Worker:Started subprocess with pid 20747
INFO:Redis-Worker:Started subprocess with pid 20748
INFO:Redis-Worker:Started subprocess with pid 20749
INFO:Redis-Worker:Started subprocess with pid 20750
INFO:Redis-Worker:Started subprocess with pid 20751
INFO:Redis-Worker:Started subprocess with pid 20752
INFO:Redis-Worker:Started subprocess with pid 20753
INFO:Redis-Worker:Started subprocess with pid 20754
INFO:Redis-Worker:Started subprocess with pid 20755
INFO:Redis-Worker:Started subprocess with pid 20756
INFO:Redis-Worker:Started subprocess with pid 20757
INFO:Redis-Worker:Started subprocess with pid 20758
INFO:Redis-Worker:Started subprocess with pid 20759
INFO:Redis-Worker:Started subprocess with pid 20760
INFO:Redis-Worker:Started subprocess with pid 20761
INFO:Redis-Worker:Started subprocess with pid 20762
INFO:Redis-Worker:Started subprocess with pid 20763
INFO:Redis-Worker:Started subprocess with pid 20764
INFO:Redis-Worker:Started subprocess with pid 20765
INFO:Redis-Worker:Started subprocess with pid 20766
INFO:Redis-Worker:Started subprocess with pid 20767
INFO:Redis-Worker:Started subprocess with pid 20768
INFO:Redis-Worker:Started subprocess with pid 20769
INFO:Redis-Worker:Started subprocess with pid 20770
INFO:Redis-Worker:Started subprocess with pid 20771
INFO:Redis-Worker:Started subprocess with pid 20772
INFO:Redis-Worker:Started subprocess with pid 20773
INFO:Redis-Worker:Started subprocess with pid 20774
INFO:Redis-Worker:Started subprocess with pid 20775
INFO:Redis-Worker:Started subprocess with pid 20776
INFO:Redis-Worker:Started subprocess with pid 20777
INFO:Redis-Worker:Started subprocess with pid 20779
INFO:Redis-Worker:Started subprocess with pid 20780
INFO:Redis-Worker:Started subprocess with pid 20781
INFO:Redis-Worker:Started subprocess with pid 20782
INFO:Redis-Worker:Started subprocess with pid 20783
INFO:Redis-Worker:Started subprocess with pid 20784
INFO:Redis-Worker:Started subprocess with pid 20785
INFO:Redis-Worker:Started subprocess with pid 20786
INFO:Redis-Worker:Started subprocess with pid 20787
INFO:Redis-Worker:Started subprocess with pid 20788
INFO:Redis-Worker:Start redis worker. Max run time 86400.0s, HOST=jwc03n244.juwels, PID=20788
Process Process-48:
Traceback (most recent call last):
  File "/p/home/jusers/reck1/juwels/keksenv/lib/python3.8/site-packages/redis/connection.py", line 559, in connect
    sock = self._connect()
  File "/p/home/jusers/reck1/juwels/keksenv/lib/python3.8/site-packages/redis/connection.py", line 584, in _connect
    for res in socket.getaddrinfo(self.host, self.port, self.socket_type,
  File "/p/software/juwels/stages/2020/software/Python/3.8.5-GCCcore-9.3.0/lib/python3.8/socket.py", line 918, in getaddrinfo
    for res in _socket.getaddrinfo(host, port, family, type, proto, flags):
socket.gaierror: [Errno -2] Name or service not known

During handling of the above exception, another exception occurred:

Traceback (most recent call last):
  File "/p/software/juwels/stages/2020/software/Python/3.8.5-GCCcore-9.3.0/lib/python3.8/multiprocessing/process.py", line 315, in _bootstrap
    self.run()
  File "/p/software/juwels/stages/2020/software/Python/3.8.5-GCCcore-9.3.0/lib/python3.8/multiprocessing/process.py", line 108, in run
    self._target(*self._args, **self._kwargs)
  File "/p/home/jusers/reck1/juwels/pyABC/pyabc/sampler/redis_eps/cli.py", line 99, in _work
    p.subscribe(MSG)
  File "/p/home/jusers/reck1/juwels/keksenv/lib/python3.8/site-packages/redis/client.py", line 3580, in subscribe
    ret_val = self.execute_command('SUBSCRIBE', *iterkeys(new_channels))
  File "/p/home/jusers/reck1/juwels/keksenv/lib/python3.8/site-packages/redis/client.py", line 3466, in execute_command
    self.connection = self.connection_pool.get_connection(
  File "/p/home/jusers/reck1/juwels/keksenv/lib/python3.8/site-packages/redis/connection.py", line 1192, in get_connection
    connection.connect()
  File "/p/home/jusers/reck1/juwels/keksenv/lib/python3.8/site-packages/redis/connection.py", line 563, in connect
    raise ConnectionError(self._error_message(e))
redis.exceptions.ConnectionError: Error -2 connecting to found::6358. Name or service not known.
