#### This is the worker script job ####
INFO:Redis-Worker:Start redis worker. Max run time 86400.0s, HOST=jwc03n274.juwels, PID=28097
INFO:Redis-Worker:Start redis worker. Max run time 86400.0s, HOST=jwc03n274.juwels, PID=28098
INFO:Redis-Worker:Start redis worker. Max run time 86400.0s, HOST=jwc03n274.juwels, PID=28099
INFO:Redis-Worker:Start redis worker. Max run time 86400.0s, HOST=jwc03n274.juwels, PID=28100
INFO:Redis-Worker:Start redis worker. Max run time 86400.0s, HOST=jwc03n274.juwels, PID=28101
INFO:Redis-Worker:Start redis worker. Max run time 86400.0s, HOST=jwc03n274.juwels, PID=28102
INFO:Redis-Worker:Start redis worker. Max run time 86400.0s, HOST=jwc03n274.juwels, PID=28103
INFO:Redis-Worker:Start redis worker. Max run time 86400.0s, HOST=jwc03n274.juwels, PID=28104
INFO:Redis-Worker:Start redis worker. Max run time 86400.0s, HOST=jwc03n274.juwels, PID=28105
INFO:Redis-Worker:Start redis worker. Max run time 86400.0s, HOST=jwc03n274.juwels, PID=28106
INFO:Redis-Worker:Start redis worker. Max run time 86400.0s, HOST=jwc03n274.juwels, PID=28107
INFO:Redis-Worker:Start redis worker. Max run time 86400.0s, HOST=jwc03n274.juwels, PID=28108
INFO:Redis-Worker:Start redis worker. Max run time 86400.0s, HOST=jwc03n274.juwels, PID=28109
INFO:Redis-Worker:Start redis worker. Max run time 86400.0s, HOST=jwc03n274.juwels, PID=28110
INFO:Redis-Worker:Start redis worker. Max run time 86400.0s, HOST=jwc03n274.juwels, PID=28111
INFO:Redis-Worker:Start redis worker. Max run time 86400.0s, HOST=jwc03n274.juwels, PID=28112
Process Process-8:
Traceback (most recent call last):
  File "/p/home/jusers/reck1/juwels/keksenv/lib/python3.8/site-packages/redis/connection.py", line 559, in connect
    sock = self._connect()
  File "/p/home/jusers/reck1/juwels/keksenv/lib/python3.8/site-packages/redis/connection.py", line 584, in _connect
    for res in socket.getaddrinfo(self.host, self.port, self.socket_type,
  File "/p/software/juwels/stages/2020/software/Python/3.8.5-GCCcore-9.3.0/lib/python3.8/socket.py", line 918, in getaddrinfo
    for res in _socket.getaddrinfo(host, port, family, type, proto, flags):
socket.gaierror: [Errno -2] Name or service not known

During handling of the above exception, another exception occurred:

Traceback (most recent call last):
  File "/p/software/juwels/stages/2020/software/Python/3.8.5-GCCcore-9.3.0/lib/python3.8/multiprocessing/process.py", line 315, in _bootstrap
    self.run()
  File "/p/software/juwels/stages/2020/software/Python/3.8.5-GCCcore-9.3.0/lib/python3.8/multiprocessing/process.py", line 108, in run
    self._target(*self._args, **self._kwargs)
  File "/p/home/jusers/reck1/juwels/pyABC/pyabc/sampler/redis_eps/cli.py", line 99, in _work
    p.subscribe(MSG)
  File "/p/home/jusers/reck1/juwels/keksenv/lib/python3.8/site-packages/redis/client.py", line 3580, in subscribe
    ret_val = self.execute_command('SUBSCRIBE', *iterkeys(new_channels))
  File "/p/home/jusers/reck1/juwels/keksenv/lib/python3.8/site-packages/redis/client.py", line 3466, in execute_command
    self.connection = self.connection_pool.get_connection(
  File "/p/home/jusers/reck1/juwels/keksenv/lib/python3.8/site-packages/redis/connection.py", line 1192, in get_connection
    connection.connect()
  File "/p/home/jusers/reck1/juwels/keksenv/lib/python3.8/site-packages/redis/connection.py", line 563, in connect
    raise ConnectionError(self._error_message(e))
redis.exceptions.ConnectionError: Error -2 connecting to found::6358. Name or service not known.
Process Process-15:
Traceback (most recent call last):
  File "/p/home/jusers/reck1/juwels/keksenv/lib/python3.8/site-packages/redis/connection.py", line 559, in connect
    sock = self._connect()
  File "/p/home/jusers/reck1/juwels/keksenv/lib/python3.8/site-packages/redis/connection.py", line 584, in _connect
    for res in socket.getaddrinfo(self.host, self.port, self.socket_type,
  File "/p/software/juwels/stages/2020/software/Python/3.8.5-GCCcore-9.3.0/lib/python3.8/socket.py", line 918, in getaddrinfo
    for res in _socket.getaddrinfo(host, port, family, type, proto, flags):
socket.gaierror: [Errno -2] Name or service not known

During handling of the above exception, another exception occurred:

Traceback (most recent call last):
  File "/p/software/juwels/stages/2020/software/Python/3.8.5-GCCcore-9.3.0/lib/python3.8/multiprocessing/process.py", line 315, in _bootstrap
    self.run()
  File "/p/software/juwels/stages/2020/software/Python/3.8.5-GCCcore-9.3.0/lib/python3.8/multiprocessing/process.py", line 108, in run
    self._target(*self._args, **self._kwargs)
  File "/p/home/jusers/reck1/juwels/pyABC/pyabc/sampler/redis_eps/cli.py", line 99, in _work
    p.subscribe(MSG)
  File "/p/home/jusers/reck1/juwels/keksenv/lib/python3.8/site-packages/redis/client.py", line 3580, in subscribe
    ret_val = self.execute_command('SUBSCRIBE', *iterkeys(new_channels))
  File "/p/home/jusers/reck1/juwels/keksenv/lib/python3.8/site-packages/redis/client.py", line 3466, in execute_command
    self.connection = self.connection_pool.get_connection(
  File "/p/home/jusers/reck1/juwels/keksenv/lib/python3.8/site-packages/redis/connection.py", line 1192, in get_connection
    connection.connect()
  File "/p/home/jusers/reck1/juwels/keksenv/lib/python3.8/site-packages/redis/connection.py", line 563, in connect
    raise ConnectionError(self._error_message(e))
redis.exceptions.ConnectionError: Error -2 connecting to found::6358. Name or service not known.
Process Process-12:
Traceback (most recent call last):
  File "/p/home/jusers/reck1/juwels/keksenv/lib/python3.8/site-packages/redis/connection.py", line 559, in connect
    sock = self._connect()
  File "/p/home/jusers/reck1/juwels/keksenv/lib/python3.8/site-packages/redis/connection.py", line 584, in _connect
    for res in socket.getaddrinfo(self.host, self.port, self.socket_type,
  File "/p/software/juwels/stages/2020/software/Python/3.8.5-GCCcore-9.3.0/lib/python3.8/socket.py", line 918, in getaddrinfo
    for res in _socket.getaddrinfo(host, port, family, type, proto, flags):
socket.gaierror: [Errno -2] Name or service not known

During handling of the above exception, another exception occurred:

Traceback (most recent call last):
  File "/p/software/juwels/stages/2020/software/Python/3.8.5-GCCcore-9.3.0/lib/python3.8/multiprocessing/process.py", line 315, in _bootstrap
    self.run()
  File "/p/software/juwels/stages/2020/software/Python/3.8.5-GCCcore-9.3.0/lib/python3.8/multiprocessing/process.py", line 108, in run
    self._target(*self._args, **self._kwargs)
  File "/p/home/jusers/reck1/juwels/pyABC/pyabc/sampler/redis_eps/cli.py", line 99, in _work
    p.subscribe(MSG)
  File "/p/home/jusers/reck1/juwels/keksenv/lib/python3.8/site-packages/redis/client.py", line 3580, in subscribe
    ret_val = self.execute_command('SUBSCRIBE', *iterkeys(new_channels))
  File "/p/home/jusers/reck1/juwels/keksenv/lib/python3.8/site-packages/redis/client.py", line 3466, in execute_command
    self.connection = self.connection_pool.get_connection(
  File "/p/home/jusers/reck1/juwels/keksenv/lib/python3.8/site-packages/redis/connection.py", line 1192, in get_connection
    connection.connect()
  File "/p/home/jusers/reck1/juwels/keksenv/lib/python3.8/site-packages/redis/connection.py", line 563, in connect
    raise ConnectionError(self._error_message(e))
redis.exceptions.ConnectionError: Error -2 connecting to found::6358. Name or service not known.
Process Process-5:
Traceback (most recent call last):
  File "/p/home/jusers/reck1/juwels/keksenv/lib/python3.8/site-packages/redis/connection.py", line 559, in connect
    sock = self._connect()
  File "/p/home/jusers/reck1/juwels/keksenv/lib/python3.8/site-packages/redis/connection.py", line 584, in _connect
    for res in socket.getaddrinfo(self.host, self.port, self.socket_type,
  File "/p/software/juwels/stages/2020/software/Python/3.8.5-GCCcore-9.3.0/lib/python3.8/socket.py", line 918, in getaddrinfo
    for res in _socket.getaddrinfo(host, port, family, type, proto, flags):
socket.gaierror: [Errno -2] Name or service not known

During handling of the above exception, another exception occurred:

Traceback (most recent call last):
  File "/p/software/juwels/stages/2020/software/Python/3.8.5-GCCcore-9.3.0/lib/python3.8/multiprocessing/process.py", line 315, in _bootstrap
    self.run()
  File "/p/software/juwels/stages/2020/software/Python/3.8.5-GCCcore-9.3.0/lib/python3.8/multiprocessing/process.py", line 108, in run
    self._target(*self._args, **self._kwargs)
  File "/p/home/jusers/reck1/juwels/pyABC/pyabc/sampler/redis_eps/cli.py", line 99, in _work
    p.subscribe(MSG)
  File "/p/home/jusers/reck1/juwels/keksenv/lib/python3.8/site-packages/redis/client.py", line 3580, in subscribe
    ret_val = self.execute_command('SUBSCRIBE', *iterkeys(new_channels))
  File "/p/home/jusers/reck1/juwels/keksenv/lib/python3.8/site-packages/redis/client.py", line 3466, in execute_command
    self.connection = self.connection_pool.get_connection(
  File "/p/home/jusers/reck1/juwels/keksenv/lib/python3.8/site-packages/redis/connection.py", line 1192, in get_connection
    connection.connect()
  File "/p/home/jusers/reck1/juwels/keksenv/lib/python3.8/site-packages/redis/connection.py", line 563, in connect
    raise ConnectionError(self._error_message(e))
redis.exceptions.ConnectionError: Error -2 connecting to found::6358. Name or service not known.
Process Process-14:
Traceback (most recent call last):
  File "/p/home/jusers/reck1/juwels/keksenv/lib/python3.8/site-packages/redis/connection.py", line 559, in connect
    sock = self._connect()
  File "/p/home/jusers/reck1/juwels/keksenv/lib/python3.8/site-packages/redis/connection.py", line 584, in _connect
    for res in socket.getaddrinfo(self.host, self.port, self.socket_type,
  File "/p/software/juwels/stages/2020/software/Python/3.8.5-GCCcore-9.3.0/lib/python3.8/socket.py", line 918, in getaddrinfo
    for res in _socket.getaddrinfo(host, port, family, type, proto, flags):
socket.gaierror: [Errno -2] Name or service not known

During handling of the above exception, another exception occurred:

Traceback (most recent call last):
  File "/p/software/juwels/stages/2020/software/Python/3.8.5-GCCcore-9.3.0/lib/python3.8/multiprocessing/process.py", line 315, in _bootstrap
    self.run()
  File "/p/software/juwels/stages/2020/software/Python/3.8.5-GCCcore-9.3.0/lib/python3.8/multiprocessing/process.py", line 108, in run
    self._target(*self._args, **self._kwargs)
  File "/p/home/jusers/reck1/juwels/pyABC/pyabc/sampler/redis_eps/cli.py", line 99, in _work
    p.subscribe(MSG)
  File "/p/home/jusers/reck1/juwels/keksenv/lib/python3.8/site-packages/redis/client.py", line 3580, in subscribe
    ret_val = self.execute_command('SUBSCRIBE', *iterkeys(new_channels))
  File "/p/home/jusers/reck1/juwels/keksenv/lib/python3.8/site-packages/redis/client.py", line 3466, in execute_command
    self.connection = self.connection_pool.get_connection(
  File "/p/home/jusers/reck1/juwels/keksenv/lib/python3.8/site-packages/redis/connection.py", line 1192, in get_connection
    connection.connect()
  File "/p/home/jusers/reck1/juwels/keksenv/lib/python3.8/site-packages/redis/connection.py", line 563, in connect
    raise ConnectionError(self._error_message(e))
redis.exceptions.ConnectionError: Error -2 connecting to found::6358. Name or service not known.
Process Process-13:
Traceback (most recent call last):
  File "/p/home/jusers/reck1/juwels/keksenv/lib/python3.8/site-packages/redis/connection.py", line 559, in connect
    sock = self._connect()
  File "/p/home/jusers/reck1/juwels/keksenv/lib/python3.8/site-packages/redis/connection.py", line 584, in _connect
    for res in socket.getaddrinfo(self.host, self.port, self.socket_type,
  File "/p/software/juwels/stages/2020/software/Python/3.8.5-GCCcore-9.3.0/lib/python3.8/socket.py", line 918, in getaddrinfo
    for res in _socket.getaddrinfo(host, port, family, type, proto, flags):
socket.gaierror: [Errno -2] Name or service not known

During handling of the above exception, another exception occurred:

Traceback (most recent call last):
  File "/p/software/juwels/stages/2020/software/Python/3.8.5-GCCcore-9.3.0/lib/python3.8/multiprocessing/process.py", line 315, in _bootstrap
    self.run()
  File "/p/software/juwels/stages/2020/software/Python/3.8.5-GCCcore-9.3.0/lib/python3.8/multiprocessing/process.py", line 108, in run
    self._target(*self._args, **self._kwargs)
  File "/p/home/jusers/reck1/juwels/pyABC/pyabc/sampler/redis_eps/cli.py", line 99, in _work
    p.subscribe(MSG)
  File "/p/home/jusers/reck1/juwels/keksenv/lib/python3.8/site-packages/redis/client.py", line 3580, in subscribe
    ret_val = self.execute_command('SUBSCRIBE', *iterkeys(new_channels))
  File "/p/home/jusers/reck1/juwels/keksenv/lib/python3.8/site-packages/redis/client.py", line 3466, in execute_command
    self.connection = self.connection_pool.get_connection(
  File "/p/home/jusers/reck1/juwels/keksenv/lib/python3.8/site-packages/redis/connection.py", line 1192, in get_connection
    connection.connect()
  File "/p/home/jusers/reck1/juwels/keksenv/lib/python3.8/site-packages/redis/connection.py", line 563, in connect
    raise ConnectionError(self._error_message(e))
redis.exceptions.ConnectionError: Error -2 connecting to found::6358. Name or service not known.
Process Process-4:
Traceback (most recent call last):
  File "/p/home/jusers/reck1/juwels/keksenv/lib/python3.8/site-packages/redis/connection.py", line 559, in connect
    sock = self._connect()
  File "/p/home/jusers/reck1/juwels/keksenv/lib/python3.8/site-packages/redis/connection.py", line 584, in _connect
    for res in socket.getaddrinfo(self.host, self.port, self.socket_type,
  File "/p/software/juwels/stages/2020/software/Python/3.8.5-GCCcore-9.3.0/lib/python3.8/socket.py", line 918, in getaddrinfo
    for res in _socket.getaddrinfo(host, port, family, type, proto, flags):
socket.gaierror: [Errno -2] Name or service not known

During handling of the above exception, another exception occurred:

Traceback (most recent call last):
  File "/p/software/juwels/stages/2020/software/Python/3.8.5-GCCcore-9.3.0/lib/python3.8/multiprocessing/process.py", line 315, in _bootstrap
    self.run()
  File "/p/software/juwels/stages/2020/software/Python/3.8.5-GCCcore-9.3.0/lib/python3.8/multiprocessing/process.py", line 108, in run
    self._target(*self._args, **self._kwargs)
  File "/p/home/jusers/reck1/juwels/pyABC/pyabc/sampler/redis_eps/cli.py", line 99, in _work
    p.subscribe(MSG)
  File "/p/home/jusers/reck1/juwels/keksenv/lib/python3.8/site-packages/redis/client.py", line 3580, in subscribe
    ret_val = self.execute_command('SUBSCRIBE', *iterkeys(new_channels))
  File "/p/home/jusers/reck1/juwels/keksenv/lib/python3.8/site-packages/redis/client.py", line 3466, in execute_command
    self.connection = self.connection_pool.get_connection(
  File "/p/home/jusers/reck1/juwels/keksenv/lib/python3.8/site-packages/redis/connection.py", line 1192, in get_connection
    connection.connect()
  File "/p/home/jusers/reck1/juwels/keksenv/lib/python3.8/site-packages/redis/connection.py", line 563, in connect
    raise ConnectionError(self._error_message(e))
redis.exceptions.ConnectionError: Error -2 connecting to found::6358. Name or service not known.
Process Process-3:
Traceback (most recent call last):
  File "/p/home/jusers/reck1/juwels/keksenv/lib/python3.8/site-packages/redis/connection.py", line 559, in connect
    sock = self._connect()
  File "/p/home/jusers/reck1/juwels/keksenv/lib/python3.8/site-packages/redis/connection.py", line 584, in _connect
    for res in socket.getaddrinfo(self.host, self.port, self.socket_type,
  File "/p/software/juwels/stages/2020/software/Python/3.8.5-GCCcore-9.3.0/lib/python3.8/socket.py", line 918, in getaddrinfo
    for res in _socket.getaddrinfo(host, port, family, type, proto, flags):
socket.gaierror: [Errno -2] Name or service not known

During handling of the above exception, another exception occurred:

Traceback (most recent call last):
  File "/p/software/juwels/stages/2020/software/Python/3.8.5-GCCcore-9.3.0/lib/python3.8/multiprocessing/process.py", line 315, in _bootstrap
    self.run()
  File "/p/software/juwels/stages/2020/software/Python/3.8.5-GCCcore-9.3.0/lib/python3.8/multiprocessing/process.py", line 108, in run
    self._target(*self._args, **self._kwargs)
  File "/p/home/jusers/reck1/juwels/pyABC/pyabc/sampler/redis_eps/cli.py", line 99, in _work
    p.subscribe(MSG)
  File "/p/home/jusers/reck1/juwels/keksenv/lib/python3.8/site-packages/redis/client.py", line 3580, in subscribe
    ret_val = self.execute_command('SUBSCRIBE', *iterkeys(new_channels))
  File "/p/home/jusers/reck1/juwels/keksenv/lib/python3.8/site-packages/redis/client.py", line 3466, in execute_command
    self.connection = self.connection_pool.get_connection(
  File "/p/home/jusers/reck1/juwels/keksenv/lib/python3.8/site-packages/redis/connection.py", line 1192, in get_connection
    connection.connect()
  File "/p/home/jusers/reck1/juwels/keksenv/lib/python3.8/site-packages/redis/connection.py", line 563, in connect
    raise ConnectionError(self._error_message(e))
redis.exceptions.ConnectionError: Error -2 connecting to found::6358. Name or service not known.
Process Process-2:
Traceback (most recent call last):
  File "/p/home/jusers/reck1/juwels/keksenv/lib/python3.8/site-packages/redis/connection.py", line 559, in connect
    sock = self._connect()
  File "/p/home/jusers/reck1/juwels/keksenv/lib/python3.8/site-packages/redis/connection.py", line 584, in _connect
    for res in socket.getaddrinfo(self.host, self.port, self.socket_type,
  File "/p/software/juwels/stages/2020/software/Python/3.8.5-GCCcore-9.3.0/lib/python3.8/socket.py", line 918, in getaddrinfo
    for res in _socket.getaddrinfo(host, port, family, type, proto, flags):
socket.gaierror: [Errno -2] Name or service not known

During handling of the above exception, another exception occurred:

Traceback (most recent call last):
  File "/p/software/juwels/stages/2020/software/Python/3.8.5-GCCcore-9.3.0/lib/python3.8/multiprocessing/process.py", line 315, in _bootstrap
    self.run()
  File "/p/software/juwels/stages/2020/software/Python/3.8.5-GCCcore-9.3.0/lib/python3.8/multiprocessing/process.py", line 108, in run
    self._target(*self._args, **self._kwargs)
  File "/p/home/jusers/reck1/juwels/pyABC/pyabc/sampler/redis_eps/cli.py", line 99, in _work
    p.subscribe(MSG)
  File "/p/home/jusers/reck1/juwels/keksenv/lib/python3.8/site-packages/redis/client.py", line 3580, in subscribe
    ret_val = self.execute_command('SUBSCRIBE', *iterkeys(new_channels))
  File "/p/home/jusers/reck1/juwels/keksenv/lib/python3.8/site-packages/redis/client.py", line 3466, in execute_command
    self.connection = self.connection_pool.get_connection(
  File "/p/home/jusers/reck1/juwels/keksenv/lib/python3.8/site-packages/redis/connection.py", line 1192, in get_connection
    connection.connect()
  File "/p/home/jusers/reck1/juwels/keksenv/lib/python3.8/site-packages/redis/connection.py", line 563, in connect
    raise ConnectionError(self._error_message(e))
redis.exceptions.ConnectionError: Error -2 connecting to found::6358. Name or service not known.
Process Process-11:
Traceback (most recent call last):
  File "/p/home/jusers/reck1/juwels/keksenv/lib/python3.8/site-packages/redis/connection.py", line 559, in connect
    sock = self._connect()
  File "/p/home/jusers/reck1/juwels/keksenv/lib/python3.8/site-packages/redis/connection.py", line 584, in _connect
    for res in socket.getaddrinfo(self.host, self.port, self.socket_type,
  File "/p/software/juwels/stages/2020/software/Python/3.8.5-GCCcore-9.3.0/lib/python3.8/socket.py", line 918, in getaddrinfo
    for res in _socket.getaddrinfo(host, port, family, type, proto, flags):
socket.gaierror: [Errno -2] Name or service not known

During handling of the above exception, another exception occurred:

Traceback (most recent call last):
  File "/p/software/juwels/stages/2020/software/Python/3.8.5-GCCcore-9.3.0/lib/python3.8/multiprocessing/process.py", line 315, in _bootstrap
    self.run()
  File "/p/software/juwels/stages/2020/software/Python/3.8.5-GCCcore-9.3.0/lib/python3.8/multiprocessing/process.py", line 108, in run
    self._target(*self._args, **self._kwargs)
  File "/p/home/jusers/reck1/juwels/pyABC/pyabc/sampler/redis_eps/cli.py", line 99, in _work
    p.subscribe(MSG)
  File "/p/home/jusers/reck1/juwels/keksenv/lib/python3.8/site-packages/redis/client.py", line 3580, in subscribe
    ret_val = self.execute_command('SUBSCRIBE', *iterkeys(new_channels))
  File "/p/home/jusers/reck1/juwels/keksenv/lib/python3.8/site-packages/redis/client.py", line 3466, in execute_command
    self.connection = self.connection_pool.get_connection(
  File "/p/home/jusers/reck1/juwels/keksenv/lib/python3.8/site-packages/redis/connection.py", line 1192, in get_connection
    connection.connect()
  File "/p/home/jusers/reck1/juwels/keksenv/lib/python3.8/site-packages/redis/connection.py", line 563, in connect
    raise ConnectionError(self._error_message(e))
redis.exceptions.ConnectionError: Error -2 connecting to found::6358. Name or service not known.
Process Process-6:
Traceback (most recent call last):
  File "/p/home/jusers/reck1/juwels/keksenv/lib/python3.8/site-packages/redis/connection.py", line 559, in connect
    sock = self._connect()
  File "/p/home/jusers/reck1/juwels/keksenv/lib/python3.8/site-packages/redis/connection.py", line 584, in _connect
    for res in socket.getaddrinfo(self.host, self.port, self.socket_type,
  File "/p/software/juwels/stages/2020/software/Python/3.8.5-GCCcore-9.3.0/lib/python3.8/socket.py", line 918, in getaddrinfo
    for res in _socket.getaddrinfo(host, port, family, type, proto, flags):
socket.gaierror: [Errno -2] Name or service not known

During handling of the above exception, another exception occurred:

Traceback (most recent call last):
  File "/p/software/juwels/stages/2020/software/Python/3.8.5-GCCcore-9.3.0/lib/python3.8/multiprocessing/process.py", line 315, in _bootstrap
    self.run()
  File "/p/software/juwels/stages/2020/software/Python/3.8.5-GCCcore-9.3.0/lib/python3.8/multiprocessing/process.py", line 108, in run
    self._target(*self._args, **self._kwargs)
  File "/p/home/jusers/reck1/juwels/pyABC/pyabc/sampler/redis_eps/cli.py", line 99, in _work
    p.subscribe(MSG)
  File "/p/home/jusers/reck1/juwels/keksenv/lib/python3.8/site-packages/redis/client.py", line 3580, in subscribe
    ret_val = self.execute_command('SUBSCRIBE', *iterkeys(new_channels))
  File "/p/home/jusers/reck1/juwels/keksenv/lib/python3.8/site-packages/redis/client.py", line 3466, in execute_command
    self.connection = self.connection_pool.get_connection(
  File "/p/home/jusers/reck1/juwels/keksenv/lib/python3.8/site-packages/redis/connection.py", line 1192, in get_connection
    connection.connect()
  File "/p/home/jusers/reck1/juwels/keksenv/lib/python3.8/site-packages/redis/connection.py", line 563, in connect
    raise ConnectionError(self._error_message(e))
redis.exceptions.ConnectionError: Error -2 connecting to found::6358. Name or service not known.
Process Process-10:
Traceback (most recent call last):
  File "/p/home/jusers/reck1/juwels/keksenv/lib/python3.8/site-packages/redis/connection.py", line 559, in connect
    sock = self._connect()
  File "/p/home/jusers/reck1/juwels/keksenv/lib/python3.8/site-packages/redis/connection.py", line 584, in _connect
    for res in socket.getaddrinfo(self.host, self.port, self.socket_type,
  File "/p/software/juwels/stages/2020/software/Python/3.8.5-GCCcore-9.3.0/lib/python3.8/socket.py", line 918, in getaddrinfo
    for res in _socket.getaddrinfo(host, port, family, type, proto, flags):
socket.gaierror: [Errno -2] Name or service not known

During handling of the above exception, another exception occurred:

Traceback (most recent call last):
  File "/p/software/juwels/stages/2020/software/Python/3.8.5-GCCcore-9.3.0/lib/python3.8/multiprocessing/process.py", line 315, in _bootstrap
    self.run()
  File "/p/software/juwels/stages/2020/software/Python/3.8.5-GCCcore-9.3.0/lib/python3.8/multiprocessing/process.py", line 108, in run
    self._target(*self._args, **self._kwargs)
  File "/p/home/jusers/reck1/juwels/pyABC/pyabc/sampler/redis_eps/cli.py", line 99, in _work
    p.subscribe(MSG)
  File "/p/home/jusers/reck1/juwels/keksenv/lib/python3.8/site-packages/redis/client.py", line 3580, in subscribe
    ret_val = self.execute_command('SUBSCRIBE', *iterkeys(new_channels))
  File "/p/home/jusers/reck1/juwels/keksenv/lib/python3.8/site-packages/redis/client.py", line 3466, in execute_command
    self.connection = self.connection_pool.get_connection(
  File "/p/home/jusers/reck1/juwels/keksenv/lib/python3.8/site-packages/redis/connection.py", line 1192, in get_connection
    connection.connect()
  File "/p/home/jusers/reck1/juwels/keksenv/lib/python3.8/site-packages/redis/connection.py", line 563, in connect
    raise ConnectionError(self._error_message(e))
redis.exceptions.ConnectionError: Error -2 connecting to found::6358. Name or service not known.
Process Process-1:
Traceback (most recent call last):
  File "/p/home/jusers/reck1/juwels/keksenv/lib/python3.8/site-packages/redis/connection.py", line 559, in connect
    sock = self._connect()
  File "/p/home/jusers/reck1/juwels/keksenv/lib/python3.8/site-packages/redis/connection.py", line 584, in _connect
    for res in socket.getaddrinfo(self.host, self.port, self.socket_type,
  File "/p/software/juwels/stages/2020/software/Python/3.8.5-GCCcore-9.3.0/lib/python3.8/socket.py", line 918, in getaddrinfo
    for res in _socket.getaddrinfo(host, port, family, type, proto, flags):
socket.gaierror: [Errno -2] Name or service not known

During handling of the above exception, another exception occurred:

Traceback (most recent call last):
  File "/p/software/juwels/stages/2020/software/Python/3.8.5-GCCcore-9.3.0/lib/python3.8/multiprocessing/process.py", line 315, in _bootstrap
    self.run()
  File "/p/software/juwels/stages/2020/software/Python/3.8.5-GCCcore-9.3.0/lib/python3.8/multiprocessing/process.py", line 108, in run
    self._target(*self._args, **self._kwargs)
  File "/p/home/jusers/reck1/juwels/pyABC/pyabc/sampler/redis_eps/cli.py", line 99, in _work
    p.subscribe(MSG)
  File "/p/home/jusers/reck1/juwels/keksenv/lib/python3.8/site-packages/redis/client.py", line 3580, in subscribe
    ret_val = self.execute_command('SUBSCRIBE', *iterkeys(new_channels))
  File "/p/home/jusers/reck1/juwels/keksenv/lib/python3.8/site-packages/redis/client.py", line 3466, in execute_command
    self.connection = self.connection_pool.get_connection(
  File "/p/home/jusers/reck1/juwels/keksenv/lib/python3.8/site-packages/redis/connection.py", line 1192, in get_connection
    connection.connect()
  File "/p/home/jusers/reck1/juwels/keksenv/lib/python3.8/site-packages/redis/connection.py", line 563, in connect
    raise ConnectionError(self._error_message(e))
redis.exceptions.ConnectionError: Error -2 connecting to found::6358. Name or service not known.
Process Process-7:
Traceback (most recent call last):
  File "/p/home/jusers/reck1/juwels/keksenv/lib/python3.8/site-packages/redis/connection.py", line 559, in connect
    sock = self._connect()
  File "/p/home/jusers/reck1/juwels/keksenv/lib/python3.8/site-packages/redis/connection.py", line 584, in _connect
    for res in socket.getaddrinfo(self.host, self.port, self.socket_type,
  File "/p/software/juwels/stages/2020/software/Python/3.8.5-GCCcore-9.3.0/lib/python3.8/socket.py", line 918, in getaddrinfo
    for res in _socket.getaddrinfo(host, port, family, type, proto, flags):
socket.gaierror: [Errno -2] Name or service not known

During handling of the above exception, another exception occurred:

Traceback (most recent call last):
  File "/p/software/juwels/stages/2020/software/Python/3.8.5-GCCcore-9.3.0/lib/python3.8/multiprocessing/process.py", line 315, in _bootstrap
    self.run()
  File "/p/software/juwels/stages/2020/software/Python/3.8.5-GCCcore-9.3.0/lib/python3.8/multiprocessing/process.py", line 108, in run
    self._target(*self._args, **self._kwargs)
  File "/p/home/jusers/reck1/juwels/pyABC/pyabc/sampler/redis_eps/cli.py", line 99, in _work
    p.subscribe(MSG)
  File "/p/home/jusers/reck1/juwels/keksenv/lib/python3.8/site-packages/redis/client.py", line 3580, in subscribe
    ret_val = self.execute_command('SUBSCRIBE', *iterkeys(new_channels))
  File "/p/home/jusers/reck1/juwels/keksenv/lib/python3.8/site-packages/redis/client.py", line 3466, in execute_command
    self.connection = self.connection_pool.get_connection(
  File "/p/home/jusers/reck1/juwels/keksenv/lib/python3.8/site-packages/redis/connection.py", line 1192, in get_connection
    connection.connect()
  File "/p/home/jusers/reck1/juwels/keksenv/lib/python3.8/site-packages/redis/connection.py", line 563, in connect
    raise ConnectionError(self._error_message(e))
redis.exceptions.ConnectionError: Error -2 connecting to found::6358. Name or service not known.
Process Process-9:
Traceback (most recent call last):
  File "/p/home/jusers/reck1/juwels/keksenv/lib/python3.8/site-packages/redis/connection.py", line 559, in connect
    sock = self._connect()
  File "/p/home/jusers/reck1/juwels/keksenv/lib/python3.8/site-packages/redis/connection.py", line 584, in _connect
    for res in socket.getaddrinfo(self.host, self.port, self.socket_type,
  File "/p/software/juwels/stages/2020/software/Python/3.8.5-GCCcore-9.3.0/lib/python3.8/socket.py", line 918, in getaddrinfo
    for res in _socket.getaddrinfo(host, port, family, type, proto, flags):
socket.gaierror: [Errno -2] Name or service not known

During handling of the above exception, another exception occurred:

Traceback (most recent call last):
  File "/p/software/juwels/stages/2020/software/Python/3.8.5-GCCcore-9.3.0/lib/python3.8/multiprocessing/process.py", line 315, in _bootstrap
    self.run()
  File "/p/software/juwels/stages/2020/software/Python/3.8.5-GCCcore-9.3.0/lib/python3.8/multiprocessing/process.py", line 108, in run
    self._target(*self._args, **self._kwargs)
  File "/p/home/jusers/reck1/juwels/pyABC/pyabc/sampler/redis_eps/cli.py", line 99, in _work
    p.subscribe(MSG)
  File "/p/home/jusers/reck1/juwels/keksenv/lib/python3.8/site-packages/redis/client.py", line 3580, in subscribe
    ret_val = self.execute_command('SUBSCRIBE', *iterkeys(new_channels))
  File "/p/home/jusers/reck1/juwels/keksenv/lib/python3.8/site-packages/redis/client.py", line 3466, in execute_command
    self.connection = self.connection_pool.get_connection(
  File "/p/home/jusers/reck1/juwels/keksenv/lib/python3.8/site-packages/redis/connection.py", line 1192, in get_connection
    connection.connect()
  File "/p/home/jusers/reck1/juwels/keksenv/lib/python3.8/site-packages/redis/connection.py", line 563, in connect
    raise ConnectionError(self._error_message(e))
redis.exceptions.ConnectionError: Error -2 connecting to found::6358. Name or service not known.
Process Process-16:
Traceback (most recent call last):
  File "/p/home/jusers/reck1/juwels/keksenv/lib/python3.8/site-packages/redis/connection.py", line 559, in connect
    sock = self._connect()
  File "/p/home/jusers/reck1/juwels/keksenv/lib/python3.8/site-packages/redis/connection.py", line 584, in _connect
    for res in socket.getaddrinfo(self.host, self.port, self.socket_type,
  File "/p/software/juwels/stages/2020/software/Python/3.8.5-GCCcore-9.3.0/lib/python3.8/socket.py", line 918, in getaddrinfo
    for res in _socket.getaddrinfo(host, port, family, type, proto, flags):
socket.gaierror: [Errno -2] Name or service not known

During handling of the above exception, another exception occurred:

Traceback (most recent call last):
  File "/p/software/juwels/stages/2020/software/Python/3.8.5-GCCcore-9.3.0/lib/python3.8/multiprocessing/process.py", line 315, in _bootstrap
    self.run()
  File "/p/software/juwels/stages/2020/software/Python/3.8.5-GCCcore-9.3.0/lib/python3.8/multiprocessing/process.py", line 108, in run
    self._target(*self._args, **self._kwargs)
  File "/p/home/jusers/reck1/juwels/pyABC/pyabc/sampler/redis_eps/cli.py", line 99, in _work
    p.subscribe(MSG)
  File "/p/home/jusers/reck1/juwels/keksenv/lib/python3.8/site-packages/redis/client.py", line 3580, in subscribe
    ret_val = self.execute_command('SUBSCRIBE', *iterkeys(new_channels))
  File "/p/home/jusers/reck1/juwels/keksenv/lib/python3.8/site-packages/redis/client.py", line 3466, in execute_command
    self.connection = self.connection_pool.get_connection(
  File "/p/home/jusers/reck1/juwels/keksenv/lib/python3.8/site-packages/redis/connection.py", line 1192, in get_connection
    connection.connect()
  File "/p/home/jusers/reck1/juwels/keksenv/lib/python3.8/site-packages/redis/connection.py", line 563, in connect
    raise ConnectionError(self._error_message(e))
redis.exceptions.ConnectionError: Error -2 connecting to found::6358. Name or service not known.
INFO:Redis-Worker:Start redis worker. Max run time 86400.0s, HOST=jwc03n274.juwels, PID=28113
Process Process-17:
Traceback (most recent call last):
  File "/p/home/jusers/reck1/juwels/keksenv/lib/python3.8/site-packages/redis/connection.py", line 559, in connect
    sock = self._connect()
  File "/p/home/jusers/reck1/juwels/keksenv/lib/python3.8/site-packages/redis/connection.py", line 584, in _connect
    for res in socket.getaddrinfo(self.host, self.port, self.socket_type,
  File "/p/software/juwels/stages/2020/software/Python/3.8.5-GCCcore-9.3.0/lib/python3.8/socket.py", line 918, in getaddrinfo
    for res in _socket.getaddrinfo(host, port, family, type, proto, flags):
socket.gaierror: [Errno -2] Name or service not known

During handling of the above exception, another exception occurred:

Traceback (most recent call last):
  File "/p/software/juwels/stages/2020/software/Python/3.8.5-GCCcore-9.3.0/lib/python3.8/multiprocessing/process.py", line 315, in _bootstrap
    self.run()
  File "/p/software/juwels/stages/2020/software/Python/3.8.5-GCCcore-9.3.0/lib/python3.8/multiprocessing/process.py", line 108, in run
    self._target(*self._args, **self._kwargs)
  File "/p/home/jusers/reck1/juwels/pyABC/pyabc/sampler/redis_eps/cli.py", line 99, in _work
    p.subscribe(MSG)
  File "/p/home/jusers/reck1/juwels/keksenv/lib/python3.8/site-packages/redis/client.py", line 3580, in subscribe
    ret_val = self.execute_command('SUBSCRIBE', *iterkeys(new_channels))
  File "/p/home/jusers/reck1/juwels/keksenv/lib/python3.8/site-packages/redis/client.py", line 3466, in execute_command
    self.connection = self.connection_pool.get_connection(
  File "/p/home/jusers/reck1/juwels/keksenv/lib/python3.8/site-packages/redis/connection.py", line 1192, in get_connection
    connection.connect()
  File "/p/home/jusers/reck1/juwels/keksenv/lib/python3.8/site-packages/redis/connection.py", line 563, in connect
    raise ConnectionError(self._error_message(e))
redis.exceptions.ConnectionError: Error -2 connecting to found::6358. Name or service not known.
INFO:Redis-Worker:Start redis worker. Max run time 86400.0s, HOST=jwc03n274.juwels, PID=28114
Process Process-18:
Traceback (most recent call last):
  File "/p/home/jusers/reck1/juwels/keksenv/lib/python3.8/site-packages/redis/connection.py", line 559, in connect
    sock = self._connect()
  File "/p/home/jusers/reck1/juwels/keksenv/lib/python3.8/site-packages/redis/connection.py", line 584, in _connect
    for res in socket.getaddrinfo(self.host, self.port, self.socket_type,
  File "/p/software/juwels/stages/2020/software/Python/3.8.5-GCCcore-9.3.0/lib/python3.8/socket.py", line 918, in getaddrinfo
    for res in _socket.getaddrinfo(host, port, family, type, proto, flags):
socket.gaierror: [Errno -2] Name or service not known

During handling of the above exception, another exception occurred:

Traceback (most recent call last):
  File "/p/software/juwels/stages/2020/software/Python/3.8.5-GCCcore-9.3.0/lib/python3.8/multiprocessing/process.py", line 315, in _bootstrap
    self.run()
  File "/p/software/juwels/stages/2020/software/Python/3.8.5-GCCcore-9.3.0/lib/python3.8/multiprocessing/process.py", line 108, in run
    self._target(*self._args, **self._kwargs)
  File "/p/home/jusers/reck1/juwels/pyABC/pyabc/sampler/redis_eps/cli.py", line 99, in _work
    p.subscribe(MSG)
  File "/p/home/jusers/reck1/juwels/keksenv/lib/python3.8/site-packages/redis/client.py", line 3580, in subscribe
    ret_val = self.execute_command('SUBSCRIBE', *iterkeys(new_channels))
  File "/p/home/jusers/reck1/juwels/keksenv/lib/python3.8/site-packages/redis/client.py", line 3466, in execute_command
    self.connection = self.connection_pool.get_connection(
  File "/p/home/jusers/reck1/juwels/keksenv/lib/python3.8/site-packages/redis/connection.py", line 1192, in get_connection
    connection.connect()
  File "/p/home/jusers/reck1/juwels/keksenv/lib/python3.8/site-packages/redis/connection.py", line 563, in connect
    raise ConnectionError(self._error_message(e))
redis.exceptions.ConnectionError: Error -2 connecting to found::6358. Name or service not known.
INFO:Redis-Worker:Start redis worker. Max run time 86400.0s, HOST=jwc03n274.juwels, PID=28115
Process Process-19:
Traceback (most recent call last):
  File "/p/home/jusers/reck1/juwels/keksenv/lib/python3.8/site-packages/redis/connection.py", line 559, in connect
    sock = self._connect()
  File "/p/home/jusers/reck1/juwels/keksenv/lib/python3.8/site-packages/redis/connection.py", line 584, in _connect
    for res in socket.getaddrinfo(self.host, self.port, self.socket_type,
  File "/p/software/juwels/stages/2020/software/Python/3.8.5-GCCcore-9.3.0/lib/python3.8/socket.py", line 918, in getaddrinfo
    for res in _socket.getaddrinfo(host, port, family, type, proto, flags):
socket.gaierror: [Errno -2] Name or service not known

During handling of the above exception, another exception occurred:

Traceback (most recent call last):
  File "/p/software/juwels/stages/2020/software/Python/3.8.5-GCCcore-9.3.0/lib/python3.8/multiprocessing/process.py", line 315, in _bootstrap
    self.run()
  File "/p/software/juwels/stages/2020/software/Python/3.8.5-GCCcore-9.3.0/lib/python3.8/multiprocessing/process.py", line 108, in run
    self._target(*self._args, **self._kwargs)
  File "/p/home/jusers/reck1/juwels/pyABC/pyabc/sampler/redis_eps/cli.py", line 99, in _work
    p.subscribe(MSG)
  File "/p/home/jusers/reck1/juwels/keksenv/lib/python3.8/site-packages/redis/client.py", line 3580, in subscribe
    ret_val = self.execute_command('SUBSCRIBE', *iterkeys(new_channels))
  File "/p/home/jusers/reck1/juwels/keksenv/lib/python3.8/site-packages/redis/client.py", line 3466, in execute_command
    self.connection = self.connection_pool.get_connection(
  File "/p/home/jusers/reck1/juwels/keksenv/lib/python3.8/site-packages/redis/connection.py", line 1192, in get_connection
    connection.connect()
  File "/p/home/jusers/reck1/juwels/keksenv/lib/python3.8/site-packages/redis/connection.py", line 563, in connect
    raise ConnectionError(self._error_message(e))
redis.exceptions.ConnectionError: Error -2 connecting to found::6358. Name or service not known.
INFO:Redis-Worker:Start redis worker. Max run time 86400.0s, HOST=jwc03n274.juwels, PID=28116
Process Process-20:
Traceback (most recent call last):
  File "/p/home/jusers/reck1/juwels/keksenv/lib/python3.8/site-packages/redis/connection.py", line 559, in connect
    sock = self._connect()
  File "/p/home/jusers/reck1/juwels/keksenv/lib/python3.8/site-packages/redis/connection.py", line 584, in _connect
    for res in socket.getaddrinfo(self.host, self.port, self.socket_type,
  File "/p/software/juwels/stages/2020/software/Python/3.8.5-GCCcore-9.3.0/lib/python3.8/socket.py", line 918, in getaddrinfo
    for res in _socket.getaddrinfo(host, port, family, type, proto, flags):
socket.gaierror: [Errno -2] Name or service not known

During handling of the above exception, another exception occurred:

Traceback (most recent call last):
  File "/p/software/juwels/stages/2020/software/Python/3.8.5-GCCcore-9.3.0/lib/python3.8/multiprocessing/process.py", line 315, in _bootstrap
    self.run()
  File "/p/software/juwels/stages/2020/software/Python/3.8.5-GCCcore-9.3.0/lib/python3.8/multiprocessing/process.py", line 108, in run
    self._target(*self._args, **self._kwargs)
  File "/p/home/jusers/reck1/juwels/pyABC/pyabc/sampler/redis_eps/cli.py", line 99, in _work
    p.subscribe(MSG)
  File "/p/home/jusers/reck1/juwels/keksenv/lib/python3.8/site-packages/redis/client.py", line 3580, in subscribe
    ret_val = self.execute_command('SUBSCRIBE', *iterkeys(new_channels))
  File "/p/home/jusers/reck1/juwels/keksenv/lib/python3.8/site-packages/redis/client.py", line 3466, in execute_command
    self.connection = self.connection_pool.get_connection(
  File "/p/home/jusers/reck1/juwels/keksenv/lib/python3.8/site-packages/redis/connection.py", line 1192, in get_connection
    connection.connect()
  File "/p/home/jusers/reck1/juwels/keksenv/lib/python3.8/site-packages/redis/connection.py", line 563, in connect
    raise ConnectionError(self._error_message(e))
redis.exceptions.ConnectionError: Error -2 connecting to found::6358. Name or service not known.
INFO:Redis-Worker:Start redis worker. Max run time 86400.0s, HOST=jwc03n274.juwels, PID=28117
Process Process-21:
Traceback (most recent call last):
  File "/p/home/jusers/reck1/juwels/keksenv/lib/python3.8/site-packages/redis/connection.py", line 559, in connect
    sock = self._connect()
  File "/p/home/jusers/reck1/juwels/keksenv/lib/python3.8/site-packages/redis/connection.py", line 584, in _connect
    for res in socket.getaddrinfo(self.host, self.port, self.socket_type,
  File "/p/software/juwels/stages/2020/software/Python/3.8.5-GCCcore-9.3.0/lib/python3.8/socket.py", line 918, in getaddrinfo
    for res in _socket.getaddrinfo(host, port, family, type, proto, flags):
socket.gaierror: [Errno -2] Name or service not known

During handling of the above exception, another exception occurred:

Traceback (most recent call last):
  File "/p/software/juwels/stages/2020/software/Python/3.8.5-GCCcore-9.3.0/lib/python3.8/multiprocessing/process.py", line 315, in _bootstrap
    self.run()
  File "/p/software/juwels/stages/2020/software/Python/3.8.5-GCCcore-9.3.0/lib/python3.8/multiprocessing/process.py", line 108, in run
    self._target(*self._args, **self._kwargs)
  File "/p/home/jusers/reck1/juwels/pyABC/pyabc/sampler/redis_eps/cli.py", line 99, in _work
    p.subscribe(MSG)
  File "/p/home/jusers/reck1/juwels/keksenv/lib/python3.8/site-packages/redis/client.py", line 3580, in subscribe
    ret_val = self.execute_command('SUBSCRIBE', *iterkeys(new_channels))
  File "/p/home/jusers/reck1/juwels/keksenv/lib/python3.8/site-packages/redis/client.py", line 3466, in execute_command
    self.connection = self.connection_pool.get_connection(
  File "/p/home/jusers/reck1/juwels/keksenv/lib/python3.8/site-packages/redis/connection.py", line 1192, in get_connection
    connection.connect()
  File "/p/home/jusers/reck1/juwels/keksenv/lib/python3.8/site-packages/redis/connection.py", line 563, in connect
    raise ConnectionError(self._error_message(e))
redis.exceptions.ConnectionError: Error -2 connecting to found::6358. Name or service not known.
INFO:Redis-Worker:Start redis worker. Max run time 86400.0s, HOST=jwc03n274.juwels, PID=28118
Process Process-22:
Traceback (most recent call last):
  File "/p/home/jusers/reck1/juwels/keksenv/lib/python3.8/site-packages/redis/connection.py", line 559, in connect
    sock = self._connect()
  File "/p/home/jusers/reck1/juwels/keksenv/lib/python3.8/site-packages/redis/connection.py", line 584, in _connect
    for res in socket.getaddrinfo(self.host, self.port, self.socket_type,
  File "/p/software/juwels/stages/2020/software/Python/3.8.5-GCCcore-9.3.0/lib/python3.8/socket.py", line 918, in getaddrinfo
    for res in _socket.getaddrinfo(host, port, family, type, proto, flags):
socket.gaierror: [Errno -2] Name or service not known

During handling of the above exception, another exception occurred:

Traceback (most recent call last):
  File "/p/software/juwels/stages/2020/software/Python/3.8.5-GCCcore-9.3.0/lib/python3.8/multiprocessing/process.py", line 315, in _bootstrap
    self.run()
  File "/p/software/juwels/stages/2020/software/Python/3.8.5-GCCcore-9.3.0/lib/python3.8/multiprocessing/process.py", line 108, in run
    self._target(*self._args, **self._kwargs)
  File "/p/home/jusers/reck1/juwels/pyABC/pyabc/sampler/redis_eps/cli.py", line 99, in _work
    p.subscribe(MSG)
  File "/p/home/jusers/reck1/juwels/keksenv/lib/python3.8/site-packages/redis/client.py", line 3580, in subscribe
    ret_val = self.execute_command('SUBSCRIBE', *iterkeys(new_channels))
  File "/p/home/jusers/reck1/juwels/keksenv/lib/python3.8/site-packages/redis/client.py", line 3466, in execute_command
    self.connection = self.connection_pool.get_connection(
  File "/p/home/jusers/reck1/juwels/keksenv/lib/python3.8/site-packages/redis/connection.py", line 1192, in get_connection
    connection.connect()
  File "/p/home/jusers/reck1/juwels/keksenv/lib/python3.8/site-packages/redis/connection.py", line 563, in connect
    raise ConnectionError(self._error_message(e))
redis.exceptions.ConnectionError: Error -2 connecting to found::6358. Name or service not known.
INFO:Redis-Worker:Start redis worker. Max run time 86400.0s, HOST=jwc03n274.juwels, PID=28119
Process Process-23:
Traceback (most recent call last):
  File "/p/home/jusers/reck1/juwels/keksenv/lib/python3.8/site-packages/redis/connection.py", line 559, in connect
    sock = self._connect()
  File "/p/home/jusers/reck1/juwels/keksenv/lib/python3.8/site-packages/redis/connection.py", line 584, in _connect
    for res in socket.getaddrinfo(self.host, self.port, self.socket_type,
  File "/p/software/juwels/stages/2020/software/Python/3.8.5-GCCcore-9.3.0/lib/python3.8/socket.py", line 918, in getaddrinfo
    for res in _socket.getaddrinfo(host, port, family, type, proto, flags):
socket.gaierror: [Errno -2] Name or service not known

During handling of the above exception, another exception occurred:

Traceback (most recent call last):
  File "/p/software/juwels/stages/2020/software/Python/3.8.5-GCCcore-9.3.0/lib/python3.8/multiprocessing/process.py", line 315, in _bootstrap
    self.run()
  File "/p/software/juwels/stages/2020/software/Python/3.8.5-GCCcore-9.3.0/lib/python3.8/multiprocessing/process.py", line 108, in run
    self._target(*self._args, **self._kwargs)
  File "/p/home/jusers/reck1/juwels/pyABC/pyabc/sampler/redis_eps/cli.py", line 99, in _work
    p.subscribe(MSG)
  File "/p/home/jusers/reck1/juwels/keksenv/lib/python3.8/site-packages/redis/client.py", line 3580, in subscribe
    ret_val = self.execute_command('SUBSCRIBE', *iterkeys(new_channels))
  File "/p/home/jusers/reck1/juwels/keksenv/lib/python3.8/site-packages/redis/client.py", line 3466, in execute_command
    self.connection = self.connection_pool.get_connection(
  File "/p/home/jusers/reck1/juwels/keksenv/lib/python3.8/site-packages/redis/connection.py", line 1192, in get_connection
    connection.connect()
  File "/p/home/jusers/reck1/juwels/keksenv/lib/python3.8/site-packages/redis/connection.py", line 563, in connect
    raise ConnectionError(self._error_message(e))
redis.exceptions.ConnectionError: Error -2 connecting to found::6358. Name or service not known.
INFO:Redis-Worker:Start redis worker. Max run time 86400.0s, HOST=jwc03n274.juwels, PID=28120
Process Process-24:
Traceback (most recent call last):
  File "/p/home/jusers/reck1/juwels/keksenv/lib/python3.8/site-packages/redis/connection.py", line 559, in connect
    sock = self._connect()
  File "/p/home/jusers/reck1/juwels/keksenv/lib/python3.8/site-packages/redis/connection.py", line 584, in _connect
    for res in socket.getaddrinfo(self.host, self.port, self.socket_type,
  File "/p/software/juwels/stages/2020/software/Python/3.8.5-GCCcore-9.3.0/lib/python3.8/socket.py", line 918, in getaddrinfo
    for res in _socket.getaddrinfo(host, port, family, type, proto, flags):
socket.gaierror: [Errno -2] Name or service not known

During handling of the above exception, another exception occurred:

Traceback (most recent call last):
  File "/p/software/juwels/stages/2020/software/Python/3.8.5-GCCcore-9.3.0/lib/python3.8/multiprocessing/process.py", line 315, in _bootstrap
    self.run()
  File "/p/software/juwels/stages/2020/software/Python/3.8.5-GCCcore-9.3.0/lib/python3.8/multiprocessing/process.py", line 108, in run
    self._target(*self._args, **self._kwargs)
  File "/p/home/jusers/reck1/juwels/pyABC/pyabc/sampler/redis_eps/cli.py", line 99, in _work
    p.subscribe(MSG)
  File "/p/home/jusers/reck1/juwels/keksenv/lib/python3.8/site-packages/redis/client.py", line 3580, in subscribe
    ret_val = self.execute_command('SUBSCRIBE', *iterkeys(new_channels))
  File "/p/home/jusers/reck1/juwels/keksenv/lib/python3.8/site-packages/redis/client.py", line 3466, in execute_command
    self.connection = self.connection_pool.get_connection(
  File "/p/home/jusers/reck1/juwels/keksenv/lib/python3.8/site-packages/redis/connection.py", line 1192, in get_connection
    connection.connect()
  File "/p/home/jusers/reck1/juwels/keksenv/lib/python3.8/site-packages/redis/connection.py", line 563, in connect
    raise ConnectionError(self._error_message(e))
redis.exceptions.ConnectionError: Error -2 connecting to found::6358. Name or service not known.
INFO:Redis-Worker:Start redis worker. Max run time 86400.0s, HOST=jwc03n274.juwels, PID=28121
Process Process-25:
Traceback (most recent call last):
  File "/p/home/jusers/reck1/juwels/keksenv/lib/python3.8/site-packages/redis/connection.py", line 559, in connect
    sock = self._connect()
  File "/p/home/jusers/reck1/juwels/keksenv/lib/python3.8/site-packages/redis/connection.py", line 584, in _connect
    for res in socket.getaddrinfo(self.host, self.port, self.socket_type,
  File "/p/software/juwels/stages/2020/software/Python/3.8.5-GCCcore-9.3.0/lib/python3.8/socket.py", line 918, in getaddrinfo
    for res in _socket.getaddrinfo(host, port, family, type, proto, flags):
socket.gaierror: [Errno -2] Name or service not known

During handling of the above exception, another exception occurred:

Traceback (most recent call last):
  File "/p/software/juwels/stages/2020/software/Python/3.8.5-GCCcore-9.3.0/lib/python3.8/multiprocessing/process.py", line 315, in _bootstrap
    self.run()
  File "/p/software/juwels/stages/2020/software/Python/3.8.5-GCCcore-9.3.0/lib/python3.8/multiprocessing/process.py", line 108, in run
    self._target(*self._args, **self._kwargs)
  File "/p/home/jusers/reck1/juwels/pyABC/pyabc/sampler/redis_eps/cli.py", line 99, in _work
    p.subscribe(MSG)
  File "/p/home/jusers/reck1/juwels/keksenv/lib/python3.8/site-packages/redis/client.py", line 3580, in subscribe
    ret_val = self.execute_command('SUBSCRIBE', *iterkeys(new_channels))
  File "/p/home/jusers/reck1/juwels/keksenv/lib/python3.8/site-packages/redis/client.py", line 3466, in execute_command
    self.connection = self.connection_pool.get_connection(
  File "/p/home/jusers/reck1/juwels/keksenv/lib/python3.8/site-packages/redis/connection.py", line 1192, in get_connection
    connection.connect()
  File "/p/home/jusers/reck1/juwels/keksenv/lib/python3.8/site-packages/redis/connection.py", line 563, in connect
    raise ConnectionError(self._error_message(e))
redis.exceptions.ConnectionError: Error -2 connecting to found::6358. Name or service not known.
INFO:Redis-Worker:Start redis worker. Max run time 86400.0s, HOST=jwc03n274.juwels, PID=28122
Process Process-26:
Traceback (most recent call last):
  File "/p/home/jusers/reck1/juwels/keksenv/lib/python3.8/site-packages/redis/connection.py", line 559, in connect
    sock = self._connect()
  File "/p/home/jusers/reck1/juwels/keksenv/lib/python3.8/site-packages/redis/connection.py", line 584, in _connect
    for res in socket.getaddrinfo(self.host, self.port, self.socket_type,
  File "/p/software/juwels/stages/2020/software/Python/3.8.5-GCCcore-9.3.0/lib/python3.8/socket.py", line 918, in getaddrinfo
    for res in _socket.getaddrinfo(host, port, family, type, proto, flags):
socket.gaierror: [Errno -2] Name or service not known

During handling of the above exception, another exception occurred:

Traceback (most recent call last):
  File "/p/software/juwels/stages/2020/software/Python/3.8.5-GCCcore-9.3.0/lib/python3.8/multiprocessing/process.py", line 315, in _bootstrap
    self.run()
  File "/p/software/juwels/stages/2020/software/Python/3.8.5-GCCcore-9.3.0/lib/python3.8/multiprocessing/process.py", line 108, in run
    self._target(*self._args, **self._kwargs)
  File "/p/home/jusers/reck1/juwels/pyABC/pyabc/sampler/redis_eps/cli.py", line 99, in _work
    p.subscribe(MSG)
  File "/p/home/jusers/reck1/juwels/keksenv/lib/python3.8/site-packages/redis/client.py", line 3580, in subscribe
    ret_val = self.execute_command('SUBSCRIBE', *iterkeys(new_channels))
  File "/p/home/jusers/reck1/juwels/keksenv/lib/python3.8/site-packages/redis/client.py", line 3466, in execute_command
    self.connection = self.connection_pool.get_connection(
  File "/p/home/jusers/reck1/juwels/keksenv/lib/python3.8/site-packages/redis/connection.py", line 1192, in get_connection
    connection.connect()
  File "/p/home/jusers/reck1/juwels/keksenv/lib/python3.8/site-packages/redis/connection.py", line 563, in connect
    raise ConnectionError(self._error_message(e))
redis.exceptions.ConnectionError: Error -2 connecting to found::6358. Name or service not known.
INFO:Redis-Worker:Start redis worker. Max run time 86400.0s, HOST=jwc03n274.juwels, PID=28123
Process Process-27:
Traceback (most recent call last):
  File "/p/home/jusers/reck1/juwels/keksenv/lib/python3.8/site-packages/redis/connection.py", line 559, in connect
    sock = self._connect()
  File "/p/home/jusers/reck1/juwels/keksenv/lib/python3.8/site-packages/redis/connection.py", line 584, in _connect
    for res in socket.getaddrinfo(self.host, self.port, self.socket_type,
  File "/p/software/juwels/stages/2020/software/Python/3.8.5-GCCcore-9.3.0/lib/python3.8/socket.py", line 918, in getaddrinfo
    for res in _socket.getaddrinfo(host, port, family, type, proto, flags):
socket.gaierror: [Errno -2] Name or service not known

During handling of the above exception, another exception occurred:

Traceback (most recent call last):
  File "/p/software/juwels/stages/2020/software/Python/3.8.5-GCCcore-9.3.0/lib/python3.8/multiprocessing/process.py", line 315, in _bootstrap
    self.run()
  File "/p/software/juwels/stages/2020/software/Python/3.8.5-GCCcore-9.3.0/lib/python3.8/multiprocessing/process.py", line 108, in run
    self._target(*self._args, **self._kwargs)
  File "/p/home/jusers/reck1/juwels/pyABC/pyabc/sampler/redis_eps/cli.py", line 99, in _work
    p.subscribe(MSG)
  File "/p/home/jusers/reck1/juwels/keksenv/lib/python3.8/site-packages/redis/client.py", line 3580, in subscribe
    ret_val = self.execute_command('SUBSCRIBE', *iterkeys(new_channels))
  File "/p/home/jusers/reck1/juwels/keksenv/lib/python3.8/site-packages/redis/client.py", line 3466, in execute_command
    self.connection = self.connection_pool.get_connection(
  File "/p/home/jusers/reck1/juwels/keksenv/lib/python3.8/site-packages/redis/connection.py", line 1192, in get_connection
    connection.connect()
  File "/p/home/jusers/reck1/juwels/keksenv/lib/python3.8/site-packages/redis/connection.py", line 563, in connect
    raise ConnectionError(self._error_message(e))
redis.exceptions.ConnectionError: Error -2 connecting to found::6358. Name or service not known.
INFO:Redis-Worker:Start redis worker. Max run time 86400.0s, HOST=jwc03n274.juwels, PID=28124
Process Process-28:
Traceback (most recent call last):
  File "/p/home/jusers/reck1/juwels/keksenv/lib/python3.8/site-packages/redis/connection.py", line 559, in connect
    sock = self._connect()
  File "/p/home/jusers/reck1/juwels/keksenv/lib/python3.8/site-packages/redis/connection.py", line 584, in _connect
    for res in socket.getaddrinfo(self.host, self.port, self.socket_type,
  File "/p/software/juwels/stages/2020/software/Python/3.8.5-GCCcore-9.3.0/lib/python3.8/socket.py", line 918, in getaddrinfo
    for res in _socket.getaddrinfo(host, port, family, type, proto, flags):
socket.gaierror: [Errno -2] Name or service not known

During handling of the above exception, another exception occurred:

Traceback (most recent call last):
  File "/p/software/juwels/stages/2020/software/Python/3.8.5-GCCcore-9.3.0/lib/python3.8/multiprocessing/process.py", line 315, in _bootstrap
    self.run()
  File "/p/software/juwels/stages/2020/software/Python/3.8.5-GCCcore-9.3.0/lib/python3.8/multiprocessing/process.py", line 108, in run
    self._target(*self._args, **self._kwargs)
  File "/p/home/jusers/reck1/juwels/pyABC/pyabc/sampler/redis_eps/cli.py", line 99, in _work
    p.subscribe(MSG)
  File "/p/home/jusers/reck1/juwels/keksenv/lib/python3.8/site-packages/redis/client.py", line 3580, in subscribe
    ret_val = self.execute_command('SUBSCRIBE', *iterkeys(new_channels))
  File "/p/home/jusers/reck1/juwels/keksenv/lib/python3.8/site-packages/redis/client.py", line 3466, in execute_command
    self.connection = self.connection_pool.get_connection(
  File "/p/home/jusers/reck1/juwels/keksenv/lib/python3.8/site-packages/redis/connection.py", line 1192, in get_connection
    connection.connect()
  File "/p/home/jusers/reck1/juwels/keksenv/lib/python3.8/site-packages/redis/connection.py", line 563, in connect
    raise ConnectionError(self._error_message(e))
redis.exceptions.ConnectionError: Error -2 connecting to found::6358. Name or service not known.
INFO:Redis-Worker:Start redis worker. Max run time 86400.0s, HOST=jwc03n274.juwels, PID=28125
Process Process-29:
Traceback (most recent call last):
  File "/p/home/jusers/reck1/juwels/keksenv/lib/python3.8/site-packages/redis/connection.py", line 559, in connect
    sock = self._connect()
  File "/p/home/jusers/reck1/juwels/keksenv/lib/python3.8/site-packages/redis/connection.py", line 584, in _connect
    for res in socket.getaddrinfo(self.host, self.port, self.socket_type,
  File "/p/software/juwels/stages/2020/software/Python/3.8.5-GCCcore-9.3.0/lib/python3.8/socket.py", line 918, in getaddrinfo
    for res in _socket.getaddrinfo(host, port, family, type, proto, flags):
socket.gaierror: [Errno -2] Name or service not known

During handling of the above exception, another exception occurred:

Traceback (most recent call last):
  File "/p/software/juwels/stages/2020/software/Python/3.8.5-GCCcore-9.3.0/lib/python3.8/multiprocessing/process.py", line 315, in _bootstrap
    self.run()
  File "/p/software/juwels/stages/2020/software/Python/3.8.5-GCCcore-9.3.0/lib/python3.8/multiprocessing/process.py", line 108, in run
    self._target(*self._args, **self._kwargs)
  File "/p/home/jusers/reck1/juwels/pyABC/pyabc/sampler/redis_eps/cli.py", line 99, in _work
    p.subscribe(MSG)
  File "/p/home/jusers/reck1/juwels/keksenv/lib/python3.8/site-packages/redis/client.py", line 3580, in subscribe
    ret_val = self.execute_command('SUBSCRIBE', *iterkeys(new_channels))
  File "/p/home/jusers/reck1/juwels/keksenv/lib/python3.8/site-packages/redis/client.py", line 3466, in execute_command
    self.connection = self.connection_pool.get_connection(
  File "/p/home/jusers/reck1/juwels/keksenv/lib/python3.8/site-packages/redis/connection.py", line 1192, in get_connection
    connection.connect()
  File "/p/home/jusers/reck1/juwels/keksenv/lib/python3.8/site-packages/redis/connection.py", line 563, in connect
    raise ConnectionError(self._error_message(e))
redis.exceptions.ConnectionError: Error -2 connecting to found::6358. Name or service not known.
INFO:Redis-Worker:Start redis worker. Max run time 86400.0s, HOST=jwc03n274.juwels, PID=28126
Process Process-30:
Traceback (most recent call last):
  File "/p/home/jusers/reck1/juwels/keksenv/lib/python3.8/site-packages/redis/connection.py", line 559, in connect
    sock = self._connect()
  File "/p/home/jusers/reck1/juwels/keksenv/lib/python3.8/site-packages/redis/connection.py", line 584, in _connect
    for res in socket.getaddrinfo(self.host, self.port, self.socket_type,
  File "/p/software/juwels/stages/2020/software/Python/3.8.5-GCCcore-9.3.0/lib/python3.8/socket.py", line 918, in getaddrinfo
    for res in _socket.getaddrinfo(host, port, family, type, proto, flags):
socket.gaierror: [Errno -2] Name or service not known

During handling of the above exception, another exception occurred:

Traceback (most recent call last):
  File "/p/software/juwels/stages/2020/software/Python/3.8.5-GCCcore-9.3.0/lib/python3.8/multiprocessing/process.py", line 315, in _bootstrap
    self.run()
  File "/p/software/juwels/stages/2020/software/Python/3.8.5-GCCcore-9.3.0/lib/python3.8/multiprocessing/process.py", line 108, in run
    self._target(*self._args, **self._kwargs)
  File "/p/home/jusers/reck1/juwels/pyABC/pyabc/sampler/redis_eps/cli.py", line 99, in _work
    p.subscribe(MSG)
  File "/p/home/jusers/reck1/juwels/keksenv/lib/python3.8/site-packages/redis/client.py", line 3580, in subscribe
    ret_val = self.execute_command('SUBSCRIBE', *iterkeys(new_channels))
  File "/p/home/jusers/reck1/juwels/keksenv/lib/python3.8/site-packages/redis/client.py", line 3466, in execute_command
    self.connection = self.connection_pool.get_connection(
  File "/p/home/jusers/reck1/juwels/keksenv/lib/python3.8/site-packages/redis/connection.py", line 1192, in get_connection
    connection.connect()
  File "/p/home/jusers/reck1/juwels/keksenv/lib/python3.8/site-packages/redis/connection.py", line 563, in connect
    raise ConnectionError(self._error_message(e))
redis.exceptions.ConnectionError: Error -2 connecting to found::6358. Name or service not known.
INFO:Redis-Worker:Start redis worker. Max run time 86400.0s, HOST=jwc03n274.juwels, PID=28127
Process Process-31:
Traceback (most recent call last):
  File "/p/home/jusers/reck1/juwels/keksenv/lib/python3.8/site-packages/redis/connection.py", line 559, in connect
    sock = self._connect()
  File "/p/home/jusers/reck1/juwels/keksenv/lib/python3.8/site-packages/redis/connection.py", line 584, in _connect
    for res in socket.getaddrinfo(self.host, self.port, self.socket_type,
  File "/p/software/juwels/stages/2020/software/Python/3.8.5-GCCcore-9.3.0/lib/python3.8/socket.py", line 918, in getaddrinfo
    for res in _socket.getaddrinfo(host, port, family, type, proto, flags):
socket.gaierror: [Errno -2] Name or service not known

During handling of the above exception, another exception occurred:

Traceback (most recent call last):
  File "/p/software/juwels/stages/2020/software/Python/3.8.5-GCCcore-9.3.0/lib/python3.8/multiprocessing/process.py", line 315, in _bootstrap
    self.run()
  File "/p/software/juwels/stages/2020/software/Python/3.8.5-GCCcore-9.3.0/lib/python3.8/multiprocessing/process.py", line 108, in run
    self._target(*self._args, **self._kwargs)
  File "/p/home/jusers/reck1/juwels/pyABC/pyabc/sampler/redis_eps/cli.py", line 99, in _work
    p.subscribe(MSG)
  File "/p/home/jusers/reck1/juwels/keksenv/lib/python3.8/site-packages/redis/client.py", line 3580, in subscribe
    ret_val = self.execute_command('SUBSCRIBE', *iterkeys(new_channels))
  File "/p/home/jusers/reck1/juwels/keksenv/lib/python3.8/site-packages/redis/client.py", line 3466, in execute_command
    self.connection = self.connection_pool.get_connection(
  File "/p/home/jusers/reck1/juwels/keksenv/lib/python3.8/site-packages/redis/connection.py", line 1192, in get_connection
    connection.connect()
  File "/p/home/jusers/reck1/juwels/keksenv/lib/python3.8/site-packages/redis/connection.py", line 563, in connect
    raise ConnectionError(self._error_message(e))
redis.exceptions.ConnectionError: Error -2 connecting to found::6358. Name or service not known.
INFO:Redis-Worker:Start redis worker. Max run time 86400.0s, HOST=jwc03n274.juwels, PID=28128
Process Process-32:
Traceback (most recent call last):
  File "/p/home/jusers/reck1/juwels/keksenv/lib/python3.8/site-packages/redis/connection.py", line 559, in connect
    sock = self._connect()
  File "/p/home/jusers/reck1/juwels/keksenv/lib/python3.8/site-packages/redis/connection.py", line 584, in _connect
    for res in socket.getaddrinfo(self.host, self.port, self.socket_type,
  File "/p/software/juwels/stages/2020/software/Python/3.8.5-GCCcore-9.3.0/lib/python3.8/socket.py", line 918, in getaddrinfo
    for res in _socket.getaddrinfo(host, port, family, type, proto, flags):
socket.gaierror: [Errno -2] Name or service not known

During handling of the above exception, another exception occurred:

Traceback (most recent call last):
  File "/p/software/juwels/stages/2020/software/Python/3.8.5-GCCcore-9.3.0/lib/python3.8/multiprocessing/process.py", line 315, in _bootstrap
    self.run()
  File "/p/software/juwels/stages/2020/software/Python/3.8.5-GCCcore-9.3.0/lib/python3.8/multiprocessing/process.py", line 108, in run
    self._target(*self._args, **self._kwargs)
  File "/p/home/jusers/reck1/juwels/pyABC/pyabc/sampler/redis_eps/cli.py", line 99, in _work
    p.subscribe(MSG)
  File "/p/home/jusers/reck1/juwels/keksenv/lib/python3.8/site-packages/redis/client.py", line 3580, in subscribe
    ret_val = self.execute_command('SUBSCRIBE', *iterkeys(new_channels))
  File "/p/home/jusers/reck1/juwels/keksenv/lib/python3.8/site-packages/redis/client.py", line 3466, in execute_command
    self.connection = self.connection_pool.get_connection(
  File "/p/home/jusers/reck1/juwels/keksenv/lib/python3.8/site-packages/redis/connection.py", line 1192, in get_connection
    connection.connect()
  File "/p/home/jusers/reck1/juwels/keksenv/lib/python3.8/site-packages/redis/connection.py", line 563, in connect
    raise ConnectionError(self._error_message(e))
redis.exceptions.ConnectionError: Error -2 connecting to found::6358. Name or service not known.
INFO:Redis-Worker:Start redis worker. Max run time 86400.0s, HOST=jwc03n274.juwels, PID=28129
Process Process-33:
Traceback (most recent call last):
  File "/p/home/jusers/reck1/juwels/keksenv/lib/python3.8/site-packages/redis/connection.py", line 559, in connect
    sock = self._connect()
  File "/p/home/jusers/reck1/juwels/keksenv/lib/python3.8/site-packages/redis/connection.py", line 584, in _connect
    for res in socket.getaddrinfo(self.host, self.port, self.socket_type,
  File "/p/software/juwels/stages/2020/software/Python/3.8.5-GCCcore-9.3.0/lib/python3.8/socket.py", line 918, in getaddrinfo
    for res in _socket.getaddrinfo(host, port, family, type, proto, flags):
socket.gaierror: [Errno -2] Name or service not known

During handling of the above exception, another exception occurred:

Traceback (most recent call last):
  File "/p/software/juwels/stages/2020/software/Python/3.8.5-GCCcore-9.3.0/lib/python3.8/multiprocessing/process.py", line 315, in _bootstrap
    self.run()
  File "/p/software/juwels/stages/2020/software/Python/3.8.5-GCCcore-9.3.0/lib/python3.8/multiprocessing/process.py", line 108, in run
    self._target(*self._args, **self._kwargs)
  File "/p/home/jusers/reck1/juwels/pyABC/pyabc/sampler/redis_eps/cli.py", line 99, in _work
    p.subscribe(MSG)
  File "/p/home/jusers/reck1/juwels/keksenv/lib/python3.8/site-packages/redis/client.py", line 3580, in subscribe
    ret_val = self.execute_command('SUBSCRIBE', *iterkeys(new_channels))
  File "/p/home/jusers/reck1/juwels/keksenv/lib/python3.8/site-packages/redis/client.py", line 3466, in execute_command
    self.connection = self.connection_pool.get_connection(
  File "/p/home/jusers/reck1/juwels/keksenv/lib/python3.8/site-packages/redis/connection.py", line 1192, in get_connection
    connection.connect()
  File "/p/home/jusers/reck1/juwels/keksenv/lib/python3.8/site-packages/redis/connection.py", line 563, in connect
    raise ConnectionError(self._error_message(e))
redis.exceptions.ConnectionError: Error -2 connecting to found::6358. Name or service not known.
INFO:Redis-Worker:Start redis worker. Max run time 86400.0s, HOST=jwc03n274.juwels, PID=28130
Process Process-34:
Traceback (most recent call last):
  File "/p/home/jusers/reck1/juwels/keksenv/lib/python3.8/site-packages/redis/connection.py", line 559, in connect
    sock = self._connect()
  File "/p/home/jusers/reck1/juwels/keksenv/lib/python3.8/site-packages/redis/connection.py", line 584, in _connect
    for res in socket.getaddrinfo(self.host, self.port, self.socket_type,
  File "/p/software/juwels/stages/2020/software/Python/3.8.5-GCCcore-9.3.0/lib/python3.8/socket.py", line 918, in getaddrinfo
    for res in _socket.getaddrinfo(host, port, family, type, proto, flags):
socket.gaierror: [Errno -2] Name or service not known

During handling of the above exception, another exception occurred:

Traceback (most recent call last):
  File "/p/software/juwels/stages/2020/software/Python/3.8.5-GCCcore-9.3.0/lib/python3.8/multiprocessing/process.py", line 315, in _bootstrap
    self.run()
  File "/p/software/juwels/stages/2020/software/Python/3.8.5-GCCcore-9.3.0/lib/python3.8/multiprocessing/process.py", line 108, in run
    self._target(*self._args, **self._kwargs)
  File "/p/home/jusers/reck1/juwels/pyABC/pyabc/sampler/redis_eps/cli.py", line 99, in _work
    p.subscribe(MSG)
  File "/p/home/jusers/reck1/juwels/keksenv/lib/python3.8/site-packages/redis/client.py", line 3580, in subscribe
    ret_val = self.execute_command('SUBSCRIBE', *iterkeys(new_channels))
  File "/p/home/jusers/reck1/juwels/keksenv/lib/python3.8/site-packages/redis/client.py", line 3466, in execute_command
    self.connection = self.connection_pool.get_connection(
  File "/p/home/jusers/reck1/juwels/keksenv/lib/python3.8/site-packages/redis/connection.py", line 1192, in get_connection
    connection.connect()
  File "/p/home/jusers/reck1/juwels/keksenv/lib/python3.8/site-packages/redis/connection.py", line 563, in connect
    raise ConnectionError(self._error_message(e))
redis.exceptions.ConnectionError: Error -2 connecting to found::6358. Name or service not known.
INFO:Redis-Worker:Start redis worker. Max run time 86400.0s, HOST=jwc03n274.juwels, PID=28131
Process Process-35:
Traceback (most recent call last):
  File "/p/home/jusers/reck1/juwels/keksenv/lib/python3.8/site-packages/redis/connection.py", line 559, in connect
    sock = self._connect()
  File "/p/home/jusers/reck1/juwels/keksenv/lib/python3.8/site-packages/redis/connection.py", line 584, in _connect
    for res in socket.getaddrinfo(self.host, self.port, self.socket_type,
  File "/p/software/juwels/stages/2020/software/Python/3.8.5-GCCcore-9.3.0/lib/python3.8/socket.py", line 918, in getaddrinfo
    for res in _socket.getaddrinfo(host, port, family, type, proto, flags):
socket.gaierror: [Errno -2] Name or service not known

During handling of the above exception, another exception occurred:

Traceback (most recent call last):
  File "/p/software/juwels/stages/2020/software/Python/3.8.5-GCCcore-9.3.0/lib/python3.8/multiprocessing/process.py", line 315, in _bootstrap
    self.run()
  File "/p/software/juwels/stages/2020/software/Python/3.8.5-GCCcore-9.3.0/lib/python3.8/multiprocessing/process.py", line 108, in run
    self._target(*self._args, **self._kwargs)
  File "/p/home/jusers/reck1/juwels/pyABC/pyabc/sampler/redis_eps/cli.py", line 99, in _work
    p.subscribe(MSG)
  File "/p/home/jusers/reck1/juwels/keksenv/lib/python3.8/site-packages/redis/client.py", line 3580, in subscribe
    ret_val = self.execute_command('SUBSCRIBE', *iterkeys(new_channels))
  File "/p/home/jusers/reck1/juwels/keksenv/lib/python3.8/site-packages/redis/client.py", line 3466, in execute_command
    self.connection = self.connection_pool.get_connection(
  File "/p/home/jusers/reck1/juwels/keksenv/lib/python3.8/site-packages/redis/connection.py", line 1192, in get_connection
    connection.connect()
  File "/p/home/jusers/reck1/juwels/keksenv/lib/python3.8/site-packages/redis/connection.py", line 563, in connect
    raise ConnectionError(self._error_message(e))
redis.exceptions.ConnectionError: Error -2 connecting to found::6358. Name or service not known.
INFO:Redis-Worker:Start redis worker. Max run time 86400.0s, HOST=jwc03n274.juwels, PID=28132
Process Process-36:
Traceback (most recent call last):
  File "/p/home/jusers/reck1/juwels/keksenv/lib/python3.8/site-packages/redis/connection.py", line 559, in connect
    sock = self._connect()
  File "/p/home/jusers/reck1/juwels/keksenv/lib/python3.8/site-packages/redis/connection.py", line 584, in _connect
    for res in socket.getaddrinfo(self.host, self.port, self.socket_type,
  File "/p/software/juwels/stages/2020/software/Python/3.8.5-GCCcore-9.3.0/lib/python3.8/socket.py", line 918, in getaddrinfo
    for res in _socket.getaddrinfo(host, port, family, type, proto, flags):
socket.gaierror: [Errno -2] Name or service not known

During handling of the above exception, another exception occurred:

Traceback (most recent call last):
  File "/p/software/juwels/stages/2020/software/Python/3.8.5-GCCcore-9.3.0/lib/python3.8/multiprocessing/process.py", line 315, in _bootstrap
    self.run()
  File "/p/software/juwels/stages/2020/software/Python/3.8.5-GCCcore-9.3.0/lib/python3.8/multiprocessing/process.py", line 108, in run
    self._target(*self._args, **self._kwargs)
  File "/p/home/jusers/reck1/juwels/pyABC/pyabc/sampler/redis_eps/cli.py", line 99, in _work
    p.subscribe(MSG)
  File "/p/home/jusers/reck1/juwels/keksenv/lib/python3.8/site-packages/redis/client.py", line 3580, in subscribe
    ret_val = self.execute_command('SUBSCRIBE', *iterkeys(new_channels))
  File "/p/home/jusers/reck1/juwels/keksenv/lib/python3.8/site-packages/redis/client.py", line 3466, in execute_command
    self.connection = self.connection_pool.get_connection(
  File "/p/home/jusers/reck1/juwels/keksenv/lib/python3.8/site-packages/redis/connection.py", line 1192, in get_connection
    connection.connect()
  File "/p/home/jusers/reck1/juwels/keksenv/lib/python3.8/site-packages/redis/connection.py", line 563, in connect
    raise ConnectionError(self._error_message(e))
redis.exceptions.ConnectionError: Error -2 connecting to found::6358. Name or service not known.
INFO:Redis-Worker:Start redis worker. Max run time 86400.0s, HOST=jwc03n274.juwels, PID=28133
Process Process-37:
Traceback (most recent call last):
  File "/p/home/jusers/reck1/juwels/keksenv/lib/python3.8/site-packages/redis/connection.py", line 559, in connect
    sock = self._connect()
  File "/p/home/jusers/reck1/juwels/keksenv/lib/python3.8/site-packages/redis/connection.py", line 584, in _connect
    for res in socket.getaddrinfo(self.host, self.port, self.socket_type,
  File "/p/software/juwels/stages/2020/software/Python/3.8.5-GCCcore-9.3.0/lib/python3.8/socket.py", line 918, in getaddrinfo
    for res in _socket.getaddrinfo(host, port, family, type, proto, flags):
socket.gaierror: [Errno -2] Name or service not known

During handling of the above exception, another exception occurred:

Traceback (most recent call last):
  File "/p/software/juwels/stages/2020/software/Python/3.8.5-GCCcore-9.3.0/lib/python3.8/multiprocessing/process.py", line 315, in _bootstrap
    self.run()
  File "/p/software/juwels/stages/2020/software/Python/3.8.5-GCCcore-9.3.0/lib/python3.8/multiprocessing/process.py", line 108, in run
    self._target(*self._args, **self._kwargs)
  File "/p/home/jusers/reck1/juwels/pyABC/pyabc/sampler/redis_eps/cli.py", line 99, in _work
    p.subscribe(MSG)
  File "/p/home/jusers/reck1/juwels/keksenv/lib/python3.8/site-packages/redis/client.py", line 3580, in subscribe
    ret_val = self.execute_command('SUBSCRIBE', *iterkeys(new_channels))
  File "/p/home/jusers/reck1/juwels/keksenv/lib/python3.8/site-packages/redis/client.py", line 3466, in execute_command
    self.connection = self.connection_pool.get_connection(
  File "/p/home/jusers/reck1/juwels/keksenv/lib/python3.8/site-packages/redis/connection.py", line 1192, in get_connection
    connection.connect()
  File "/p/home/jusers/reck1/juwels/keksenv/lib/python3.8/site-packages/redis/connection.py", line 563, in connect
    raise ConnectionError(self._error_message(e))
redis.exceptions.ConnectionError: Error -2 connecting to found::6358. Name or service not known.
INFO:Redis-Worker:Start redis worker. Max run time 86400.0s, HOST=jwc03n274.juwels, PID=28134
Process Process-38:
Traceback (most recent call last):
  File "/p/home/jusers/reck1/juwels/keksenv/lib/python3.8/site-packages/redis/connection.py", line 559, in connect
    sock = self._connect()
  File "/p/home/jusers/reck1/juwels/keksenv/lib/python3.8/site-packages/redis/connection.py", line 584, in _connect
    for res in socket.getaddrinfo(self.host, self.port, self.socket_type,
  File "/p/software/juwels/stages/2020/software/Python/3.8.5-GCCcore-9.3.0/lib/python3.8/socket.py", line 918, in getaddrinfo
    for res in _socket.getaddrinfo(host, port, family, type, proto, flags):
socket.gaierror: [Errno -2] Name or service not known

During handling of the above exception, another exception occurred:

Traceback (most recent call last):
  File "/p/software/juwels/stages/2020/software/Python/3.8.5-GCCcore-9.3.0/lib/python3.8/multiprocessing/process.py", line 315, in _bootstrap
    self.run()
  File "/p/software/juwels/stages/2020/software/Python/3.8.5-GCCcore-9.3.0/lib/python3.8/multiprocessing/process.py", line 108, in run
    self._target(*self._args, **self._kwargs)
  File "/p/home/jusers/reck1/juwels/pyABC/pyabc/sampler/redis_eps/cli.py", line 99, in _work
    p.subscribe(MSG)
  File "/p/home/jusers/reck1/juwels/keksenv/lib/python3.8/site-packages/redis/client.py", line 3580, in subscribe
    ret_val = self.execute_command('SUBSCRIBE', *iterkeys(new_channels))
  File "/p/home/jusers/reck1/juwels/keksenv/lib/python3.8/site-packages/redis/client.py", line 3466, in execute_command
    self.connection = self.connection_pool.get_connection(
  File "/p/home/jusers/reck1/juwels/keksenv/lib/python3.8/site-packages/redis/connection.py", line 1192, in get_connection
    connection.connect()
  File "/p/home/jusers/reck1/juwels/keksenv/lib/python3.8/site-packages/redis/connection.py", line 563, in connect
    raise ConnectionError(self._error_message(e))
redis.exceptions.ConnectionError: Error -2 connecting to found::6358. Name or service not known.
INFO:Redis-Worker:Start redis worker. Max run time 86400.0s, HOST=jwc03n274.juwels, PID=28135
Process Process-39:
Traceback (most recent call last):
  File "/p/home/jusers/reck1/juwels/keksenv/lib/python3.8/site-packages/redis/connection.py", line 559, in connect
    sock = self._connect()
  File "/p/home/jusers/reck1/juwels/keksenv/lib/python3.8/site-packages/redis/connection.py", line 584, in _connect
    for res in socket.getaddrinfo(self.host, self.port, self.socket_type,
  File "/p/software/juwels/stages/2020/software/Python/3.8.5-GCCcore-9.3.0/lib/python3.8/socket.py", line 918, in getaddrinfo
    for res in _socket.getaddrinfo(host, port, family, type, proto, flags):
socket.gaierror: [Errno -2] Name or service not known

During handling of the above exception, another exception occurred:

Traceback (most recent call last):
  File "/p/software/juwels/stages/2020/software/Python/3.8.5-GCCcore-9.3.0/lib/python3.8/multiprocessing/process.py", line 315, in _bootstrap
    self.run()
  File "/p/software/juwels/stages/2020/software/Python/3.8.5-GCCcore-9.3.0/lib/python3.8/multiprocessing/process.py", line 108, in run
    self._target(*self._args, **self._kwargs)
  File "/p/home/jusers/reck1/juwels/pyABC/pyabc/sampler/redis_eps/cli.py", line 99, in _work
    p.subscribe(MSG)
  File "/p/home/jusers/reck1/juwels/keksenv/lib/python3.8/site-packages/redis/client.py", line 3580, in subscribe
    ret_val = self.execute_command('SUBSCRIBE', *iterkeys(new_channels))
  File "/p/home/jusers/reck1/juwels/keksenv/lib/python3.8/site-packages/redis/client.py", line 3466, in execute_command
    self.connection = self.connection_pool.get_connection(
  File "/p/home/jusers/reck1/juwels/keksenv/lib/python3.8/site-packages/redis/connection.py", line 1192, in get_connection
    connection.connect()
  File "/p/home/jusers/reck1/juwels/keksenv/lib/python3.8/site-packages/redis/connection.py", line 563, in connect
    raise ConnectionError(self._error_message(e))
redis.exceptions.ConnectionError: Error -2 connecting to found::6358. Name or service not known.
INFO:Redis-Worker:Start redis worker. Max run time 86400.0s, HOST=jwc03n274.juwels, PID=28136
Process Process-40:
Traceback (most recent call last):
  File "/p/home/jusers/reck1/juwels/keksenv/lib/python3.8/site-packages/redis/connection.py", line 559, in connect
    sock = self._connect()
  File "/p/home/jusers/reck1/juwels/keksenv/lib/python3.8/site-packages/redis/connection.py", line 584, in _connect
    for res in socket.getaddrinfo(self.host, self.port, self.socket_type,
  File "/p/software/juwels/stages/2020/software/Python/3.8.5-GCCcore-9.3.0/lib/python3.8/socket.py", line 918, in getaddrinfo
    for res in _socket.getaddrinfo(host, port, family, type, proto, flags):
socket.gaierror: [Errno -2] Name or service not known

During handling of the above exception, another exception occurred:

Traceback (most recent call last):
  File "/p/software/juwels/stages/2020/software/Python/3.8.5-GCCcore-9.3.0/lib/python3.8/multiprocessing/process.py", line 315, in _bootstrap
    self.run()
  File "/p/software/juwels/stages/2020/software/Python/3.8.5-GCCcore-9.3.0/lib/python3.8/multiprocessing/process.py", line 108, in run
    self._target(*self._args, **self._kwargs)
  File "/p/home/jusers/reck1/juwels/pyABC/pyabc/sampler/redis_eps/cli.py", line 99, in _work
    p.subscribe(MSG)
  File "/p/home/jusers/reck1/juwels/keksenv/lib/python3.8/site-packages/redis/client.py", line 3580, in subscribe
    ret_val = self.execute_command('SUBSCRIBE', *iterkeys(new_channels))
  File "/p/home/jusers/reck1/juwels/keksenv/lib/python3.8/site-packages/redis/client.py", line 3466, in execute_command
    self.connection = self.connection_pool.get_connection(
  File "/p/home/jusers/reck1/juwels/keksenv/lib/python3.8/site-packages/redis/connection.py", line 1192, in get_connection
    connection.connect()
  File "/p/home/jusers/reck1/juwels/keksenv/lib/python3.8/site-packages/redis/connection.py", line 563, in connect
    raise ConnectionError(self._error_message(e))
redis.exceptions.ConnectionError: Error -2 connecting to found::6358. Name or service not known.
INFO:Redis-Worker:Start redis worker. Max run time 86400.0s, HOST=jwc03n274.juwels, PID=28137
Process Process-41:
Traceback (most recent call last):
  File "/p/home/jusers/reck1/juwels/keksenv/lib/python3.8/site-packages/redis/connection.py", line 559, in connect
    sock = self._connect()
  File "/p/home/jusers/reck1/juwels/keksenv/lib/python3.8/site-packages/redis/connection.py", line 584, in _connect
    for res in socket.getaddrinfo(self.host, self.port, self.socket_type,
  File "/p/software/juwels/stages/2020/software/Python/3.8.5-GCCcore-9.3.0/lib/python3.8/socket.py", line 918, in getaddrinfo
    for res in _socket.getaddrinfo(host, port, family, type, proto, flags):
socket.gaierror: [Errno -2] Name or service not known

During handling of the above exception, another exception occurred:

Traceback (most recent call last):
  File "/p/software/juwels/stages/2020/software/Python/3.8.5-GCCcore-9.3.0/lib/python3.8/multiprocessing/process.py", line 315, in _bootstrap
    self.run()
  File "/p/software/juwels/stages/2020/software/Python/3.8.5-GCCcore-9.3.0/lib/python3.8/multiprocessing/process.py", line 108, in run
    self._target(*self._args, **self._kwargs)
  File "/p/home/jusers/reck1/juwels/pyABC/pyabc/sampler/redis_eps/cli.py", line 99, in _work
    p.subscribe(MSG)
  File "/p/home/jusers/reck1/juwels/keksenv/lib/python3.8/site-packages/redis/client.py", line 3580, in subscribe
    ret_val = self.execute_command('SUBSCRIBE', *iterkeys(new_channels))
  File "/p/home/jusers/reck1/juwels/keksenv/lib/python3.8/site-packages/redis/client.py", line 3466, in execute_command
    self.connection = self.connection_pool.get_connection(
  File "/p/home/jusers/reck1/juwels/keksenv/lib/python3.8/site-packages/redis/connection.py", line 1192, in get_connection
    connection.connect()
  File "/p/home/jusers/reck1/juwels/keksenv/lib/python3.8/site-packages/redis/connection.py", line 563, in connect
    raise ConnectionError(self._error_message(e))
redis.exceptions.ConnectionError: Error -2 connecting to found::6358. Name or service not known.
INFO:Redis-Worker:Start redis worker. Max run time 86400.0s, HOST=jwc03n274.juwels, PID=28138
Process Process-42:
Traceback (most recent call last):
  File "/p/home/jusers/reck1/juwels/keksenv/lib/python3.8/site-packages/redis/connection.py", line 559, in connect
    sock = self._connect()
  File "/p/home/jusers/reck1/juwels/keksenv/lib/python3.8/site-packages/redis/connection.py", line 584, in _connect
    for res in socket.getaddrinfo(self.host, self.port, self.socket_type,
  File "/p/software/juwels/stages/2020/software/Python/3.8.5-GCCcore-9.3.0/lib/python3.8/socket.py", line 918, in getaddrinfo
    for res in _socket.getaddrinfo(host, port, family, type, proto, flags):
socket.gaierror: [Errno -2] Name or service not known

During handling of the above exception, another exception occurred:

Traceback (most recent call last):
  File "/p/software/juwels/stages/2020/software/Python/3.8.5-GCCcore-9.3.0/lib/python3.8/multiprocessing/process.py", line 315, in _bootstrap
    self.run()
  File "/p/software/juwels/stages/2020/software/Python/3.8.5-GCCcore-9.3.0/lib/python3.8/multiprocessing/process.py", line 108, in run
    self._target(*self._args, **self._kwargs)
  File "/p/home/jusers/reck1/juwels/pyABC/pyabc/sampler/redis_eps/cli.py", line 99, in _work
    p.subscribe(MSG)
  File "/p/home/jusers/reck1/juwels/keksenv/lib/python3.8/site-packages/redis/client.py", line 3580, in subscribe
    ret_val = self.execute_command('SUBSCRIBE', *iterkeys(new_channels))
  File "/p/home/jusers/reck1/juwels/keksenv/lib/python3.8/site-packages/redis/client.py", line 3466, in execute_command
    self.connection = self.connection_pool.get_connection(
  File "/p/home/jusers/reck1/juwels/keksenv/lib/python3.8/site-packages/redis/connection.py", line 1192, in get_connection
    connection.connect()
  File "/p/home/jusers/reck1/juwels/keksenv/lib/python3.8/site-packages/redis/connection.py", line 563, in connect
    raise ConnectionError(self._error_message(e))
redis.exceptions.ConnectionError: Error -2 connecting to found::6358. Name or service not known.
INFO:Redis-Worker:Start redis worker. Max run time 86400.0s, HOST=jwc03n274.juwels, PID=28139
Process Process-43:
Traceback (most recent call last):
  File "/p/home/jusers/reck1/juwels/keksenv/lib/python3.8/site-packages/redis/connection.py", line 559, in connect
    sock = self._connect()
  File "/p/home/jusers/reck1/juwels/keksenv/lib/python3.8/site-packages/redis/connection.py", line 584, in _connect
    for res in socket.getaddrinfo(self.host, self.port, self.socket_type,
  File "/p/software/juwels/stages/2020/software/Python/3.8.5-GCCcore-9.3.0/lib/python3.8/socket.py", line 918, in getaddrinfo
    for res in _socket.getaddrinfo(host, port, family, type, proto, flags):
socket.gaierror: [Errno -2] Name or service not known

During handling of the above exception, another exception occurred:

Traceback (most recent call last):
  File "/p/software/juwels/stages/2020/software/Python/3.8.5-GCCcore-9.3.0/lib/python3.8/multiprocessing/process.py", line 315, in _bootstrap
    self.run()
  File "/p/software/juwels/stages/2020/software/Python/3.8.5-GCCcore-9.3.0/lib/python3.8/multiprocessing/process.py", line 108, in run
    self._target(*self._args, **self._kwargs)
  File "/p/home/jusers/reck1/juwels/pyABC/pyabc/sampler/redis_eps/cli.py", line 99, in _work
    p.subscribe(MSG)
  File "/p/home/jusers/reck1/juwels/keksenv/lib/python3.8/site-packages/redis/client.py", line 3580, in subscribe
    ret_val = self.execute_command('SUBSCRIBE', *iterkeys(new_channels))
  File "/p/home/jusers/reck1/juwels/keksenv/lib/python3.8/site-packages/redis/client.py", line 3466, in execute_command
    self.connection = self.connection_pool.get_connection(
  File "/p/home/jusers/reck1/juwels/keksenv/lib/python3.8/site-packages/redis/connection.py", line 1192, in get_connection
    connection.connect()
  File "/p/home/jusers/reck1/juwels/keksenv/lib/python3.8/site-packages/redis/connection.py", line 563, in connect
    raise ConnectionError(self._error_message(e))
redis.exceptions.ConnectionError: Error -2 connecting to found::6358. Name or service not known.
INFO:Redis-Worker:Start redis worker. Max run time 86400.0s, HOST=jwc03n274.juwels, PID=28140
Process Process-44:
Traceback (most recent call last):
  File "/p/home/jusers/reck1/juwels/keksenv/lib/python3.8/site-packages/redis/connection.py", line 559, in connect
    sock = self._connect()
  File "/p/home/jusers/reck1/juwels/keksenv/lib/python3.8/site-packages/redis/connection.py", line 584, in _connect
    for res in socket.getaddrinfo(self.host, self.port, self.socket_type,
  File "/p/software/juwels/stages/2020/software/Python/3.8.5-GCCcore-9.3.0/lib/python3.8/socket.py", line 918, in getaddrinfo
    for res in _socket.getaddrinfo(host, port, family, type, proto, flags):
socket.gaierror: [Errno -2] Name or service not known

During handling of the above exception, another exception occurred:

Traceback (most recent call last):
  File "/p/software/juwels/stages/2020/software/Python/3.8.5-GCCcore-9.3.0/lib/python3.8/multiprocessing/process.py", line 315, in _bootstrap
    self.run()
  File "/p/software/juwels/stages/2020/software/Python/3.8.5-GCCcore-9.3.0/lib/python3.8/multiprocessing/process.py", line 108, in run
    self._target(*self._args, **self._kwargs)
  File "/p/home/jusers/reck1/juwels/pyABC/pyabc/sampler/redis_eps/cli.py", line 99, in _work
    p.subscribe(MSG)
  File "/p/home/jusers/reck1/juwels/keksenv/lib/python3.8/site-packages/redis/client.py", line 3580, in subscribe
    ret_val = self.execute_command('SUBSCRIBE', *iterkeys(new_channels))
  File "/p/home/jusers/reck1/juwels/keksenv/lib/python3.8/site-packages/redis/client.py", line 3466, in execute_command
    self.connection = self.connection_pool.get_connection(
  File "/p/home/jusers/reck1/juwels/keksenv/lib/python3.8/site-packages/redis/connection.py", line 1192, in get_connection
    connection.connect()
  File "/p/home/jusers/reck1/juwels/keksenv/lib/python3.8/site-packages/redis/connection.py", line 563, in connect
    raise ConnectionError(self._error_message(e))
redis.exceptions.ConnectionError: Error -2 connecting to found::6358. Name or service not known.
INFO:Redis-Worker:Start redis worker. Max run time 86400.0s, HOST=jwc03n274.juwels, PID=28141
Process Process-45:
Traceback (most recent call last):
  File "/p/home/jusers/reck1/juwels/keksenv/lib/python3.8/site-packages/redis/connection.py", line 559, in connect
    sock = self._connect()
  File "/p/home/jusers/reck1/juwels/keksenv/lib/python3.8/site-packages/redis/connection.py", line 584, in _connect
    for res in socket.getaddrinfo(self.host, self.port, self.socket_type,
  File "/p/software/juwels/stages/2020/software/Python/3.8.5-GCCcore-9.3.0/lib/python3.8/socket.py", line 918, in getaddrinfo
    for res in _socket.getaddrinfo(host, port, family, type, proto, flags):
socket.gaierror: [Errno -2] Name or service not known

During handling of the above exception, another exception occurred:

Traceback (most recent call last):
  File "/p/software/juwels/stages/2020/software/Python/3.8.5-GCCcore-9.3.0/lib/python3.8/multiprocessing/process.py", line 315, in _bootstrap
    self.run()
  File "/p/software/juwels/stages/2020/software/Python/3.8.5-GCCcore-9.3.0/lib/python3.8/multiprocessing/process.py", line 108, in run
    self._target(*self._args, **self._kwargs)
  File "/p/home/jusers/reck1/juwels/pyABC/pyabc/sampler/redis_eps/cli.py", line 99, in _work
    p.subscribe(MSG)
  File "/p/home/jusers/reck1/juwels/keksenv/lib/python3.8/site-packages/redis/client.py", line 3580, in subscribe
    ret_val = self.execute_command('SUBSCRIBE', *iterkeys(new_channels))
  File "/p/home/jusers/reck1/juwels/keksenv/lib/python3.8/site-packages/redis/client.py", line 3466, in execute_command
    self.connection = self.connection_pool.get_connection(
  File "/p/home/jusers/reck1/juwels/keksenv/lib/python3.8/site-packages/redis/connection.py", line 1192, in get_connection
    connection.connect()
  File "/p/home/jusers/reck1/juwels/keksenv/lib/python3.8/site-packages/redis/connection.py", line 563, in connect
    raise ConnectionError(self._error_message(e))
redis.exceptions.ConnectionError: Error -2 connecting to found::6358. Name or service not known.
INFO:Redis-Worker:Start redis worker. Max run time 86400.0s, HOST=jwc03n274.juwels, PID=28142
Process Process-46:
Traceback (most recent call last):
  File "/p/home/jusers/reck1/juwels/keksenv/lib/python3.8/site-packages/redis/connection.py", line 559, in connect
    sock = self._connect()
  File "/p/home/jusers/reck1/juwels/keksenv/lib/python3.8/site-packages/redis/connection.py", line 584, in _connect
    for res in socket.getaddrinfo(self.host, self.port, self.socket_type,
  File "/p/software/juwels/stages/2020/software/Python/3.8.5-GCCcore-9.3.0/lib/python3.8/socket.py", line 918, in getaddrinfo
    for res in _socket.getaddrinfo(host, port, family, type, proto, flags):
socket.gaierror: [Errno -2] Name or service not known

During handling of the above exception, another exception occurred:

Traceback (most recent call last):
  File "/p/software/juwels/stages/2020/software/Python/3.8.5-GCCcore-9.3.0/lib/python3.8/multiprocessing/process.py", line 315, in _bootstrap
    self.run()
  File "/p/software/juwels/stages/2020/software/Python/3.8.5-GCCcore-9.3.0/lib/python3.8/multiprocessing/process.py", line 108, in run
    self._target(*self._args, **self._kwargs)
  File "/p/home/jusers/reck1/juwels/pyABC/pyabc/sampler/redis_eps/cli.py", line 99, in _work
    p.subscribe(MSG)
  File "/p/home/jusers/reck1/juwels/keksenv/lib/python3.8/site-packages/redis/client.py", line 3580, in subscribe
    ret_val = self.execute_command('SUBSCRIBE', *iterkeys(new_channels))
  File "/p/home/jusers/reck1/juwels/keksenv/lib/python3.8/site-packages/redis/client.py", line 3466, in execute_command
    self.connection = self.connection_pool.get_connection(
  File "/p/home/jusers/reck1/juwels/keksenv/lib/python3.8/site-packages/redis/connection.py", line 1192, in get_connection
    connection.connect()
  File "/p/home/jusers/reck1/juwels/keksenv/lib/python3.8/site-packages/redis/connection.py", line 563, in connect
    raise ConnectionError(self._error_message(e))
redis.exceptions.ConnectionError: Error -2 connecting to found::6358. Name or service not known.
INFO:Redis-Worker:Start redis worker. Max run time 86400.0s, HOST=jwc03n274.juwels, PID=28143
Process Process-47:
Traceback (most recent call last):
  File "/p/home/jusers/reck1/juwels/keksenv/lib/python3.8/site-packages/redis/connection.py", line 559, in connect
    sock = self._connect()
  File "/p/home/jusers/reck1/juwels/keksenv/lib/python3.8/site-packages/redis/connection.py", line 584, in _connect
    for res in socket.getaddrinfo(self.host, self.port, self.socket_type,
  File "/p/software/juwels/stages/2020/software/Python/3.8.5-GCCcore-9.3.0/lib/python3.8/socket.py", line 918, in getaddrinfo
    for res in _socket.getaddrinfo(host, port, family, type, proto, flags):
socket.gaierror: [Errno -2] Name or service not known

During handling of the above exception, another exception occurred:

Traceback (most recent call last):
  File "/p/software/juwels/stages/2020/software/Python/3.8.5-GCCcore-9.3.0/lib/python3.8/multiprocessing/process.py", line 315, in _bootstrap
    self.run()
  File "/p/software/juwels/stages/2020/software/Python/3.8.5-GCCcore-9.3.0/lib/python3.8/multiprocessing/process.py", line 108, in run
    self._target(*self._args, **self._kwargs)
  File "/p/home/jusers/reck1/juwels/pyABC/pyabc/sampler/redis_eps/cli.py", line 99, in _work
    p.subscribe(MSG)
  File "/p/home/jusers/reck1/juwels/keksenv/lib/python3.8/site-packages/redis/client.py", line 3580, in subscribe
    ret_val = self.execute_command('SUBSCRIBE', *iterkeys(new_channels))
  File "/p/home/jusers/reck1/juwels/keksenv/lib/python3.8/site-packages/redis/client.py", line 3466, in execute_command
    self.connection = self.connection_pool.get_connection(
  File "/p/home/jusers/reck1/juwels/keksenv/lib/python3.8/site-packages/redis/connection.py", line 1192, in get_connection
    connection.connect()
  File "/p/home/jusers/reck1/juwels/keksenv/lib/python3.8/site-packages/redis/connection.py", line 563, in connect
    raise ConnectionError(self._error_message(e))
redis.exceptions.ConnectionError: Error -2 connecting to found::6358. Name or service not known.
INFO:Redis-Worker:Started subprocess with pid 28097
INFO:Redis-Worker:Started subprocess with pid 28098
INFO:Redis-Worker:Started subprocess with pid 28099
INFO:Redis-Worker:Started subprocess with pid 28100
INFO:Redis-Worker:Started subprocess with pid 28101
INFO:Redis-Worker:Started subprocess with pid 28102
INFO:Redis-Worker:Started subprocess with pid 28103
INFO:Redis-Worker:Started subprocess with pid 28104
INFO:Redis-Worker:Started subprocess with pid 28105
INFO:Redis-Worker:Started subprocess with pid 28106
INFO:Redis-Worker:Started subprocess with pid 28107
INFO:Redis-Worker:Started subprocess with pid 28108
INFO:Redis-Worker:Started subprocess with pid 28109
INFO:Redis-Worker:Started subprocess with pid 28110
INFO:Redis-Worker:Started subprocess with pid 28111
INFO:Redis-Worker:Started subprocess with pid 28112
INFO:Redis-Worker:Started subprocess with pid 28113
INFO:Redis-Worker:Started subprocess with pid 28114
INFO:Redis-Worker:Started subprocess with pid 28115
INFO:Redis-Worker:Started subprocess with pid 28116
INFO:Redis-Worker:Started subprocess with pid 28117
INFO:Redis-Worker:Started subprocess with pid 28118
INFO:Redis-Worker:Started subprocess with pid 28119
INFO:Redis-Worker:Started subprocess with pid 28120
INFO:Redis-Worker:Started subprocess with pid 28121
INFO:Redis-Worker:Started subprocess with pid 28122
INFO:Redis-Worker:Started subprocess with pid 28123
INFO:Redis-Worker:Started subprocess with pid 28124
INFO:Redis-Worker:Started subprocess with pid 28125
INFO:Redis-Worker:Started subprocess with pid 28126
INFO:Redis-Worker:Started subprocess with pid 28127
INFO:Redis-Worker:Started subprocess with pid 28128
INFO:Redis-Worker:Started subprocess with pid 28129
INFO:Redis-Worker:Started subprocess with pid 28130
INFO:Redis-Worker:Started subprocess with pid 28131
INFO:Redis-Worker:Started subprocess with pid 28132
INFO:Redis-Worker:Started subprocess with pid 28133
INFO:Redis-Worker:Started subprocess with pid 28134
INFO:Redis-Worker:Started subprocess with pid 28135
INFO:Redis-Worker:Started subprocess with pid 28136
INFO:Redis-Worker:Started subprocess with pid 28137
INFO:Redis-Worker:Started subprocess with pid 28138
INFO:Redis-Worker:Started subprocess with pid 28139
INFO:Redis-Worker:Started subprocess with pid 28140
INFO:Redis-Worker:Started subprocess with pid 28141
INFO:Redis-Worker:Started subprocess with pid 28142
INFO:Redis-Worker:Started subprocess with pid 28143
INFO:Redis-Worker:Started subprocess with pid 28144
INFO:Redis-Worker:Start redis worker. Max run time 86400.0s, HOST=jwc03n274.juwels, PID=28144
Process Process-48:
Traceback (most recent call last):
  File "/p/home/jusers/reck1/juwels/keksenv/lib/python3.8/site-packages/redis/connection.py", line 559, in connect
    sock = self._connect()
  File "/p/home/jusers/reck1/juwels/keksenv/lib/python3.8/site-packages/redis/connection.py", line 584, in _connect
    for res in socket.getaddrinfo(self.host, self.port, self.socket_type,
  File "/p/software/juwels/stages/2020/software/Python/3.8.5-GCCcore-9.3.0/lib/python3.8/socket.py", line 918, in getaddrinfo
    for res in _socket.getaddrinfo(host, port, family, type, proto, flags):
socket.gaierror: [Errno -2] Name or service not known

During handling of the above exception, another exception occurred:

Traceback (most recent call last):
  File "/p/software/juwels/stages/2020/software/Python/3.8.5-GCCcore-9.3.0/lib/python3.8/multiprocessing/process.py", line 315, in _bootstrap
    self.run()
  File "/p/software/juwels/stages/2020/software/Python/3.8.5-GCCcore-9.3.0/lib/python3.8/multiprocessing/process.py", line 108, in run
    self._target(*self._args, **self._kwargs)
  File "/p/home/jusers/reck1/juwels/pyABC/pyabc/sampler/redis_eps/cli.py", line 99, in _work
    p.subscribe(MSG)
  File "/p/home/jusers/reck1/juwels/keksenv/lib/python3.8/site-packages/redis/client.py", line 3580, in subscribe
    ret_val = self.execute_command('SUBSCRIBE', *iterkeys(new_channels))
  File "/p/home/jusers/reck1/juwels/keksenv/lib/python3.8/site-packages/redis/client.py", line 3466, in execute_command
    self.connection = self.connection_pool.get_connection(
  File "/p/home/jusers/reck1/juwels/keksenv/lib/python3.8/site-packages/redis/connection.py", line 1192, in get_connection
    connection.connect()
  File "/p/home/jusers/reck1/juwels/keksenv/lib/python3.8/site-packages/redis/connection.py", line 563, in connect
    raise ConnectionError(self._error_message(e))
redis.exceptions.ConnectionError: Error -2 connecting to found::6358. Name or service not known.
